Workbook

Sheet Read Me
A1: AI API / Infrastructure — 3-Year Financial Model
A2: 36-month integrated financial model — Read Me
A4: Overview
A5: A 36-month, formula-driven financial model for an AI API / infrastructure company with tiered customers, usage-based billing, and compute-heavy cost of revenue. Start on the Assumptions tab: set your Base / Upside / Downside inputs and pick a scenario. Every downstream tab recalculates automatically.
A7: How this workbook is organized
A8: Assumptions -> Headcount -> Revenue -> COGS & GM -> Opex -> Working Capital -> P&L -> Balance Sheet -> Cash Flow -> Cash & Runway -> Scenarios -> Visuals -> Checks. Data flows strictly left-to-right through that order: change an assumption, and every downstream tab recalculates automatically (workbook calculation mode is Automatic).
A10: Formatting legend
A11: Blue text on light-blue fill = an input you can edit (Assumptions tab, and scenario selector).
A12: Black text on white = a live formula. Do not hard-code over these cells.
A13: Cells on a light-gray band = a value linked in from another tab.
A15: Color palette
A16: Purple (#7B68EE)
... A35: 36 monthly periods, plus quarterly (12) and annual (3) roll-up columns on each schedule tab. Workbook calculation is set to Automatic — Excel recalculates on every edit. Deterministic, seeded default assumptions are provided so the model is internally consistent out of the box; replace them with your own numbers on the Assumptions tab.

Sheet Assumptions
A1: AI API / Infrastructure — 3-Year Financial Model — Assumptions
A2: Plain-language inputs. Edit the Base / Upside / Downside columns only — everything else in this workbook is a formula.
A4: Scenario selector: | C4: Base | D4: << Pick Base / Upside / Downside. This one cell drives every formula in the model.
A6: Assumption | B6: Unit | C6: Base | D6: Upside | E6: Downside | F6: Active (used in model) | G6: Notes / definition
A7: Company & Financial
A8: Starting cash balance | B8: $ | C8: 5000000 | D8: 5000000 | E8: 5000000 | F8: =CHOOSE(MATCH('Assumptions'!$C$4,{"Base","Upside","Downside"},0),C8,D8,E8) -> 0 | G8: Cash on hand at the start of month 1.
A9: Starting paid-in capital | B9: $ | C9: 6500000 | D9: 6500000 | E9: 6500000 | F9: =CHOOSE(MATCH('Assumptions'!$C$4,{"Base","Upside","Downside"},0),C9,D9,E9) -> 0 | G9: Cumulative equity raised before the modeled period.
A10: Income tax rate | B10: % | C10: 0 | D10: 0 | E10: 0 | F10: =CHOOSE(MATCH('Assumptions'!$C$4,{"Base","Upside","Downside"},0),C10,D10,E10) -> 0 | G10: Applied only when Earnings Before Tax is positive; no NOL schedule modeled.
A12: Customers & Volume
A13: Starter customers at month 1 start | B13: # | C13: 30 | D13: 34 | E13: 26 | F13: =CHOOSE(MATCH('Assumptions'!$C$4,{"Base","Upside","Downside"},0),C13,D13,E13) -> 0 | G13: Small self-serve / startup accounts.
A14: Starter new customers, month 1 | B14: # | C14: 6 | D14: 8 | E14: 4 | F14: =CHOOSE(MATCH('Assumptions'!$C$4,{"Base","Upside","Downside"},0),C14,D14,E14) -> 0 | G14: New Starter logos landed in month 1.
A15: Starter new-customer growth, month over month | B15: % | C15: 0.0314 | D15: 0.0535 | E15: 0.0031 | F15: =CHOOSE(MATCH('Assumptions'!$C$4,{"Base","Upside","Downside"},0),C15,D15,E15) -> 0 | G15: Compounding growth in monthly Starter logo adds.
A16: Starter monthly churn rate | B16: % | C16: 0.03 | D16: 0.02 | E16: 0.045 | F16: =CHOOSE(MATCH('Assumptions'!$C$4,{"Base","Upside","Downside"},0),C16,D16,E16) -> 0 | G16: Share of beginning Starter customers that churn each month.
A17: Starter usage per customer, month 1 | B17: M req/mo | C17: 4 | D17: 4.5 | E17: 3.5 | F17: =CHOOSE(MATCH('Assumptions'!$C$4,{"Base","Upside","Downside"},0),C17,D17,E17) -> 0 | G17: Average monthly inference request-equivalents per active Starter customer.
A18: Starter usage growth per customer, month over month | B18: % | C18: 0.04 | D18: 0.0645 | E18: 0.0143 | F18: =CHOOSE(MATCH('Assumptions'!$C$4,{"Base","Upside","Downside"},0),C18,D18,E18) -> 0 | G18: Growth in monthly usage intensity per Starter customer.
A19: Growth customers at month 1 start | B19: # | C19: 12 | D19: 14 | E19: 10 | F19: =CHOOSE(MATCH('Assumptions'!$C$4,{"Base","Upside","Downside"},0),C19,D19,E19) -> 0 | G19: Mid-market accounts on annual commits.
A20: Growth new customers, month 1 | B20: # | C20: 3 | D20: 4 | E20: 2 | F20: =CHOOSE(MATCH('Assumptions'!$C$4,{"Base","Upside","Downside"},0),C20,D20,E20) -> 0 | G20: New Growth customers landed in month 1.
A21: Growth new-customer growth, month over month | B21: % | C21: 0.0226 | D21: 0.0323 | E21: 0.0037 | F21: =CHOOSE(MATCH('Assumptions'!$C$4,{"Base","Upside","Downside"},0),C21,D21,E21) -> 0 | G21: Compounding growth in monthly Growth-customer adds.
A22: Growth monthly churn rate | B22: % | C22: 0.015 | D22: 0.01 | E22: 0.025 | F22: =CHOOSE(MATCH('Assumptions'!$C$4,{"Base","Upside","Downside"},0),C22,D22,E22) -> 0 | G22: Share of beginning Growth customers lost each month.
A23: Growth usage per customer, month 1 | B23: M req/mo | C23: 25 | D23: 28 | E23: 22 | F23: =CHOOSE(MATCH('Assumptions'!$C$4,{"Base","Upside","Downside"},0),C23,D23,E23) -> 0 | G23: Average monthly inference request-equivalents per active Growth customer.
A24: Growth usage growth per customer, month over month | B24: % | C24: 0.0307 | D24: 0.0596 | E24: 0.0119 | F24: =CHOOSE(MATCH('Assumptions'!$C$4,{"Base","Upside","Downside"},0),C24,D24,E24) -> 0 | G24: Growth in monthly usage intensity per Growth customer.
... A30: Enterprise usage growth per customer, month over month | B30: % | C30: 0.0282 | D30: 0.0471 | E30: 0.0131 | F30: =CHOOSE(MATCH('Assumptions'!$C$4,{"Base","Upside","Downside"},0),C30,D30,E30) -> 0 | G30: Growth in monthly usage intensity per Enterprise customer.
A32: Pricing & Unit Economics
A33: Standard-model list price per 1M requests | B33: $/M req | C33: 2200 | D33: 2350 | E33: 2050 | F33: =CHOOSE(MATCH('Assumptions'!$C$4,{"Base","Upside","Downside"},0),C33,D33,E33) -> 0 | G33: Realized before tier multipliers and discounting.
A34: Premium-model list price per 1M requests | B34: $/M req | C34: 5000 | D34: 5250 | E34: 4750 | F34: =CHOOSE(MATCH('Assumptions'!$C$4,{"Base","Upside","Downside"},0),C34,D34,E34) -> 0 | G34: Higher-value reasoning / multimodal request pricing.
A35: Premium-model mix, month 1 | B35: % | C35: 0.25 | D35: 0.32 | E35: 0.18 | F35: =CHOOSE(MATCH('Assumptions'!$C$4,{"Base","Upside","Downside"},0),C35,D35,E35) -> 0 | G35: Share of usage billed on premium models at the start of the model.
A36: Premium-model mix shift, month over month | B36: % | C36: 0.0038 | D36: 0.0057 | E36: 0.0009 | F36: =CHOOSE(MATCH('Assumptions'!$C$4,{"Base","Upside","Downside"},0),C36,D36,E36) -> 0 | G36: Monthly change in premium-model mix; capped inside the model.
A37: Starter realized price multiplier | B37: x | C37: 0.85 | D37: 0.88 | E37: 0.82 | F37: =CHOOSE(MATCH('Assumptions'!$C$4,{"Base","Upside","Downside"},0),C37,D37,E37) -> 0 | G37: Discounted vs blended list price due to lower ACV and promotional pricing.
A38: Growth realized price multiplier | B38: x | C38: 1 | D38: 1.03 | E38: 0.97 | F38: =CHOOSE(MATCH('Assumptions'!$C$4,{"Base","Upside","Downside"},0),C38,D38,E38) -> 0 | G38: Mid-market customers roughly at blended list price.
A39: Enterprise realized price multiplier | B39: x | C39: 1.18 | D39: 1.22 | E39: 1.12 | F39: =CHOOSE(MATCH('Assumptions'!$C$4,{"Base","Upside","Downside"},0),C39,D39,E39) -> 0 | G39: Premium for SLA, throughput, and higher-value workloads.
A40: Committed-use / volume discount rate | B40: % | C40: 0.08 | D40: 0.06 | E40: 0.12 | F40: =CHOOSE(MATCH('Assumptions'!$C$4,{"Base","Upside","Downside"},0),C40,D40,E40) -> 0 | G40: Blended discount off list price for annual commits and committed capacity.
A41: Cache hit rate | B41: % | C41: 0.18 | D41: 0.24 | E41: 0.1 | F41: =CHOOSE(MATCH('Assumptions'!$C$4,{"Base","Upside","Downside"},0),C41,D41,E41) -> 0 | G41: Share of gross requests satisfied by cache rather than fresh inference.
A42: Share of cache benefit passed back to customers | B42: % | C42: 0.35 | D42: 0.25 | E42: 0.45 | F42: =CHOOSE(MATCH('Assumptions'!$C$4,{"Base","Upside","Downside"},0),C42,D42,E42) -> 0 | G42: Portion of cache savings that lowers billable units / effective invoice volume.
A43: Batch / async discount rate | B43: % | C43: 0.07 | D43: 0.1 | E43: 0.03 | F43: =CHOOSE(MATCH('Assumptions'!$C$4,{"Base","Upside","Downside"},0),C43,D43,E43) -> 0 | G43: Effective unit reduction from customers opting into batched / async processing.
A44: Starter platform fee per customer | B44: $/mo | C44: 500 | D44: 600 | E44: 450 | F44: =CHOOSE(MATCH('Assumptions'!$C$4,{"Base","Upside","Downside"},0),C44,D44,E44) -> 0 | G44: Base platform / support fee billed monthly per Starter account.
... A46: Enterprise platform fee per customer | B46: $/mo | C46: 12000 | D46: 14000 | E46: 10000 | F46: =CHOOSE(MATCH('Assumptions'!$C$4,{"Base","Upside","Downside"},0),C46,D46,E46) -> 0 | G46: Base platform / SLA fee billed monthly per Enterprise account.
A48: COGS & Compute Costs
A49: Reserved capacity compute cost per 1M requests | B49: $/M req | C49: 900 | D49: 820 | E49: 1020 | F49: =CHOOSE(MATCH('Assumptions'!$C$4,{"Base","Upside","Downside"},0),C49,D49,E49) -> 0 | G49: At target utilization; actual effective cost is adjusted by utilization.
A50: On-demand compute cost per 1M requests | B50: $/M req | C50: 1500 | D50: 1380 | E50: 1700 | F50: =CHOOSE(MATCH('Assumptions'!$C$4,{"Base","Upside","Downside"},0),C50,D50,E50) -> 0 | G50: Pay-as-you-go compute cost for overflow / burst workloads.
A51: External model/API cost per 1M standard requests | B51: $/M req | C51: 400 | D51: 360 | E51: 470 | F51: =CHOOSE(MATCH('Assumptions'!$C$4,{"Base","Upside","Downside"},0),C51,D51,E51) -> 0 | G51: Third-party inference / foundation-model provider cost.
...

Sheet Headcount
A1: AI API / Infrastructure — 3-Year Financial Model — Headcount
A2: Fully-loaded FTE ramps by role — flows into COGS or Opex by classification.
A5: Line item | B5: Units / source | C5: Monthly (36 months) | AN5: Quarterly | BA5: Annual
C6: 46023 | D6: 46054 | E6: 46082 | F6: 46113 | G6: 46143 | H6: 46174 | I6: 46204 | J6: 46235 | K6: 46266 | L6: 46296 | M6: 46327 | N6: 46357 | O6: 46388 | P6: 46419 | Q6: 46447 | R6: 46478 | S6: 46508 | T6: 46539 | U6: 46569 | V6: 46600 | W6: 46631 | X6: 46661 | Y6: 46692 | Z6: 46722 | AA6: 46753 | AB6: 46784 | AC6: 46813 | AD6: 46844 | AE6: 46874 | AF6: 46905 | AG6: 46935 | AH6: 46966 | AI6: 46997 | AJ6: 47027 | AK6: 47058 | AL6: 47088 | AN6: Q1 | AO6: Q2 | AP6: Q3 | AQ6: Q4 | AR6: Q5 | AS6: Q6 | AT6: Q7 | AU6: Q8 | AV6: Q9 | AW6: Q10 | AX6: Q11 | AY6: Q12 | BA6: FY1 | BB6: FY2 | BC6: FY3
A7: Cost of Goods Sold headcount (COGS-classified)
A8: Infrastructure / SRE — headcount (FTE) | B8: Cost of Revenue · start + net adds/qtr ÷ 3 | C8: =ROUND('Assumptions'!$F$60,1) -> 0 | D8: =ROUND(C8+'Assumptions'!$F$61/3,1) -> 0 | E8: =ROUND(D8+'Assumptions'!$F$61/3,1) -> 0 | F8: =ROUND(E8+'Assumptions'!$F$61/3,1) -> 0 | G8: =ROUND(F8+'Assumptions'!$F$61/3,1) -> 0 | H8: =ROUND(G8+'Assumptions'!$F$61/3,1) -> 0 | I8: =ROUND(H8+'Assumptions'!$F$61/3,1) -> 0 | J8: =ROUND(I8+'Assumptions'!$F$61/3,1) -> 0 | K8: =ROUND(J8+'Assumptions'!$F$61/3,1) -> 0 | ... AL8: =ROUND(AK8+'Assumptions'!$F$61/3,1) -> 0 | AN8: =E8 -> 0 | AO8: =H8 -> 0 | AP8: =K8 -> 0 | AQ8: =N8 -> 0 | AR8: =Q8 -> 0 | AS8: =T8 -> 0 | AT8: =W8 -> 0 | AU8: =Z8 -> 0 | AV8: =AC8 -> 0 | AW8: =AF8 -> 0 | AX8: =AI8 -> 0 | AY8: =AL8 -> 0 | BA8: =N8 -> 0 | BB8: =Z8 -> 0 | BC8: =AL8 -> 0
A9: Infrastructure / SRE — fully-loaded cost | B9: Headcount × monthly fully-loaded cost/FTE | C9: =C8*'Assumptions'!$F$62 -> 0 | D9: =D8*'Assumptions'!$F$62 -> 0 | E9: =E8*'Assumptions'!$F$62 -> 0 | F9: =F8*'Assumptions'!$F$62 -> 0 | G9: =G8*'Assumptions'!$F$62 -> 0 | H9: =H8*'Assumptions'!$F$62 -> 0 | I9: =I8*'Assumptions'!$F$62 -> 0 | J9: =J8*'Assumptions'!$F$62 -> 0 | ... AL9: =AL8*'Assumptions'!$F$62 -> 0 | AN9: =SUM(C9:E9) -> 0 | AO9: =SUM(F9:H9) -> 0 | AP9: =SUM(I9:K9) -> 0 | AQ9: =SUM(L9:N9) -> 0 | AR9: =SUM(O9:Q9) -> 0 | AS9: =SUM(R9:T9) -> 0 | AT9: =SUM(U9:W9) -> 0 | AU9: =SUM(X9:Z9) -> 0 | AV9: =SUM(AA9:AC9) -> 0 | AW9: =SUM(AD9:AF9) -> 0 | AX9: =SUM(AG9:AI9) -> 0 | AY9: =SUM(AJ9:AL9) -> 0 | BA9: =SUM(C9:N9) -> 0 | BB9: =SUM(O9:Z9) -> 0 | BC9: =SUM(AA9:AL9) -> 0
A11: Operating expense headcount (Opex-classified)
A12: Model Engineering / Applied Research — headcount (FTE) | B12: R&D / Engineering · start + net adds/qtr ÷ 3 | C12: =ROUND('Assumptions'!$F$65,1) -> 0 | D12: =ROUND(C12+'Assumptions'!$F$66/3,1) -> 0 | E12: =ROUND(D12+'Assumptions'!$F$66/3,1) -> 0 | F12: =ROUND(E12+'Assumptions'!$F$66/3,1) -> 0 | G12: =ROUND(F12+'Assumptions'!$F$66/3,1) -> 0 | H12: =ROUND(G12+'Assumptions'!$F$66/3,1) -> 0 | I12: =ROUND(H12+'Assumptions'!$F$66/3,1) -> 0 | J12: =ROUND(I12+'Assumptions'!$F$66/3,1) -> 0 | K12: =ROUND(J12+'Assumptions'!$F$66/3,1) -> 0 | ... AL12: =ROUND(AK12+'Assumptions'!$F$66/3,1) -> 0 | AN12: =E12 -> 0 | AO12: =H12 -> 0 | AP12: =K12 -> 0 | AQ12: =N12 -> 0 | AR12: =Q12 -> 0 | AS12: =T12 -> 0 | AT12: =W12 -> 0 | AU12: =Z12 -> 0 | AV12: =AC12 -> 0 | AW12: =AF12 -> 0 | AX12: =AI12 -> 0 | AY12: =AL12 -> 0 | BA12: =N12 -> 0 | BB12: =Z12 -> 0 | BC12: =AL12 -> 0
A13: Model Engineering / Applied Research — fully-loaded cost | B13: Headcount × monthly fully-loaded cost/FTE | C13: =C12*'Assumptions'!$F$67 -> 0 | D13: =D12*'Assumptions'!$F$67 -> 0 | E13: =E12*'Assumptions'!$F$67 -> 0 | F13: =F12*'Assumptions'!$F$67 -> 0 | G13: =G12*'Assumptions'!$F$67 -> 0 | H13: =H12*'Assumptions'!$F$67 -> 0 | I13: =I12*'Assumptions'!$F$67 -> 0 | J13: =J12*'Assumptions'!$F$67 -> 0 | ... AL13: =AL12*'Assumptions'!$F$67 -> 0 | AN13: =SUM(C13:E13) -> 0 | AO13: =SUM(F13:H13) -> 0 | AP13: =SUM(I13:K13) -> 0 | AQ13: =SUM(L13:N13) -> 0 | AR13: =SUM(O13:Q13) -> 0 | AS13: =SUM(R13:T13) -> 0 | AT13: =SUM(U13:W13) -> 0 | AU13: =SUM(X13:Z13) -> 0 | AV13: =SUM(AA13:AC13) -> 0 | AW13: =SUM(AD13:AF13) -> 0 | AX13: =SUM(AG13:AI13) -> 0 | AY13: =SUM(AJ13:AL13) -> 0 | BA13: =SUM(C13:N13) -> 0 | BB13: =SUM(O13:Z13) -> 0 | BC13: =SUM(AA13:AL13) -> 0
A14: GTM / Sales — headcount (FTE) | B14: Sales & Marketing · start + net adds/qtr ÷ 3 | C14: =ROUND('Assumptions'!$F$70,1) -> 0 | D14: =ROUND(C14+'Assumptions'!$F$71/3,1) -> 0 | E14: =ROUND(D14+'Assumptions'!$F$71/3,1) -> 0 | F14: =ROUND(E14+'Assumptions'!$F$71/3,1) -> 0 | G14: =ROUND(F14+'Assumptions'!$F$71/3,1) -> 0 | H14: =ROUND(G14+'Assumptions'!$F$71/3,1) -> 0 | I14: =ROUND(H14+'Assumptions'!$F$71/3,1) -> 0 | J14: =ROUND(I14+'Assumptions'!$F$71/3,1) -> 0 | K14: =ROUND(J14+'Assumptions'!$F$71/3,1) -> 0 | ... AL14: =ROUND(AK14+'Assumptions'!$F$71/3,1) -> 0 | AN14: =E14 -> 0 | AO14: =H14 -> 0 | AP14: =K14 -> 0 | AQ14: =N14 -> 0 | AR14: =Q14 -> 0 | AS14: =T14 -> 0 | AT14: =W14 -> 0 | AU14: =Z14 -> 0 | AV14: =AC14 -> 0 | AW14: =AF14 -> 0 | AX14: =AI14 -> 0 | AY14: =AL14 -> 0 | BA14: =N14 -> 0 | BB14: =Z14 -> 0 | BC14: =AL14 -> 0
A15: GTM / Sales — fully-loaded cost | B15: Headcount × monthly fully-loaded cost/FTE | C15: =C14*'Assumptions'!$F$72 -> 0 | D15: =D14*'Assumptions'!$F$72 -> 0 | E15: =E14*'Assumptions'!$F$72 -> 0 | F15: =F14*'Assumptions'!$F$72 -> 0 | G15: =G14*'Assumptions'!$F$72 -> 0 | H15: =H14*'Assumptions'!$F$72 -> 0 | I15: =I14*'Assumptions'!$F$72 -> 0 | J15: =J14*'Assumptions'!$F$72 -> 0 | ... AL15: =AL14*'Assumptions'!$F$72 -> 0 | AN15: =SUM(C15:E15) -> 0 | AO15: =SUM(F15:H15) -> 0 | AP15: =SUM(I15:K15) -> 0 | AQ15: =SUM(L15:N15) -> 0 | AR15: =SUM(O15:Q15) -> 0 | AS15: =SUM(R15:T15) -> 0 | AT15: =SUM(U15:W15) -> 0 | AU15: =SUM(X15:Z15) -> 0 | AV15: =SUM(AA15:AC15) -> 0 | AW15: =SUM(AD15:AF15) -> 0 | AX15: =SUM(AG15:AI15) -> 0 | AY15: =SUM(AJ15:AL15) -> 0 | BA15: =SUM(C15:N15) -> 0 | BB15: =SUM(O15:Z15) -> 0 | BC15: =SUM(AA15:AL15) -> 0
A16: G&A (Finance / HR / Ops) — headcount (FTE) | B16: General & Administrative · start + net adds/qtr ÷ 3 | C16: =ROUND('Assumptions'!$F$75,1) -> 0 | D16: =ROUND(C16+'Assumptions'!$F$76/3,1) -> 0 | E16: =ROUND(D16+'Assumptions'!$F$76/3,1) -> 0 | F16: =ROUND(E16+'Assumptions'!$F$76/3,1) -> 0 | G16: =ROUND(F16+'Assumptions'!$F$76/3,1) -> 0 | H16: =ROUND(G16+'Assumptions'!$F$76/3,1) -> 0 | I16: =ROUND(H16+'Assumptions'!$F$76/3,1) -> 0 | J16: =ROUND(I16+'Assumptions'!$F$76/3,1) -> 0 | K16: =ROUND(J16+'Assumptions'!$F$76/3,1) -> 0 | ... AL16: =ROUND(AK16+'Assumptions'!$F$76/3,1) -> 0 | AN16: =E16 -> 0 | AO16: =H16 -> 0 | AP16: =K16 -> 0 | AQ16: =N16 -> 0 | AR16: =Q16 -> 0 | AS16: =T16 -> 0 | AT16: =W16 -> 0 | AU16: =Z16 -> 0 | AV16: =AC16 -> 0 | AW16: =AF16 -> 0 | AX16: =AI16 -> 0 | AY16: =AL16 -> 0 | BA16: =N16 -> 0 | BB16: =Z16 -> 0 | BC16: =AL16 -> 0
A17: G&A (Finance / HR / Ops) — fully-loaded cost | B17: Headcount × monthly fully-loaded cost/FTE | C17: =C16*'Assumptions'!$F$77 -> 0 | D17: =D16*'Assumptions'!$F$77 -> 0 | E17: =E16*'Assumptions'!$F$77 -> 0 | F17: =F16*'Assumptions'!$F$77 -> 0 | G17: =G16*'Assumptions'!$F$77 -> 0 | H17: =H16*'Assumptions'!$F$77 -> 0 | I17: =I16*'Assumptions'!$F$77 -> 0 | J17: =J16*'Assumptions'!$F$77 -> 0 | ... AL17: =AL16*'Assumptions'!$F$77 -> 0 | AN17: =SUM(C17:E17) -> 0 | AO17: =SUM(F17:H17) -> 0 | AP17: =SUM(I17:K17) -> 0 | AQ17: =SUM(L17:N17) -> 0 | AR17: =SUM(O17:Q17) -> 0 | AS17: =SUM(R17:T17) -> 0 | AT17: =SUM(U17:W17) -> 0 | AU17: =SUM(X17:Z17) -> 0 | AV17: =SUM(AA17:AC17) -> 0 | AW17: =SUM(AD17:AF17) -> 0 | AX17: =SUM(AG17:AI17) -> 0 | AY17: =SUM(AJ17:AL17) -> 0 | BA17: =SUM(C17:N17) -> 0 | BB17: =SUM(O17:Z17) -> 0 | BC17: =SUM(AA17:AL17) -> 0
A19: Totals
A20: Total headcount (FTE) | B20: Sum of all roles | C20: =C8+C12+C14+C16 -> 0 | D20: =D8+D12+D14+D16 -> 0 | E20: =E8+E12+E14+E16 -> 0 | F20: =F8+F12+F14+F16 -> 0 | G20: =G8+G12+G14+G16 -> 0 | H20: =H8+H12+H14+H16 -> 0 | I20: =I8+I12+I14+I16 -> 0 | J20: =J8+J12+J14+J16 -> 0 | ... AL20: =AL8+AL12+AL14+AL16 -> 0 | AN20: =E20 -> 0 | AO20: =H20 -> 0 | AP20: =K20 -> 0 | AQ20: =N20 -> 0 | AR20: =Q20 -> 0 | AS20: =T20 -> 0 | AT20: =W20 -> 0 | AU20: =Z20 -> 0 | AV20: =AC20 -> 0 | AW20: =AF20 -> 0 | AX20: =AI20 -> 0 | AY20: =AL20 -> 0 | BA20: =N20 -> 0 | BB20: =Z20 -> 0 | BC20: =AL20 -> 0
A21: Total COGS-classified people cost | B21: Feeds COGS & GM tab | C21: =C9 -> 0 | D21: =D9 -> 0 | E21: =E9 -> 0 | F21: =F9 -> 0 | G21: =G9 -> 0 | H21: =H9 -> 0 | I21: =I9 -> 0 | J21: =J9 -> 0 | ... AL21: =AL9 -> 0 | AN21: =SUM(C21:E21) -> 0 | AO21: =SUM(F21:H21) -> 0 | AP21: =SUM(I21:K21) -> 0 | AQ21: =SUM(L21:N21) -> 0 | AR21: =SUM(O21:Q21) -> 0 | AS21: =SUM(R21:T21) -> 0 | AT21: =SUM(U21:W21) -> 0 | AU21: =SUM(X21:Z21) -> 0 | AV21: =SUM(AA21:AC21) -> 0 | AW21: =SUM(AD21:AF21) -> 0 | AX21: =SUM(AG21:AI21) -> 0 | AY21: =SUM(AJ21:AL21) -> 0 | BA21: =SUM(C21:N21) -> 0 | BB21: =SUM(O21:Z21) -> 0 | BC21: =SUM(AA21:AL21) -> 0
A22: Total Opex-classified people cost | B22: Feeds Opex tab | C22: =C13+C15+C17 -> 0 | D22: =D13+D15+D17 -> 0 | E22: =E13+E15+E17 -> 0 | F22: =F13+F15+F17 -> 0 | G22: =G13+G15+G17 -> 0 | H22: =H13+H15+H17 -> 0 | I22: =I13+I15+I17 -> 0 | J22: =J13+J15+J17 -> 0 | ... AL22: =AL13+AL15+AL17 -> 0 | AN22: =SUM(C22:E22) -> 0 | AO22: =SUM(F22:H22) -> 0 | AP22: =SUM(I22:K22) -> 0 | AQ22: =SUM(L22:N22) -> 0 | AR22: =SUM(O22:Q22) -> 0 | AS22: =SUM(R22:T22) -> 0 | AT22: =SUM(U22:W22) -> 0 | AU22: =SUM(X22:Z22) -> 0 | AV22: =SUM(AA22:AC22) -> 0 | AW22: =SUM(AD22:AF22) -> 0 | AX22: =SUM(AG22:AI22) -> 0 | AY22: =SUM(AJ22:AL22) -> 0 | BA22: =SUM(C22:N22) -> 0 | BB22: =SUM(O22:Z22) -> 0 | BC22: =SUM(AA22:AL22) -> 0
A23: General & Administrative people cost | C23: =C17 -> 0 | D23: =D17 -> 0 | E23: =E17 -> 0 | F23: =F17 -> 0 | G23: =G17 -> 0 | H23: =H17 -> 0 | I23: =I17 -> 0 | J23: =J17 -> 0 | ... AL23: =AL17 -> 0 | AN23: =SUM(C23:E23) -> 0 | AO23: =SUM(F23:H23) -> 0 | AP23: =SUM(I23:K23) -> 0 | AQ23: =SUM(L23:N23) -> 0 | AR23: =SUM(O23:Q23) -> 0 | AS23: =SUM(R23:T23) -> 0 | AT23: =SUM(U23:W23) -> 0 | AU23: =SUM(X23:Z23) -> 0 | AV23: =SUM(AA23:AC23) -> 0 | AW23: =SUM(AD23:AF23) -> 0 | AX23: =SUM(AG23:AI23) -> 0 | AY23: =SUM(AJ23:AL23) -> 0 | BA23: =SUM(C23:N23) -> 0 | BB23: =SUM(O23:Z23) -> 0 | BC23: =SUM(AA23:AL23) -> 0
A24: R&D / Engineering people cost | C24: =C13 -> 0 | D24: =D13 -> 0 | E24: =E13 -> 0 | F24: =F13 -> 0 | G24: =G13 -> 0 | H24: =H13 -> 0 | I24: =I13 -> 0 | J24: =J13 -> 0 | ... AL24: =AL13 -> 0 | AN24: =SUM(C24:E24) -> 0 | AO24: =SUM(F24:H24) -> 0 | AP24: =SUM(I24:K24) -> 0 | AQ24: =SUM(L24:N24) -> 0 | AR24: =SUM(O24:Q24) -> 0 | AS24: =SUM(R24:T24) -> 0 | AT24: =SUM(U24:W24) -> 0 | AU24: =SUM(X24:Z24) -> 0 | AV24: =SUM(AA24:AC24) -> 0 | AW24: =SUM(AD24:AF24) -> 0 | AX24: =SUM(AG24:AI24) -> 0 | AY24: =SUM(AJ24:AL24) -> 0 | BA24: =SUM(C24:N24) -> 0 | BB24: =SUM(O24:Z24) -> 0 | BC24: =SUM(AA24:AL24) -> 0
A25: Sales & Marketing people cost | C25: =C15 -> 0 | D25: =D15 -> 0 | E25: =E15 -> 0 | F25: =F15 -> 0 | G25: =G15 -> 0 | H25: =H15 -> 0 | I25: =I15 -> 0 | J25: =J15 -> 0 | ... AL25: =AL15 -> 0 | AN25: =SUM(C25:E25) -> 0 | AO25: =SUM(F25:H25) -> 0 | AP25: =SUM(I25:K25) -> 0 | AQ25: =SUM(L25:N25) -> 0 | AR25: =SUM(O25:Q25) -> 0 | AS25: =SUM(R25:T25) -> 0 | AT25: =SUM(U25:W25) -> 0 | AU25: =SUM(X25:Z25) -> 0 | AV25: =SUM(AA25:AC25) -> 0 | AW25: =SUM(AD25:AF25) -> 0 | AX25: =SUM(AG25:AI25) -> 0 | AY25: =SUM(AJ25:AL25) -> 0 | BA25: =SUM(C25:N25) -> 0 | BB25: =SUM(O25:Z25) -> 0 | BC25: =SUM(AA25:AL25) -> 0

Sheet Revenue
A1: AI API / Infrastructure — 3-Year Financial Model — Revenue
A2: Tiered customer bridge -> usage volume -> blended realized pricing -> usage + platform revenue.
A5: Line item | B5: Units / source | C5: Monthly (36 months) | AN5: Quarterly | BA5: Annual
C6: 46023 | D6: 46054 | E6: 46082 | F6: 46113 | G6: 46143 | H6: 46174 | I6: 46204 | J6: 46235 | K6: 46266 | L6: 46296 | M6: 46327 | N6: 46357 | O6: 46388 | P6: 46419 | Q6: 46447 | R6: 46478 | S6: 46508 | T6: 46539 | U6: 46569 | V6: 46600 | W6: 46631 | X6: 46661 | Y6: 46692 | Z6: 46722 | AA6: 46753 | AB6: 46784 | AC6: 46813 | AD6: 46844 | AE6: 46874 | AF6: 46905 | AG6: 46935 | AH6: 46966 | AI6: 46997 | AJ6: 47027 | AK6: 47058 | AL6: 47088 | AN6: Q1 | AO6: Q2 | AP6: Q3 | AQ6: Q4 | AR6: Q5 | AS6: Q6 | AT6: Q7 | AU6: Q8 | AV6: Q9 | AW6: Q10 | AX6: Q11 | AY6: Q12 | BA6: FY1 | BB6: FY2 | BC6: FY3
A7: Starter Tier
A8: Starter beginning customers | C8: ='Assumptions'!$F$13 -> 0 | D8: =C11 -> 0 | E8: =D11 -> 0 | F8: =E11 -> 0 | G8: =F11 -> 0 | H8: =G11 -> 0 | I8: =H11 -> 0 | J8: =I11 -> 0 | K8: =J11 -> 0 | ... AL8: =AK11 -> 0 | AN8: =E8 -> 0 | AO8: =H8 -> 0 | AP8: =K8 -> 0 | AQ8: =N8 -> 0 | AR8: =Q8 -> 0 | AS8: =T8 -> 0 | AT8: =W8 -> 0 | AU8: =Z8 -> 0 | AV8: =AC8 -> 0 | AW8: =AF8 -> 0 | AX8: =AI8 -> 0 | AY8: =AL8 -> 0 | BA8: =N8 -> 0 | BB8: =Z8 -> 0 | BC8: =AL8 -> 0
A9: Starter new customers | C9: ='Assumptions'!$F$14 -> 0 | D9: =C9*(1+'Assumptions'!$F$15) -> 0 | E9: =D9*(1+'Assumptions'!$F$15) -> 0 | F9: =E9*(1+'Assumptions'!$F$15) -> 0 | G9: =F9*(1+'Assumptions'!$F$15) -> 0 | H9: =G9*(1+'Assumptions'!$F$15) -> 0 | I9: =H9*(1+'Assumptions'!$F$15) -> 0 | J9: =I9*(1+'Assumptions'!$F$15) -> 0 | K9: =J9*(1+'Assumptions'!$F$15) -> 0 | ... AL9: =AK9*(1+'Assumptions'!$F$15) -> 0 | AN9: =SUM(C9:E9) -> 0 | AO9: =SUM(F9:H9) -> 0 | AP9: =SUM(I9:K9) -> 0 | AQ9: =SUM(L9:N9) -> 0 | AR9: =SUM(O9:Q9) -> 0 | AS9: =SUM(R9:T9) -> 0 | AT9: =SUM(U9:W9) -> 0 | AU9: =SUM(X9:Z9) -> 0 | AV9: =SUM(AA9:AC9) -> 0 | AW9: =SUM(AD9:AF9) -> 0 | AX9: =SUM(AG9:AI9) -> 0 | AY9: =SUM(AJ9:AL9) -> 0 | BA9: =SUM(C9:N9) -> 0 | BB9: =SUM(O9:Z9) -> 0 | BC9: =SUM(AA9:AL9) -> 0
A10: Starter churned customers | C10: =-C8*'Assumptions'!$F$16 -> 0 | D10: =-D8*'Assumptions'!$F$16 -> 0 | E10: =-E8*'Assumptions'!$F$16 -> 0 | F10: =-F8*'Assumptions'!$F$16 -> 0 | G10: =-G8*'Assumptions'!$F$16 -> 0 | H10: =-H8*'Assumptions'!$F$16 -> 0 | I10: =-I8*'Assumptions'!$F$16 -> 0 | J10: =-J8*'Assumptions'!$F$16 -> 0 | ... AL10: =-AL8*'Assumptions'!$F$16 -> 0 | AN10: =SUM(C10:E10) -> 0 | AO10: =SUM(F10:H10) -> 0 | AP10: =SUM(I10:K10) -> 0 | AQ10: =SUM(L10:N10) -> 0 | AR10: =SUM(O10:Q10) -> 0 | AS10: =SUM(R10:T10) -> 0 | AT10: =SUM(U10:W10) -> 0 | AU10: =SUM(X10:Z10) -> 0 | AV10: =SUM(AA10:AC10) -> 0 | AW10: =SUM(AD10:AF10) -> 0 | AX10: =SUM(AG10:AI10) -> 0 | AY10: =SUM(AJ10:AL10) -> 0 | BA10: =SUM(C10:N10) -> 0 | BB10: =SUM(O10:Z10) -> 0 | BC10: =SUM(AA10:AL10) -> 0
A11: Starter ending customers | C11: =C8+C9+C10 -> 0 | D11: =D8+D9+D10 -> 0 | E11: =E8+E9+E10 -> 0 | F11: =F8+F9+F10 -> 0 | G11: =G8+G9+G10 -> 0 | H11: =H8+H9+H10 -> 0 | I11: =I8+I9+I10 -> 0 | J11: =J8+J9+J10 -> 0 | ... AL11: =AL8+AL9+AL10 -> 0 | AN11: =E11 -> 0 | AO11: =H11 -> 0 | AP11: =K11 -> 0 | AQ11: =N11 -> 0 | AR11: =Q11 -> 0 | AS11: =T11 -> 0 | AT11: =W11 -> 0 | AU11: =Z11 -> 0 | AV11: =AC11 -> 0 | AW11: =AF11 -> 0 | AX11: =AI11 -> 0 | AY11: =AL11 -> 0 | BA11: =N11 -> 0 | BB11: =Z11 -> 0 | BC11: =AL11 -> 0
A12: Starter usage per customer | B12: Monthly inference request-equivalents in millions | C12: ='Assumptions'!$F$17 -> 0 | D12: =C12*(1+'Assumptions'!$F$18) -> 0 | E12: =D12*(1+'Assumptions'!$F$18) -> 0 | F12: =E12*(1+'Assumptions'!$F$18) -> 0 | G12: =F12*(1+'Assumptions'!$F$18) -> 0 | H12: =G12*(1+'Assumptions'!$F$18) -> 0 | I12: =H12*(1+'Assumptions'!$F$18) -> 0 | J12: =I12*(1+'Assumptions'!$F$18) -> 0 | K12: =J12*(1+'Assumptions'!$F$18) -> 0 | ... AL12: =AK12*(1+'Assumptions'!$F$18) -> 0 | AN12: =AVERAGE(C12:E12) -> 0 | AO12: =AVERAGE(F12:H12) -> 0 | AP12: =AVERAGE(I12:K12) -> 0 | AQ12: =AVERAGE(L12:N12) -> 0 | AR12: =AVERAGE(O12:Q12) -> 0 | AS12: =AVERAGE(R12:T12) -> 0 | AT12: =AVERAGE(U12:W12) -> 0 | AU12: =AVERAGE(X12:Z12) -> 0 | AV12: =AVERAGE(AA12:AC12) -> 0 | AW12: =AVERAGE(AD12:AF12) -> 0 | AX12: =AVERAGE(AG12:AI12) -> 0 | AY12: =AVERAGE(AJ12:AL12) -> 0 | BA12: =AVERAGE(C12:N12) -> 0 | BB12: =AVERAGE(O12:Z12) -> 0 | BC12: =AVERAGE(AA12:AL12) -> 0
A13: Starter gross request volume | B13: Active customers × usage per customer (M requests) | C13: =C11*C12 -> 0 | D13: =D11*D12 -> 0 | E13: =E11*E12 -> 0 | F13: =F11*F12 -> 0 | G13: =G11*G12 -> 0 | H13: =H11*H12 -> 0 | I13: =I11*I12 -> 0 | J13: =J11*J12 -> 0 | ... AL13: =AL11*AL12 -> 0 | AN13: =SUM(C13:E13) -> 0 | AO13: =SUM(F13:H13) -> 0 | AP13: =SUM(I13:K13) -> 0 | AQ13: =SUM(L13:N13) -> 0 | AR13: =SUM(O13:Q13) -> 0 | AS13: =SUM(R13:T13) -> 0 | AT13: =SUM(U13:W13) -> 0 | AU13: =SUM(X13:Z13) -> 0 | AV13: =SUM(AA13:AC13) -> 0 | AW13: =SUM(AD13:AF13) -> 0 | AX13: =SUM(AG13:AI13) -> 0 | AY13: =SUM(AJ13:AL13) -> 0 | BA13: =SUM(C13:N13) -> 0 | BB13: =SUM(O13:Z13) -> 0 | BC13: =SUM(AA13:AL13) -> 0
A15: Growth Tier
A16: Growth beginning customers | C16: ='Assumptions'!$F$19 -> 0 | D16: =C19 -> 0 | E16: =D19 -> 0 | F16: =E19 -> 0 | G16: =F19 -> 0 | H16: =G19 -> 0 | I16: =H19 -> 0 | J16: =I19 -> 0 | K16: =J19 -> 0 | ... AL16: =AK19 -> 0 | AN16: =E16 -> 0 | AO16: =H16 -> 0 | AP16: =K16 -> 0 | AQ16: =N16 -> 0 | AR16: =Q16 -> 0 | AS16: =T16 -> 0 | AT16: =W16 -> 0 | AU16: =Z16 -> 0 | AV16: =AC16 -> 0 | AW16: =AF16 -> 0 | AX16: =AI16 -> 0 | AY16: =AL16 -> 0 | BA16: =N16 -> 0 | BB16: =Z16 -> 0 | BC16: =AL16 -> 0
A17: Growth new customers | C17: ='Assumptions'!$F$20 -> 0 | D17: =C17*(1+'Assumptions'!$F$21) -> 0 | E17: =D17*(1+'Assumptions'!$F$21) -> 0 | F17: =E17*(1+'Assumptions'!$F$21) -> 0 | G17: =F17*(1+'Assumptions'!$F$21) -> 0 | H17: =G17*(1+'Assumptions'!$F$21) -> 0 | I17: =H17*(1+'Assumptions'!$F$21) -> 0 | J17: =I17*(1+'Assumptions'!$F$21) -> 0 | K17: =J17*(1+'Assumptions'!$F$21) -> 0 | ... AL17: =AK17*(1+'Assumptions'!$F$21) -> 0 | AN17: =SUM(C17:E17) -> 0 | AO17: =SUM(F17:H17) -> 0 | AP17: =SUM(I17:K17) -> 0 | AQ17: =SUM(L17:N17) -> 0 | AR17: =SUM(O17:Q17) -> 0 | AS17: =SUM(R17:T17) -> 0 | AT17: =SUM(U17:W17) -> 0 | AU17: =SUM(X17:Z17) -> 0 | AV17: =SUM(AA17:AC17) -> 0 | AW17: =SUM(AD17:AF17) -> 0 | AX17: =SUM(AG17:AI17) -> 0 | AY17: =SUM(AJ17:AL17) -> 0 | BA17: =SUM(C17:N17) -> 0 | BB17: =SUM(O17:Z17) -> 0 | BC17: =SUM(AA17:AL17) -> 0
A18: Growth churned customers | C18: =-C16*'Assumptions'!$F$22 -> 0 | D18: =-D16*'Assumptions'!$F$22 -> 0 | E18: =-E16*'Assumptions'!$F$22 -> 0 | F18: =-F16*'Assumptions'!$F$22 -> 0 | G18: =-G16*'Assumptions'!$F$22 -> 0 | H18: =-H16*'Assumptions'!$F$22 -> 0 | I18: =-I16*'Assumptions'!$F$22 -> 0 | J18: =-J16*'Assumptions'!$F$22 -> 0 | ... AL18: =-AL16*'Assumptions'!$F$22 -> 0 | AN18: =SUM(C18:E18) -> 0 | AO18: =SUM(F18:H18) -> 0 | AP18: =SUM(I18:K18) -> 0 | AQ18: =SUM(L18:N18) -> 0 | AR18: =SUM(O18:Q18) -> 0 | AS18: =SUM(R18:T18) -> 0 | AT18: =SUM(U18:W18) -> 0 | AU18: =SUM(X18:Z18) -> 0 | AV18: =SUM(AA18:AC18) -> 0 | AW18: =SUM(AD18:AF18) -> 0 | AX18: =SUM(AG18:AI18) -> 0 | AY18: =SUM(AJ18:AL18) -> 0 | BA18: =SUM(C18:N18) -> 0 | BB18: =SUM(O18:Z18) -> 0 | BC18: =SUM(AA18:AL18) -> 0
A19: Growth ending customers | C19: =C16+C17+C18 -> 0 | D19: =D16+D17+D18 -> 0 | E19: =E16+E17+E18 -> 0 | F19: =F16+F17+F18 -> 0 | G19: =G16+G17+G18 -> 0 | H19: =H16+H17+H18 -> 0 | I19: =I16+I17+I18 -> 0 | J19: =J16+J17+J18 -> 0 | ... AL19: =AL16+AL17+AL18 -> 0 | AN19: =E19 -> 0 | AO19: =H19 -> 0 | AP19: =K19 -> 0 | AQ19: =N19 -> 0 | AR19: =Q19 -> 0 | AS19: =T19 -> 0 | AT19: =W19 -> 0 | AU19: =Z19 -> 0 | AV19: =AC19 -> 0 | AW19: =AF19 -> 0 | AX19: =AI19 -> 0 | AY19: =AL19 -> 0 | BA19: =N19 -> 0 | BB19: =Z19 -> 0 | BC19: =AL19 -> 0
A20: Growth usage per customer | B20: Monthly inference request-equivalents in millions | C20: ='Assumptions'!$F$23 -> 0 | D20: =C20*(1+'Assumptions'!$F$24) -> 0 | E20: =D20*(1+'Assumptions'!$F$24) -> 0 | F20: =E20*(1+'Assumptions'!$F$24) -> 0 | G20: =F20*(1+'Assumptions'!$F$24) -> 0 | H20: =G20*(1+'Assumptions'!$F$24) -> 0 | I20: =H20*(1+'Assumptions'!$F$24) -> 0 | J20: =I20*(1+'Assumptions'!$F$24) -> 0 | K20: =J20*(1+'Assumptions'!$F$24) -> 0 | ... AL20: =AK20*(1+'Assumptions'!$F$24) -> 0 | AN20: =AVERAGE(C20:E20) -> 0 | AO20: =AVERAGE(F20:H20) -> 0 | AP20: =AVERAGE(I20:K20) -> 0 | AQ20: =AVERAGE(L20:N20) -> 0 | AR20: =AVERAGE(O20:Q20) -> 0 | AS20: =AVERAGE(R20:T20) -> 0 | AT20: =AVERAGE(U20:W20) -> 0 | AU20: =AVERAGE(X20:Z20) -> 0 | AV20: =AVERAGE(AA20:AC20) -> 0 | AW20: =AVERAGE(AD20:AF20) -> 0 | AX20: =AVERAGE(AG20:AI20) -> 0 | AY20: =AVERAGE(AJ20:AL20) -> 0 | BA20: =AVERAGE(C20:N20) -> 0 | BB20: =AVERAGE(O20:Z20) -> 0 | BC20: =AVERAGE(AA20:AL20) -> 0
A21: Growth gross request volume | B21: Active customers × usage per customer (M requests) | C21: =C19*C20 -> 0 | D21: =D19*D20 -> 0 | E21: =E19*E20 -> 0 | F21: =F19*F20 -> 0 | G21: =G19*G20 -> 0 | H21: =H19*H20 -> 0 | I21: =I19*I20 -> 0 | J21: =J19*J20 -> 0 | ... AL21: =AL19*AL20 -> 0 | AN21: =SUM(C21:E21) -> 0 | AO21: =SUM(F21:H21) -> 0 | AP21: =SUM(I21:K21) -> 0 | AQ21: =SUM(L21:N21) -> 0 | AR21: =SUM(O21:Q21) -> 0 | AS21: =SUM(R21:T21) -> 0 | AT21: =SUM(U21:W21) -> 0 | AU21: =SUM(X21:Z21) -> 0 | AV21: =SUM(AA21:AC21) -> 0 | AW21: =SUM(AD21:AF21) -> 0 | AX21: =SUM(AG21:AI21) -> 0 | AY21: =SUM(AJ21:AL21) -> 0 | BA21: =SUM(C21:N21) -> 0 | BB21: =SUM(O21:Z21) -> 0 | BC21: =SUM(AA21:AL21) -> 0
A23: Enterprise Tier
A24: Enterprise beginning customers | C24: ='Assumptions'!$F$25 -> 0 | D24: =C27 -> 0 | E24: =D27 -> 0 | F24: =E27 -> 0 | G24: =F27 -> 0 | H24: =G27 -> 0 | I24: =H27 -> 0 | J24: =I27 -> 0 | K24: =J27 -> 0 | ... AL24: =AK27 -> 0 | AN24: =E24 -> 0 | AO24: =H24 -> 0 | AP24: =K24 -> 0 | AQ24: =N24 -> 0 | AR24: =Q24 -> 0 | AS24: =T24 -> 0 | AT24: =W24 -> 0 | AU24: =Z24 -> 0 | AV24: =AC24 -> 0 | AW24: =AF24 -> 0 | AX24: =AI24 -> 0 | AY24: =AL24 -> 0 | BA24: =N24 -> 0 | BB24: =Z24 -> 0 | BC24: =AL24 -> 0
A25: Enterprise new customers | C25: ='Assumptions'!$F$26 -> 0 | D25: =C25*(1+'Assumptions'!$F$27) -> 0 | E25: =D25*(1+'Assumptions'!$F$27) -> 0 | F25: =E25*(1+'Assumptions'!$F$27) -> 0 | G25: =F25*(1+'Assumptions'!$F$27) -> 0 | H25: =G25*(1+'Assumptions'!$F$27) -> 0 | I25: =H25*(1+'Assumptions'!$F$27) -> 0 | J25: =I25*(1+'Assumptions'!$F$27) -> 0 | K25: =J25*(1+'Assumptions'!$F$27) -> 0 | ... AL25: =AK25*(1+'Assumptions'!$F$27) -> 0 | AN25: =SUM(C25:E25) -> 0 | AO25: =SUM(F25:H25) -> 0 | AP25: =SUM(I25:K25) -> 0 | AQ25: =SUM(L25:N25) -> 0 | AR25: =SUM(O25:Q25) -> 0 | AS25: =SUM(R25:T25) -> 0 | AT25: =SUM(U25:W25) -> 0 | AU25: =SUM(X25:Z25) -> 0 | AV25: =SUM(AA25:AC25) -> 0 | AW25: =SUM(AD25:AF25) -> 0 | AX25: =SUM(AG25:AI25) -> 0 | AY25: =SUM(AJ25:AL25) -> 0 | BA25: =SUM(C25:N25) -> 0 | BB25: =SUM(O25:Z25) -> 0 | BC25: =SUM(AA25:AL25) -> 0
A26: Enterprise churned customers | C26: =-C24*'Assumptions'!$F$28 -> 0 | D26: =-D24*'Assumptions'!$F$28 -> 0 | E26: =-E24*'Assumptions'!$F$28 -> 0 | F26: =-F24*'Assumptions'!$F$28 -> 0 | G26: =-G24*'Assumptions'!$F$28 -> 0 | H26: =-H24*'Assumptions'!$F$28 -> 0 | I26: =-I24*'Assumptions'!$F$28 -> 0 | J26: =-J24*'Assumptions'!$F$28 -> 0 | ... AL26: =-AL24*'Assumptions'!$F$28 -> 0 | AN26: =SUM(C26:E26) -> 0 | AO26: =SUM(F26:H26) -> 0 | AP26: =SUM(I26:K26) -> 0 | AQ26: =SUM(L26:N26) -> 0 | AR26: =SUM(O26:Q26) -> 0 | AS26: =SUM(R26:T26) -> 0 | AT26: =SUM(U26:W26) -> 0 | AU26: =SUM(X26:Z26) -> 0 | AV26: =SUM(AA26:AC26) -> 0 | AW26: =SUM(AD26:AF26) -> 0 | AX26: =SUM(AG26:AI26) -> 0 | AY26: =SUM(AJ26:AL26) -> 0 | BA26: =SUM(C26:N26) -> 0 | BB26: =SUM(O26:Z26) -> 0 | BC26: =SUM(AA26:AL26) -> 0
A27: Enterprise ending customers | C27: =C24+C25+C26 -> 0 | D27: =D24+D25+D26 -> 0 | E27: =E24+E25+E26 -> 0 | F27: =F24+F25+F26 -> 0 | G27: =G24+G25+G26 -> 0 | H27: =H24+H25+H26 -> 0 | I27: =I24+I25+I26 -> 0 | J27: =J24+J25+J26 -> 0 | ... AL27: =AL24+AL25+AL26 -> 0 | AN27: =E27 -> 0 | AO27: =H27 -> 0 | AP27: =K27 -> 0 | AQ27: =N27 -> 0 | AR27: =Q27 -> 0 | AS27: =T27 -> 0 | AT27: =W27 -> 0 | AU27: =Z27 -> 0 | AV27: =AC27 -> 0 | AW27: =AF27 -> 0 | AX27: =AI27 -> 0 | AY27: =AL27 -> 0 | BA27: =N27 -> 0 | BB27: =Z27 -> 0 | BC27: =AL27 -> 0
A28: Enterprise usage per customer | B28: Monthly inference request-equivalents in millions | C28: ='Assumptions'!$F$29 -> 0 | D28: =C28*(1+'Assumptions'!$F$30) -> 0 | E28: =D28*(1+'Assumptions'!$F$30) -> 0 | F28: =E28*(1+'Assumptions'!$F$30) -> 0 | G28: =F28*(1+'Assumptions'!$F$30) -> 0 | H28: =G28*(1+'Assumptions'!$F$30) -> 0 | I28: =H28*(1+'Assumptions'!$F$30) -> 0 | J28: =I28*(1+'Assumptions'!$F$30) -> 0 | K28: =J28*(1+'Assumptions'!$F$30) -> 0 | ... AL28: =AK28*(1+'Assumptions'!$F$30) -> 0 | AN28: =AVERAGE(C28:E28) -> 0 | AO28: =AVERAGE(F28:H28) -> 0 | AP28: =AVERAGE(I28:K28) -> 0 | AQ28: =AVERAGE(L28:N28) -> 0 | AR28: =AVERAGE(O28:Q28) -> 0 | AS28: =AVERAGE(R28:T28) -> 0 | AT28: =AVERAGE(U28:W28) -> 0 | AU28: =AVERAGE(X28:Z28) -> 0 | AV28: =AVERAGE(AA28:AC28) -> 0 | AW28: =AVERAGE(AD28:AF28) -> 0 | AX28: =AVERAGE(AG28:AI28) -> 0 | AY28: =AVERAGE(AJ28:AL28) -> 0 | BA28: =AVERAGE(C28:N28) -> 0 | BB28: =AVERAGE(O28:Z28) -> 0 | BC28: =AVERAGE(AA28:AL28) -> 0
A29: Enterprise gross request volume | B29: Active customers × usage per customer (M requests) | C29: =C27*C28 -> 0 | D29: =D27*D28 -> 0 | E29: =E27*E28 -> 0 | F29: =F27*F28 -> 0 | G29: =G27*G28 -> 0 | H29: =H27*H28 -> 0 | I29: =I27*I28 -> 0 | J29: =J27*J28 -> 0 | ... AL29: =AL27*AL28 -> 0 | AN29: =SUM(C29:E29) -> 0 | AO29: =SUM(F29:H29) -> 0 | AP29: =SUM(I29:K29) -> 0 | AQ29: =SUM(L29:N29) -> 0 | AR29: =SUM(O29:Q29) -> 0 | AS29: =SUM(R29:T29) -> 0 | AT29: =SUM(U29:W29) -> 0 | AU29: =SUM(X29:Z29) -> 0 | AV29: =SUM(AA29:AC29) -> 0 | AW29: =SUM(AD29:AF29) -> 0 | AX29: =SUM(AG29:AI29) -> 0 | AY29: =SUM(AJ29:AL29) -> 0 | BA29: =SUM(C29:N29) -> 0 | BB29: =SUM(O29:Z29) -> 0 | BC29: =SUM(AA29:AL29) -> 0
A31: Pricing, Volume & Revenue Bridge
A32: Premium-model mix | C32: ='Assumptions'!$F$35 -> 0 | D32: =MIN(0.60,MAX(0.05,C32+'Assumptions'!$F$36)) -> 0 | E32: =MIN(0.60,MAX(0.05,D32+'Assumptions'!$F$36)) -> 0 | F32: =MIN(0.60,MAX(0.05,E32+'Assumptions'!$F$36)) -> 0 | G32: =MIN(0.60,MAX(0.05,F32+'Assumptions'!$F$36)) -> 0 | H32: =MIN(0.60,MAX(0.05,G32+'Assumptions'!$F$36)) -> 0 | I32: =MIN(0.60,MAX(0.05,H32+'Assumptions'!$F$36)) -> 0 | J32: =MIN(0.60,MAX(0.05,I32+'Assumptions'!$F$36)) -> 0 | K32: =MIN(0.60,MAX(0.05,J32+'Assumptions'!$F$36)) -> 0 | ... AL32: =MIN(0.60,MAX(0.05,AK32+'Assumptions'!$F$36)) -> 0 | AN32: =AVERAGE(C32:E32) -> 0 | AO32: =AVERAGE(F32:H32) -> 0 | AP32: =AVERAGE(I32:K32) -> 0 | AQ32: =AVERAGE(L32:N32) -> 0 | AR32: =AVERAGE(O32:Q32) -> 0 | AS32: =AVERAGE(R32:T32) -> 0 | AT32: =AVERAGE(U32:W32) -> 0 | AU32: =AVERAGE(X32:Z32) -> 0 | AV32: =AVERAGE(AA32:AC32) -> 0 | AW32: =AVERAGE(AD32:AF32) -> 0 | AX32: =AVERAGE(AG32:AI32) -> 0 | AY32: =AVERAGE(AJ32:AL32) -> 0 | BA32: =AVERAGE(C32:N32) -> 0 | BB32: =AVERAGE(O32:Z32) -> 0 | BC32: =AVERAGE(AA32:AL32) -> 0
A33: Blended list price per 1M requests | C33: =('Assumptions'!$F$33*(1-C32)+'Assumptions'!$F$34*C32) -> 0 | D33: =('Assumptions'!$F$33*(1-D32)+'Assumptions'!$F$34*D32) -> 0 | E33: =('Assumptions'!$F$33*(1-E32)+'Assumptions'!$F$34*E32) -> 0 | F33: =('Assumptions'!$F$33*(1-F32)+'Assumptions'!$F$34*F32) -> 0 | G33: =('Assumptions'!$F$33*(1-G32)+'Assumptions'!$F$34*G32) -> 0 | H33: =('Assumptions'!$F$33*(1-H32)+'Assumptions'!$F$34*H32) -> 0 | I33: =('Assumptions'!$F$33*(1-I32)+'Assumptions'!$F$34*I32) -> 0 | J33: =('Assumptions'!$F$33*(1-J32)+'Assumptions'!$F$34*J32) -> 0 | ... AL33: =('Assumptions'!$F$33*(1-AL32)+'Assumptions'!$F$34*AL32) -> 0 | AN33: =AVERAGE(C33:E33) -> 0 | AO33: =AVERAGE(F33:H33) -> 0 | AP33: =AVERAGE(I33:K33) -> 0 | AQ33: =AVERAGE(L33:N33) -> 0 | AR33: =AVERAGE(O33:Q33) -> 0 | AS33: =AVERAGE(R33:T33) -> 0 | AT33: =AVERAGE(U33:W33) -> 0 | AU33: =AVERAGE(X33:Z33) -> 0 | AV33: =AVERAGE(AA33:AC33) -> 0 | AW33: =AVERAGE(AD33:AF33) -> 0 | AX33: =AVERAGE(AG33:AI33) -> 0 | AY33: =AVERAGE(AJ33:AL33) -> 0 | BA33: =AVERAGE(C33:N33) -> 0 | BB33: =AVERAGE(O33:Z33) -> 0 | BC33: =AVERAGE(AA33:AL33) -> 0
A34: Billable-volume factor | B34: Gross volume reduced for cache credits and batch discounts | C34: =(1-'Assumptions'!$F$41*'Assumptions'!$F$42)*(1-'Assumptions'!$F$43) -> 0 | D34: =(1-'Assumptions'!$F$41*'Assumptions'!$F$42)*(1-'Assumptions'!$F$43) -> 0 | E34: =(1-'Assumptions'!$F$41*'Assumptions'!$F$42)*(1-'Assumptions'!$F$43) -> 0 | F34: =(1-'Assumptions'!$F$41*'Assumptions'!$F$42)*(1-'Assumptions'!$F$43) -> 0 | G34: =(1-'Assumptions'!$F$41*'Assumptions'!$F$42)*(1-'Assumptions'!$F$43) -> 0 | H34: =(1-'Assumptions'!$F$41*'Assumptions'!$F$42)*(1-'Assumptions'!$F$43) -> 0 | I34: =(1-'Assumptions'!$F$41*'Assumptions'!$F$42)*(1-'Assumptions'!$F$43) -> 0 | J34: =(1-'Assumptions'!$F$41*'Assumptions'!$F$42)*(1-'Assumptions'!$F$43) -> 0 | ... AL34: =(1-'Assumptions'!$F$41*'Assumptions'!$F$42)*(1-'Assumptions'!$F$43) -> 0 | AN34: =AVERAGE(C34:E34) -> 0 | AO34: =AVERAGE(F34:H34) -> 0 | AP34: =AVERAGE(I34:K34) -> 0 | AQ34: =AVERAGE(L34:N34) -> 0 | AR34: =AVERAGE(O34:Q34) -> 0 | AS34: =AVERAGE(R34:T34) -> 0 | AT34: =AVERAGE(U34:W34) -> 0 | AU34: =AVERAGE(X34:Z34) -> 0 | AV34: =AVERAGE(AA34:AC34) -> 0 | AW34: =AVERAGE(AD34:AF34) -> 0 | AX34: =AVERAGE(AG34:AI34) -> 0 | AY34: =AVERAGE(AJ34:AL34) -> 0 | BA34: =AVERAGE(C34:N34) -> 0 | BB34: =AVERAGE(O34:Z34) -> 0 | BC34: =AVERAGE(AA34:AL34) -> 0
A35: Starter net price per 1M requests | C35: =C33*(1-'Assumptions'!$F$40)*'Assumptions'!$F$37 -> 0 | D35: =D33*(1-'Assumptions'!$F$40)*'Assumptions'!$F$37 -> 0 | E35: =E33*(1-'Assumptions'!$F$40)*'Assumptions'!$F$37 -> 0 | F35: =F33*(1-'Assumptions'!$F$40)*'Assumptions'!$F$37 -> 0 | G35: =G33*(1-'Assumptions'!$F$40)*'Assumptions'!$F$37 -> 0 | H35: =H33*(1-'Assumptions'!$F$40)*'Assumptions'!$F$37 -> 0 | I35: =I33*(1-'Assumptions'!$F$40)*'Assumptions'!$F$37 -> 0 | J35: =J33*(1-'Assumptions'!$F$40)*'Assumptions'!$F$37 -> 0 | ... AL35: =AL33*(1-'Assumptions'!$F$40)*'Assumptions'!$F$37 -> 0 | AN35: =AVERAGE(C35:E35) -> 0 | AO35: =AVERAGE(F35:H35) -> 0 | AP35: =AVERAGE(I35:K35) -> 0 | AQ35: =AVERAGE(L35:N35) -> 0 | AR35: =AVERAGE(O35:Q35) -> 0 | AS35: =AVERAGE(R35:T35) -> 0 | AT35: =AVERAGE(U35:W35) -> 0 | AU35: =AVERAGE(X35:Z35) -> 0 | AV35: =AVERAGE(AA35:AC35) -> 0 | AW35: =AVERAGE(AD35:AF35) -> 0 | AX35: =AVERAGE(AG35:AI35) -> 0 | AY35: =AVERAGE(AJ35:AL35) -> 0 | BA35: =AVERAGE(C35:N35) -> 0 | BB35: =AVERAGE(O35:Z35) -> 0 | BC35: =AVERAGE(AA35:AL35) -> 0
A36: Growth net price per 1M requests | C36: =C33*(1-'Assumptions'!$F$40)*'Assumptions'!$F$38 -> 0 | D36: =D33*(1-'Assumptions'!$F$40)*'Assumptions'!$F$38 -> 0 | E36: =E33*(1-'Assumptions'!$F$40)*'Assumptions'!$F$38 -> 0 | F36: =F33*(1-'Assumptions'!$F$40)*'Assumptions'!$F$38 -> 0 | G36: =G33*(1-'Assumptions'!$F$40)*'Assumptions'!$F$38 -> 0 | H36: =H33*(1-'Assumptions'!$F$40)*'Assumptions'!$F$38 -> 0 | I36: =I33*(1-'Assumptions'!$F$40)*'Assumptions'!$F$38 -> 0 | J36: =J33*(1-'Assumptions'!$F$40)*'Assumptions'!$F$38 -> 0 | ... AL36: =AL33*(1-'Assumptions'!$F$40)*'Assumptions'!$F$38 -> 0 | AN36: =AVERAGE(C36:E36) -> 0 | AO36: =AVERAGE(F36:H36) -> 0 | AP36: =AVERAGE(I36:K36) -> 0 | AQ36: =AVERAGE(L36:N36) -> 0 | AR36: =AVERAGE(O36:Q36) -> 0 | AS36: =AVERAGE(R36:T36) -> 0 | AT36: =AVERAGE(U36:W36) -> 0 | AU36: =AVERAGE(X36:Z36) -> 0 | AV36: =AVERAGE(AA36:AC36) -> 0 | AW36: =AVERAGE(AD36:AF36) -> 0 | AX36: =AVERAGE(AG36:AI36) -> 0 | AY36: =AVERAGE(AJ36:AL36) -> 0 | BA36: =AVERAGE(C36:N36) -> 0 | BB36: =AVERAGE(O36:Z36) -> 0 | BC36: =AVERAGE(AA36:AL36) -> 0
A37: Enterprise net price per 1M requests | C37: =C33*(1-'Assumptions'!$F$40)*'Assumptions'!$F$39 -> 0 | D37: =D33*(1-'Assumptions'!$F$40)*'Assumptions'!$F$39 -> 0 | E37: =E33*(1-'Assumptions'!$F$40)*'Assumptions'!$F$39 -> 0 | F37: =F33*(1-'Assumptions'!$F$40)*'Assumptions'!$F$39 -> 0 | G37: =G33*(1-'Assumptions'!$F$40)*'Assumptions'!$F$39 -> 0 | H37: =H33*(1-'Assumptions'!$F$40)*'Assumptions'!$F$39 -> 0 | I37: =I33*(1-'Assumptions'!$F$40)*'Assumptions'!$F$39 -> 0 | J37: =J33*(1-'Assumptions'!$F$40)*'Assumptions'!$F$39 -> 0 | ... AL37: =AL33*(1-'Assumptions'!$F$40)*'Assumptions'!$F$39 -> 0 | AN37: =AVERAGE(C37:E37) -> 0 | AO37: =AVERAGE(F37:H37) -> 0 | AP37: =AVERAGE(I37:K37) -> 0 | AQ37: =AVERAGE(L37:N37) -> 0 | AR37: =AVERAGE(O37:Q37) -> 0 | AS37: =AVERAGE(R37:T37) -> 0 | AT37: =AVERAGE(U37:W37) -> 0 | AU37: =AVERAGE(X37:Z37) -> 0 | AV37: =AVERAGE(AA37:AC37) -> 0 | AW37: =AVERAGE(AD37:AF37) -> 0 | AX37: =AVERAGE(AG37:AI37) -> 0 | AY37: =AVERAGE(AJ37:AL37) -> 0 | BA37: =AVERAGE(C37:N37) -> 0 | BB37: =AVERAGE(O37:Z37) -> 0 | BC37: =AVERAGE(AA37:AL37) -> 0
A39: Starter usage revenue | C39: =C13*C34*C35 -> 0 | D39: =D13*D34*D35 -> 0 | E39: =E13*E34*E35 -> 0 | F39: =F13*F34*F35 -> 0 | G39: =G13*G34*G35 -> 0 | H39: =H13*H34*H35 -> 0 | I39: =I13*I34*I35 -> 0 | J39: =J13*J34*J35 -> 0 | ... AL39: =AL13*AL34*AL35 -> 0 | AN39: =SUM(C39:E39) -> 0 | AO39: =SUM(F39:H39) -> 0 | AP39: =SUM(I39:K39) -> 0 | AQ39: =SUM(L39:N39) -> 0 | AR39: =SUM(O39:Q39) -> 0 | AS39: =SUM(R39:T39) -> 0 | AT39: =SUM(U39:W39) -> 0 | AU39: =SUM(X39:Z39) -> 0 | AV39: =SUM(AA39:AC39) -> 0 | AW39: =SUM(AD39:AF39) -> 0 | AX39: =SUM(AG39:AI39) -> 0 | AY39: =SUM(AJ39:AL39) -> 0 | BA39: =SUM(C39:N39) -> 0 | BB39: =SUM(O39:Z39) -> 0 | BC39: =SUM(AA39:AL39) -> 0
A40: Starter platform revenue | C40: =C11*'Assumptions'!$F$44 -> 0 | D40: =D11*'Assumptions'!$F$44 -> 0 | E40: =E11*'Assumptions'!$F$44 -> 0 | F40: =F11*'Assumptions'!$F$44 -> 0 | G40: =G11*'Assumptions'!$F$44 -> 0 | H40: =H11*'Assumptions'!$F$44 -> 0 | I40: =I11*'Assumptions'!$F$44 -> 0 | J40: =J11*'Assumptions'!$F$44 -> 0 | ... AL40: =AL11*'Assumptions'!$F$44 -> 0 | AN40: =SUM(C40:E40) -> 0 | AO40: =SUM(F40:H40) -> 0 | AP40: =SUM(I40:K40) -> 0 | AQ40: =SUM(L40:N40) -> 0 | AR40: =SUM(O40:Q40) -> 0 | AS40: =SUM(R40:T40) -> 0 | AT40: =SUM(U40:W40) -> 0 | AU40: =SUM(X40:Z40) -> 0 | AV40: =SUM(AA40:AC40) -> 0 | AW40: =SUM(AD40:AF40) -> 0 | AX40: =SUM(AG40:AI40) -> 0 | AY40: =SUM(AJ40:AL40) -> 0 | BA40: =SUM(C40:N40) -> 0 | BB40: =SUM(O40:Z40) -> 0 | BC40: =SUM(AA40:AL40) -> 0
A41: Starter total revenue | C41: =C39+C40 -> 0 | D41: =D39+D40 -> 0 | E41: =E39+E40 -> 0 | F41: =F39+F40 -> 0 | G41: =G39+G40 -> 0 | H41: =H39+H40 -> 0 | I41: =I39+I40 -> 0 | J41: =J39+J40 -> 0 | ... AL41: =AL39+AL40 -> 0 | AN41: =SUM(C41:E41) -> 0 | AO41: =SUM(F41:H41) -> 0 | AP41: =SUM(I41:K41) -> 0 | AQ41: =SUM(L41:N41) -> 0 | AR41: =SUM(O41:Q41) -> 0 | AS41: =SUM(R41:T41) -> 0 | AT41: =SUM(U41:W41) -> 0 | AU41: =SUM(X41:Z41) -> 0 | AV41: =SUM(AA41:AC41) -> 0 | AW41: =SUM(AD41:AF41) -> 0 | AX41: =SUM(AG41:AI41) -> 0 | AY41: =SUM(AJ41:AL41) -> 0 | BA41: =SUM(C41:N41) -> 0 | BB41: =SUM(O41:Z41) -> 0 | BC41: =SUM(AA41:AL41) -> 0
A42: Starter new-customer revenue added | B42: Used for sales commission modeling | C42: =C9*C12*C34*C35+C9*'Assumptions'!$F$44 -> 0 | D42: =D9*D12*D34*D35+D9*'Assumptions'!$F$44 -> 0 | E42: =E9*E12*E34*E35+E9*'Assumptions'!$F$44 -> 0 | F42: =F9*F12*F34*F35+F9*'Assumptions'!$F$44 -> 0 | G42: =G9*G12*G34*G35+G9*'Assumptions'!$F$44 -> 0 | H42: =H9*H12*H34*H35+H9*'Assumptions'!$F$44 -> 0 | I42: =I9*I12*I34*I35+I9*'Assumptions'!$F$44 -> 0 | J42: =J9*J12*J34*J35+J9*'Assumptions'!$F$44 -> 0 | ... AL42: =AL9*AL12*AL34*AL35+AL9*'Assumptions'!$F$44 -> 0 | AN42: =SUM(C42:E42) -> 0 | AO42: =SUM(F42:H42) -> 0 | AP42: =SUM(I42:K42) -> 0 | AQ42: =SUM(L42:N42) -> 0 | AR42: =SUM(O42:Q42) -> 0 | AS42: =SUM(R42:T42) -> 0 | AT42: =SUM(U42:W42) -> 0 | AU42: =SUM(X42:Z42) -> 0 | AV42: =SUM(AA42:AC42) -> 0 | AW42: =SUM(AD42:AF42) -> 0 | AX42: =SUM(AG42:AI42) -> 0 | AY42: =SUM(AJ42:AL42) -> 0 | BA42: =SUM(C42:N42) -> 0 | BB42: =SUM(O42:Z42) -> 0 | BC42: =SUM(AA42:AL42) -> 0
A44: Growth usage revenue | C44: =C21*C34*C36 -> 0 | D44: =D21*D34*D36 -> 0 | E44: =E21*E34*E36 -> 0 | F44: =F21*F34*F36 -> 0 | G44: =G21*G34*G36 -> 0 | H44: =H21*H34*H36 -> 0 | I44: =I21*I34*I36 -> 0 | J44: =J21*J34*J36 -> 0 | ... AL44: =AL21*AL34*AL36 -> 0 | AN44: =SUM(C44:E44) -> 0 | AO44: =SUM(F44:H44) -> 0 | AP44: =SUM(I44:K44) -> 0 | AQ44: =SUM(L44:N44) -> 0 | AR44: =SUM(O44:Q44) -> 0 | AS44: =SUM(R44:T44) -> 0 | AT44: =SUM(U44:W44) -> 0 | AU44: =SUM(X44:Z44) -> 0 | AV44: =SUM(AA44:AC44) -> 0 | AW44: =SUM(AD44:AF44) -> 0 | AX44: =SUM(AG44:AI44) -> 0 | AY44: =SUM(AJ44:AL44) -> 0 | BA44: =SUM(C44:N44) -> 0 | BB44: =SUM(O44:Z44) -> 0 | BC44: =SUM(AA44:AL44) -> 0
A45: Growth platform revenue | C45: =C19*'Assumptions'!$F$45 -> 0 | D45: =D19*'Assumptions'!$F$45 -> 0 | E45: =E19*'Assumptions'!$F$45 -> 0 | F45: =F19*'Assumptions'!$F$45 -> 0 | G45: =G19*'Assumptions'!$F$45 -> 0 | H45: =H19*'Assumptions'!$F$45 -> 0 | I45: =I19*'Assumptions'!$F$45 -> 0 | J45: =J19*'Assumptions'!$F$45 -> 0 | ... AL45: =AL19*'Assumptions'!$F$45 -> 0 | AN45: =SUM(C45:E45) -> 0 | AO45: =SUM(F45:H45) -> 0 | AP45: =SUM(I45:K45) -> 0 | AQ45: =SUM(L45:N45) -> 0 | AR45: =SUM(O45:Q45) -> 0 | AS45: =SUM(R45:T45) -> 0 | AT45: =SUM(U45:W45) -> 0 | AU45: =SUM(X45:Z45) -> 0 | AV45: =SUM(AA45:AC45) -> 0 | AW45: =SUM(AD45:AF45) -> 0 | AX45: =SUM(AG45:AI45) -> 0 | AY45: =SUM(AJ45:AL45) -> 0 | BA45: =SUM(C45:N45) -> 0 | BB45: =SUM(O45:Z45) -> 0 | BC45: =SUM(AA45:AL45) -> 0
A46: Growth total revenue | C46: =C44+C45 -> 0 | D46: =D44+D45 -> 0 | E46: =E44+E45 -> 0 | F46: =F44+F45 -> 0 | G46: =G44+G45 -> 0 | H46: =H44+H45 -> 0 | I46: =I44+I45 -> 0 | J46: =J44+J45 -> 0 | ... AL46: =AL44+AL45 -> 0 | AN46: =SUM(C46:E46) -> 0 | AO46: =SUM(F46:H46) -> 0 | AP46: =SUM(I46:K46) -> 0 | AQ46: =SUM(L46:N46) -> 0 | AR46: =SUM(O46:Q46) -> 0 | AS46: =SUM(R46:T46) -> 0 | AT46: =SUM(U46:W46) -> 0 | AU46: =SUM(X46:Z46) -> 0 | AV46: =SUM(AA46:AC46) -> 0 | AW46: =SUM(AD46:AF46) -> 0 | AX46: =SUM(AG46:AI46) -> 0 | AY46: =SUM(AJ46:AL46) -> 0 | BA46: =SUM(C46:N46) -> 0 | BB46: =SUM(O46:Z46) -> 0 | BC46: =SUM(AA46:AL46) -> 0
A47: Growth new-customer revenue added | B47: Used for sales commission modeling | C47: =C17*C20*C34*C36+C17*'Assumptions'!$F$45 -> 0 | D47: =D17*D20*D34*D36+D17*'Assumptions'!$F$45 -> 0 | E47: =E17*E20*E34*E36+E17*'Assumptions'!$F$45 -> 0 | F47: =F17*F20*F34*F36+F17*'Assumptions'!$F$45 -> 0 | G47: =G17*G20*G34*G36+G17*'Assumptions'!$F$45 -> 0 | H47: =H17*H20*H34*H36+H17*'Assumptions'!$F$45 -> 0 | I47: =I17*I20*I34*I36+I17*'Assumptions'!$F$45 -> 0 | J47: =J17*J20*J34*J36+J17*'Assumptions'!$F$45 -> 0 | ... AL47: =AL17*AL20*AL34*AL36+AL17*'Assumptions'!$F$45 -> 0 | AN47: =SUM(C47:E47) -> 0 | AO47: =SUM(F47:H47) -> 0 | AP47: =SUM(I47:K47) -> 0 | AQ47: =SUM(L47:N47) -> 0 | AR47: =SUM(O47:Q47) -> 0 | AS47: =SUM(R47:T47) -> 0 | AT47: =SUM(U47:W47) -> 0 | AU47: =SUM(X47:Z47) -> 0 | AV47: =SUM(AA47:AC47) -> 0 | AW47: =SUM(AD47:AF47) -> 0 | AX47: =SUM(AG47:AI47) -> 0 | AY47: =SUM(AJ47:AL47) -> 0 | BA47: =SUM(C47:N47) -> 0 | BB47: =SUM(O47:Z47) -> 0 | BC47: =SUM(AA47:AL47) -> 0
...

Sheet COGS & GM
A1: AI API / Infrastructure — 3-Year Financial Model — COGS & GM
A2: Compute, model-provider, storage, bandwidth, and infrastructure people costs tied to usage volume.
A5: Line item | B5: Units / source | C5: Monthly (36 months) | AN5: Quarterly | BA5: Annual
C6: 46023 | D6: 46054 | E6: 46082 | F6: 46113 | G6: 46143 | H6: 46174 | I6: 46204 | J6: 46235 | K6: 46266 | L6: 46296 | M6: 46327 | N6: 46357 | O6: 46388 | P6: 46419 | Q6: 46447 | R6: 46478 | S6: 46508 | T6: 46539 | U6: 46569 | V6: 46600 | W6: 46631 | X6: 46661 | Y6: 46692 | Z6: 46722 | AA6: 46753 | AB6: 46784 | AC6: 46813 | AD6: 46844 | AE6: 46874 | AF6: 46905 | AG6: 46935 | AH6: 46966 | AI6: 46997 | AJ6: 47027 | AK6: 47058 | AL6: 47088 | AN6: Q1 | AO6: Q2 | AP6: Q3 | AQ6: Q4 | AR6: Q5 | AS6: Q6 | AT6: Q7 | AU6: Q8 | AV6: Q9 | AW6: Q10 | AX6: Q11 | AY6: Q12 | BA6: FY1 | BB6: FY2 | BC6: FY3
A7: Volume Drivers & Utilization
A8: Gross request volume | B8: Linked from Revenue tab (M requests) | C8: ='Revenue'!$C$55 -> 0 | D8: ='Revenue'!$D$55 -> 0 | E8: ='Revenue'!$E$55 -> 0 | F8: ='Revenue'!$F$55 -> 0 | G8: ='Revenue'!$G$55 -> 0 | H8: ='Revenue'!$H$55 -> 0 | I8: ='Revenue'!$I$55 -> 0 | J8: ='Revenue'!$J$55 -> 0 | K8: ='Revenue'!$K$55 -> 0 | L8: ='Revenue'!$L$55 -> 0 | M8: ='Revenue'!$M$55 -> 0 | N8: ='Revenue'!$N$55 -> 0 | O8: ='Revenue'!$O$55 -> 0 | P8: ='Revenue'!$P$55 -> 0 | Q8: ='Revenue'!$Q$55 -> 0 | R8: ='Revenue'!$R$55 -> 0 | S8: ='Revenue'!$S$55 -> 0 | T8: ='Revenue'!$T$55 -> 0 | U8: ='Revenue'!$U$55 -> 0 | V8: ='Revenue'!$V$55 -> 0 | W8: ='Revenue'!$W$55 -> 0 | X8: ='Revenue'!$X$55 -> 0 | Y8: ='Revenue'!$Y$55 -> 0 | Z8: ='Revenue'!$Z$55 -> 0 | AA8: ='Revenue'!$AA$55 -> 0 | AB8: ='Revenue'!$AB$55 -> 0 | AC8: ='Revenue'!$AC$55 -> 0 | AD8: ='Revenue'!$AD$55 -> 0 | AE8: ='Revenue'!$AE$55 -> 0 | AF8: ='Revenue'!$AF$55 -> 0 | AG8: ='Revenue'!$AG$55 -> 0 | AH8: ='Revenue'!$AH$55 -> 0 | AI8: ='Revenue'!$AI$55 -> 0 | AJ8: ='Revenue'!$AJ$55 -> 0 | AK8: ='Revenue'!$AK$55 -> 0 | AL8: ='Revenue'!$AL$55 -> 0 | AN8: =SUM(C8:E8) -> 0 | AO8: =SUM(F8:H8) -> 0 | AP8: =SUM(I8:K8) -> 0 | AQ8: =SUM(L8:N8) -> 0 | AR8: =SUM(O8:Q8) -> 0 | AS8: =SUM(R8:T8) -> 0 | AT8: =SUM(U8:W8) -> 0 | AU8: =SUM(X8:Z8) -> 0 | AV8: =SUM(AA8:AC8) -> 0 | AW8: =SUM(AD8:AF8) -> 0 | AX8: =SUM(AG8:AI8) -> 0 | AY8: =SUM(AJ8:AL8) -> 0 | BA8: =SUM(C8:N8) -> 0 | BB8: =SUM(O8:Z8) -> 0 | BC8: =SUM(AA8:AL8) -> 0
A9: Billable request volume | B9: Linked from Revenue tab (M requests) | C9: ='Revenue'!$C$56 -> 0 | D9: ='Revenue'!$D$56 -> 0 | E9: ='Revenue'!$E$56 -> 0 | F9: ='Revenue'!$F$56 -> 0 | G9: ='Revenue'!$G$56 -> 0 | H9: ='Revenue'!$H$56 -> 0 | I9: ='Revenue'!$I$56 -> 0 | J9: ='Revenue'!$J$56 -> 0 | K9: ='Revenue'!$K$56 -> 0 | L9: ='Revenue'!$L$56 -> 0 | M9: ='Revenue'!$M$56 -> 0 | N9: ='Revenue'!$N$56 -> 0 | O9: ='Revenue'!$O$56 -> 0 | P9: ='Revenue'!$P$56 -> 0 | Q9: ='Revenue'!$Q$56 -> 0 | R9: ='Revenue'!$R$56 -> 0 | S9: ='Revenue'!$S$56 -> 0 | T9: ='Revenue'!$T$56 -> 0 | U9: ='Revenue'!$U$56 -> 0 | V9: ='Revenue'!$V$56 -> 0 | W9: ='Revenue'!$W$56 -> 0 | X9: ='Revenue'!$X$56 -> 0 | Y9: ='Revenue'!$Y$56 -> 0 | Z9: ='Revenue'!$Z$56 -> 0 | AA9: ='Revenue'!$AA$56 -> 0 | AB9: ='Revenue'!$AB$56 -> 0 | AC9: ='Revenue'!$AC$56 -> 0 | AD9: ='Revenue'!$AD$56 -> 0 | AE9: ='Revenue'!$AE$56 -> 0 | AF9: ='Revenue'!$AF$56 -> 0 | AG9: ='Revenue'!$AG$56 -> 0 | AH9: ='Revenue'!$AH$56 -> 0 | AI9: ='Revenue'!$AI$56 -> 0 | AJ9: ='Revenue'!$AJ$56 -> 0 | AK9: ='Revenue'!$AK$56 -> 0 | AL9: ='Revenue'!$AL$56 -> 0 | AN9: =SUM(C9:E9) -> 0 | AO9: =SUM(F9:H9) -> 0 | AP9: =SUM(I9:K9) -> 0 | AQ9: =SUM(L9:N9) -> 0 | AR9: =SUM(O9:Q9) -> 0 | AS9: =SUM(R9:T9) -> 0 | AT9: =SUM(U9:W9) -> 0 | AU9: =SUM(X9:Z9) -> 0 | AV9: =SUM(AA9:AC9) -> 0 | AW9: =SUM(AD9:AF9) -> 0 | AX9: =SUM(AG9:AI9) -> 0 | AY9: =SUM(AJ9:AL9) -> 0 | BA9: =SUM(C9:N9) -> 0 | BB9: =SUM(O9:Z9) -> 0 | BC9: =SUM(AA9:AL9) -> 0
A10: Fresh-inference / processed volume | B10: Gross volume after cache hits and batch discounts (M requests) | C10: ='Revenue'!C55*(1-'Assumptions'!$F$41)*(1-'Assumptions'!$F$43) -> 0 | D10: ='Revenue'!D55*(1-'Assumptions'!$F$41)*(1-'Assumptions'!$F$43) -> 0 | E10: ='Revenue'!E55*(1-'Assumptions'!$F$41)*(1-'Assumptions'!$F$43) -> 0 | F10: ='Revenue'!F55*(1-'Assumptions'!$F$41)*(1-'Assumptions'!$F$43) -> 0 | G10: ='Revenue'!G55*(1-'Assumptions'!$F$41)*(1-'Assumptions'!$F$43) -> 0 | H10: ='Revenue'!H55*(1-'Assumptions'!$F$41)*(1-'Assumptions'!$F$43) -> 0 | I10: ='Revenue'!I55*(1-'Assumptions'!$F$41)*(1-'Assumptions'!$F$43) -> 0 | J10: ='Revenue'!J55*(1-'Assumptions'!$F$41)*(1-'Assumptions'!$F$43) -> 0 | ... AL10: ='Revenue'!AL55*(1-'Assumptions'!$F$41)*(1-'Assumptions'!$F$43) -> 0 | AN10: =SUM(C10:E10) -> 0 | AO10: =SUM(F10:H10) -> 0 | AP10: =SUM(I10:K10) -> 0 | AQ10: =SUM(L10:N10) -> 0 | AR10: =SUM(O10:Q10) -> 0 | AS10: =SUM(R10:T10) -> 0 | AT10: =SUM(U10:W10) -> 0 | AU10: =SUM(X10:Z10) -> 0 | AV10: =SUM(AA10:AC10) -> 0 | AW10: =SUM(AD10:AF10) -> 0 | AX10: =SUM(AG10:AI10) -> 0 | AY10: =SUM(AJ10:AL10) -> 0 | BA10: =SUM(C10:N10) -> 0 | BB10: =SUM(O10:Z10) -> 0 | BC10: =SUM(AA10:AL10) -> 0
A11: Reserved-capacity utilization | C11: ='Assumptions'!$F$56 -> 0 | D11: =MIN(0.88,MAX(0.35,C11+'Assumptions'!$F$57)) -> 0 | E11: =MIN(0.88,MAX(0.35,D11+'Assumptions'!$F$57)) -> 0 | F11: =MIN(0.88,MAX(0.35,E11+'Assumptions'!$F$57)) -> 0 | G11: =MIN(0.88,MAX(0.35,F11+'Assumptions'!$F$57)) -> 0 | H11: =MIN(0.88,MAX(0.35,G11+'Assumptions'!$F$57)) -> 0 | I11: =MIN(0.88,MAX(0.35,H11+'Assumptions'!$F$57)) -> 0 | J11: =MIN(0.88,MAX(0.35,I11+'Assumptions'!$F$57)) -> 0 | K11: =MIN(0.88,MAX(0.35,J11+'Assumptions'!$F$57)) -> 0 | ... AL11: =MIN(0.88,MAX(0.35,AK11+'Assumptions'!$F$57)) -> 0 | AN11: =AVERAGE(C11:E11) -> 0 | AO11: =AVERAGE(F11:H11) -> 0 | AP11: =AVERAGE(I11:K11) -> 0 | AQ11: =AVERAGE(L11:N11) -> 0 | AR11: =AVERAGE(O11:Q11) -> 0 | AS11: =AVERAGE(R11:T11) -> 0 | AT11: =AVERAGE(U11:W11) -> 0 | AU11: =AVERAGE(X11:Z11) -> 0 | AV11: =AVERAGE(AA11:AC11) -> 0 | AW11: =AVERAGE(AD11:AF11) -> 0 | AX11: =AVERAGE(AG11:AI11) -> 0 | AY11: =AVERAGE(AJ11:AL11) -> 0 | BA11: =AVERAGE(C11:N11) -> 0 | BB11: =AVERAGE(O11:Z11) -> 0 | BC11: =AVERAGE(AA11:AL11) -> 0
A12: Effective compute cost per 1M requests | B12: Reserved cost is utilization-adjusted, then blended with on-demand | C12: =('Assumptions'!$F$55*'Assumptions'!$F$49/MAX(0.35,C11)+(1-'Assumptions'!$F$55)*'Assumptions'!$F$50) -> 0 | D12: =('Assumptions'!$F$55*'Assumptions'!$F$49/MAX(0.35,D11)+(1-'Assumptions'!$F$55)*'Assumptions'!$F$50) -> 0 | E12: =('Assumptions'!$F$55*'Assumptions'!$F$49/MAX(0.35,E11)+(1-'Assumptions'!$F$55)*'Assumptions'!$F$50) -> 0 | F12: =('Assumptions'!$F$55*'Assumptions'!$F$49/MAX(0.35,F11)+(1-'Assumptions'!$F$55)*'Assumptions'!$F$50) -> 0 | G12: =('Assumptions'!$F$55*'Assumptions'!$F$49/MAX(0.35,G11)+(1-'Assumptions'!$F$55)*'Assumptions'!$F$50) -> 0 | H12: =('Assumptions'!$F$55*'Assumptions'!$F$49/MAX(0.35,H11)+(1-'Assumptions'!$F$55)*'Assumptions'!$F$50) -> 0 | I12: =('Assumptions'!$F$55*'Assumptions'!$F$49/MAX(0.35,I11)+(1-'Assumptions'!$F$55)*'Assumptions'!$F$50) -> 0 | J12: =('Assumptions'!$F$55*'Assumptions'!$F$49/MAX(0.35,J11)+(1-'Assumptions'!$F$55)*'Assumptions'!$F$50) -> 0 | ... AL12: =('Assumptions'!$F$55*'Assumptions'!$F$49/MAX(0.35,AL11)+(1-'Assumptions'!$F$55)*'Assumptions'!$F$50) -> 0 | AN12: =AVERAGE(C12:E12) -> 0 | AO12: =AVERAGE(F12:H12) -> 0 | AP12: =AVERAGE(I12:K12) -> 0 | AQ12: =AVERAGE(L12:N12) -> 0 | AR12: =AVERAGE(O12:Q12) -> 0 | AS12: =AVERAGE(R12:T12) -> 0 | AT12: =AVERAGE(U12:W12) -> 0 | AU12: =AVERAGE(X12:Z12) -> 0 | AV12: =AVERAGE(AA12:AC12) -> 0 | AW12: =AVERAGE(AD12:AF12) -> 0 | AX12: =AVERAGE(AG12:AI12) -> 0 | AY12: =AVERAGE(AJ12:AL12) -> 0 | BA12: =AVERAGE(C12:N12) -> 0 | BB12: =AVERAGE(O12:Z12) -> 0 | BC12: =AVERAGE(AA12:AL12) -> 0
A13: Blended provider/API cost per 1M requests | B13: Weighted average of standard and premium provider cost | C13: =('Assumptions'!$F$51*(1-'Revenue'!C32)+'Assumptions'!$F$52*'Revenue'!C32) -> 0 | D13: =('Assumptions'!$F$51*(1-'Revenue'!D32)+'Assumptions'!$F$52*'Revenue'!D32) -> 0 | E13: =('Assumptions'!$F$51*(1-'Revenue'!E32)+'Assumptions'!$F$52*'Revenue'!E32) -> 0 | F13: =('Assumptions'!$F$51*(1-'Revenue'!F32)+'Assumptions'!$F$52*'Revenue'!F32) -> 0 | G13: =('Assumptions'!$F$51*(1-'Revenue'!G32)+'Assumptions'!$F$52*'Revenue'!G32) -> 0 | H13: =('Assumptions'!$F$51*(1-'Revenue'!H32)+'Assumptions'!$F$52*'Revenue'!H32) -> 0 | I13: =('Assumptions'!$F$51*(1-'Revenue'!I32)+'Assumptions'!$F$52*'Revenue'!I32) -> 0 | J13: =('Assumptions'!$F$51*(1-'Revenue'!J32)+'Assumptions'!$F$52*'Revenue'!J32) -> 0 | ... AL13: =('Assumptions'!$F$51*(1-'Revenue'!AL32)+'Assumptions'!$F$52*'Revenue'!AL32) -> 0 | AN13: =AVERAGE(C13:E13) -> 0 | AO13: =AVERAGE(F13:H13) -> 0 | AP13: =AVERAGE(I13:K13) -> 0 | AQ13: =AVERAGE(L13:N13) -> 0 | AR13: =AVERAGE(O13:Q13) -> 0 | AS13: =AVERAGE(R13:T13) -> 0 | AT13: =AVERAGE(U13:W13) -> 0 | AU13: =AVERAGE(X13:Z13) -> 0 | AV13: =AVERAGE(AA13:AC13) -> 0 | AW13: =AVERAGE(AD13:AF13) -> 0 | AX13: =AVERAGE(AG13:AI13) -> 0 | AY13: =AVERAGE(AJ13:AL13) -> 0 | BA13: =AVERAGE(C13:N13) -> 0 | BB13: =AVERAGE(O13:Z13) -> 0 | BC13: =AVERAGE(AA13:AL13) -> 0
A15: COGS Components
A16: Compute infrastructure | C16: =C10*C12 -> 0 | D16: =D10*D12 -> 0 | E16: =E10*E12 -> 0 | F16: =F10*F12 -> 0 | G16: =G10*G12 -> 0 | H16: =H10*H12 -> 0 | I16: =I10*I12 -> 0 | J16: =J10*J12 -> 0 | ... AL16: =AL10*AL12 -> 0 | AN16: =SUM(C16:E16) -> 0 | AO16: =SUM(F16:H16) -> 0 | AP16: =SUM(I16:K16) -> 0 | AQ16: =SUM(L16:N16) -> 0 | AR16: =SUM(O16:Q16) -> 0 | AS16: =SUM(R16:T16) -> 0 | AT16: =SUM(U16:W16) -> 0 | AU16: =SUM(X16:Z16) -> 0 | AV16: =SUM(AA16:AC16) -> 0 | AW16: =SUM(AD16:AF16) -> 0 | AX16: =SUM(AG16:AI16) -> 0 | AY16: =SUM(AJ16:AL16) -> 0 | BA16: =SUM(C16:N16) -> 0 | BB16: =SUM(O16:Z16) -> 0 | BC16: =SUM(AA16:AL16) -> 0
A17: External model / API providers | C17: =C10*C13 -> 0 | D17: =D10*D13 -> 0 | E17: =E10*E13 -> 0 | F17: =F10*F13 -> 0 | G17: =G10*G13 -> 0 | H17: =H10*H13 -> 0 | I17: =I10*I13 -> 0 | J17: =J10*J13 -> 0 | ... AL17: =AL10*AL13 -> 0 | AN17: =SUM(C17:E17) -> 0 | AO17: =SUM(F17:H17) -> 0 | AP17: =SUM(I17:K17) -> 0 | AQ17: =SUM(L17:N17) -> 0 | AR17: =SUM(O17:Q17) -> 0 | AS17: =SUM(R17:T17) -> 0 | AT17: =SUM(U17:W17) -> 0 | AU17: =SUM(X17:Z17) -> 0 | AV17: =SUM(AA17:AC17) -> 0 | AW17: =SUM(AD17:AF17) -> 0 | AX17: =SUM(AG17:AI17) -> 0 | AY17: =SUM(AJ17:AL17) -> 0 | BA17: =SUM(C17:N17) -> 0 | BB17: =SUM(O17:Z17) -> 0 | BC17: =SUM(AA17:AL17) -> 0
A18: Storage / vector / retrieval | C18: ='Revenue'!C55*'Assumptions'!$F$53 -> 0 | D18: ='Revenue'!D55*'Assumptions'!$F$53 -> 0 | E18: ='Revenue'!E55*'Assumptions'!$F$53 -> 0 | F18: ='Revenue'!F55*'Assumptions'!$F$53 -> 0 | G18: ='Revenue'!G55*'Assumptions'!$F$53 -> 0 | H18: ='Revenue'!H55*'Assumptions'!$F$53 -> 0 | I18: ='Revenue'!I55*'Assumptions'!$F$53 -> 0 | J18: ='Revenue'!J55*'Assumptions'!$F$53 -> 0 | ... AL18: ='Revenue'!AL55*'Assumptions'!$F$53 -> 0 | AN18: =SUM(C18:E18) -> 0 | AO18: =SUM(F18:H18) -> 0 | AP18: =SUM(I18:K18) -> 0 | AQ18: =SUM(L18:N18) -> 0 | AR18: =SUM(O18:Q18) -> 0 | AS18: =SUM(R18:T18) -> 0 | AT18: =SUM(U18:W18) -> 0 | AU18: =SUM(X18:Z18) -> 0 | AV18: =SUM(AA18:AC18) -> 0 | AW18: =SUM(AD18:AF18) -> 0 | AX18: =SUM(AG18:AI18) -> 0 | AY18: =SUM(AJ18:AL18) -> 0 | BA18: =SUM(C18:N18) -> 0 | BB18: =SUM(O18:Z18) -> 0 | BC18: =SUM(AA18:AL18) -> 0
