Workbook

Sheet Read Me
A1: AI-Enabled Services — 3-Year Financial Model
A2: 36-month integrated financial model — Read Me
A4: Overview
A5: A 36-month, formula-driven financial model for an AI-enabled services company. Start on the Assumptions tab, pick Base/Upside/Downside, and the model flows from sales pipeline to bookings, backlog, recognized revenue, gross margin, cash flow, and runway.
A7: How this workbook is organized
A8: Assumptions -> Headcount -> Revenue -> COGS & GM -> Opex -> Working Capital -> P&L -> Balance Sheet -> Cash Flow -> Cash & Runway -> Scenarios -> Visuals -> Checks. Data flows strictly left-to-right through that order: change an assumption, and every downstream tab recalculates automatically (workbook calculation mode is Automatic).
A10: Formatting legend
A11: Blue text on light-blue fill = an input you can edit (Assumptions tab, and scenario selector).
A12: Black text on white = a live formula. Do not hard-code over these cells.
A13: Cells on a light-gray band = a value linked in from another tab.
A15: Color palette
A16: Purple (#7B68EE)
... A35: 36 monthly periods, plus quarterly (12) and annual (3) roll-up columns on each schedule tab. Workbook calculation is set to Automatic — Excel recalculates on every edit. Deterministic, seeded default assumptions are provided so the model is internally consistent out of the box; replace them with your own numbers on the Assumptions tab.

Sheet Assumptions
A1: AI-Enabled Services — 3-Year Financial Model — Assumptions
A2: Plain-language inputs. Edit the Base / Upside / Downside columns only — everything else in this workbook is a formula.
A4: Scenario selector: | C4: Base | D4: << Pick Base / Upside / Downside. This one cell drives every formula in the model.
A6: Assumption | B6: Unit | C6: Base | D6: Upside | E6: Downside | F6: Active (used in model) | G6: Notes / definition
A7: Company & Financial
A8: Starting cash balance | B8: $ | C8: 900000 | D8: 900000 | E8: 900000 | F8: =CHOOSE(MATCH('Assumptions'!$C$4,{"Base","Upside","Downside"},0),C8,D8,E8) -> 0 | G8: Cash on hand at the start of month 1.
A9: Starting paid-in capital | B9: $ | C9: 1250000 | D9: 1250000 | E9: 1250000 | F9: =CHOOSE(MATCH('Assumptions'!$C$4,{"Base","Upside","Downside"},0),C9,D9,E9) -> 0 | G9: Cumulative equity funded before the model begins.
A10: Income tax rate | B10: % | C10: 0 | D10: 0 | E10: 0 | F10: =CHOOSE(MATCH('Assumptions'!$C$4,{"Base","Upside","Downside"},0),C10,D10,E10) -> 0 | G10: Applied only to positive EBT; no NOL carryforward modeled.
A12: Pipeline & Bookings
A13: Starting signed backlog | B13: $ | C13: 650000 | D13: 725000 | E13: 500000 | F13: =CHOOSE(MATCH('Assumptions'!$C$4,{"Base","Upside","Downside"},0),C13,D13,E13) -> 0 | G13: Contracted work not yet recognized as revenue at the start of month 1.
A14: Qualified pipeline opportunities per Sales/BD FTE, month 1 | B14: #/mo | C14: 2.4 | D14: 2.9 | E14: 1.9 | F14: =CHOOSE(MATCH('Assumptions'!$C$4,{"Base","Upside","Downside"},0),C14,D14,E14) -> 0 | G14: Average proposal-ready projects each sales rep creates in month 1.
A15: Pipeline opportunities growth, month over month | B15: % | C15: 0.0384 | D15: 0.0491 | E15: 0.0123 | F15: =CHOOSE(MATCH('Assumptions'!$C$4,{"Base","Upside","Downside"},0),C15,D15,E15) -> 0 | G15: Improvement in qualified opportunities per sales rep over time from references, content, and partner channels.
A16: Proposal win rate | B16: % | C16: 0.34 | D16: 0.4 | E16: 0.26 | F16: =CHOOSE(MATCH('Assumptions'!$C$4,{"Base","Upside","Downside"},0),C16,D16,E16) -> 0 | G16: Share of qualified opportunities that close into signed projects.
A17: Average project contract value, month 1 | B17: $ | C17: 85000 | D17: 95000 | E17: 72000 | F17: =CHOOSE(MATCH('Assumptions'!$C$4,{"Base","Upside","Downside"},0),C17,D17,E17) -> 0 | G17: Fixed-fee project value equivalent for a typical implementation or consulting engagement.
A18: Average project value growth, month over month | B18: % | C18: 0.0037 | D18: 0.0123 | E18: -0.0017 | F18: =CHOOSE(MATCH('Assumptions'!$C$4,{"Base","Upside","Downside"},0),C18,D18,E18) -> 0 | G18: Mix/pricing improvement in signed project value over time.
A19: Average project duration | B19: months | C19: 2.5 | D19: 2.2 | E19: 3.1 | F19: =CHOOSE(MATCH('Assumptions'!$C$4,{"Base","Upside","Downside"},0),C19,D19,E19) -> 0 | G19: Average time over which signed backlog converts into recognized revenue.
A21: Delivery & Utilization
A22: Standard billable-hours capacity per Delivery FTE | B22: hrs/mo | C22: 140 | D22: 145 | E22: 135 | F22: =CHOOSE(MATCH('Assumptions'!$C$4,{"Base","Upside","Downside"},0),C22,D22,E22) -> 0 | G22: Monthly capacity before utilization and AI productivity uplift.
A23: Target delivery utilization | B23: % | C23: 0.72 | D23: 0.8 | E23: 0.62 | F23: =CHOOSE(MATCH('Assumptions'!$C$4,{"Base","Upside","Downside"},0),C23,D23,E23) -> 0 | G23: Share of effective delivery capacity expected to be client-billable.
A24: Realization rate | B24: % | C24: 0.93 | D24: 0.97 | E24: 0.88 | F24: =CHOOSE(MATCH('Assumptions'!$C$4,{"Base","Upside","Downside"},0),C24,D24,E24) -> 0 | G24: Billed/collected rate as a % of standard rate after discounts, write-offs, and scope leakage.
A25: Blended billing rate, month 1 | B25: $/hr | C25: 195 | D25: 210 | E25: 180 | F25: =CHOOSE(MATCH('Assumptions'!$C$4,{"Base","Upside","Downside"},0),C25,D25,E25) -> 0 | G25: Average realized delivery price before realization adjustments.
A26: Billing-rate growth, month over month | B26: % | C26: 0.0049 | D26: 0.009 | E26: 0.0001 | F26: =CHOOSE(MATCH('Assumptions'!$C$4,{"Base","Upside","Downside"},0),C26,D26,E26) -> 0 | G26: Price/mix improvement in the standard delivery rate.
A27: AI productivity uplift | B27: % | C27: 0.18 | D27: 0.28 | E27: 0.08 | F27: =CHOOSE(MATCH('Assumptions'!$C$4,{"Base","Upside","Downside"},0),C27,D27,E27) -> 0 | G27: AI tooling increases effective delivery capacity without a proportional increase in headcount.
A29: COGS & AI Tooling
A30: Subcontractor cost, % of revenue | B30: % | C30: 0.1 | D30: 0.07 | E30: 0.14 | F30: =CHOOSE(MATCH('Assumptions'!$C$4,{"Base","Upside","Downside"},0),C30,D30,E30) -> 0 | G30: External specialists used to flex delivery capacity or cover niche skills.
A31: AI tool/API cost per Delivery FTE | B31: $/mo | C31: 1450 | D31: 1300 | E31: 1700 | F31: =CHOOSE(MATCH('Assumptions'!$C$4,{"Base","Upside","Downside"},0),C31,D31,E31) -> 0 | G31: Model/API/tooling spend consumed directly in service delivery.
A33: Headcount — Delivery (COGS)
A34: Starting Delivery/Consulting FTEs | B34: # | C34: 6 | D34: 7 | E34: 5 | F34: =CHOOSE(MATCH('Assumptions'!$C$4,{"Base","Upside","Downside"},0),C34,D34,E34) -> 0 | G34: Billable consultants and implementation specialists.
A35: Delivery/Consulting net adds per quarter | B35: # | C35: 1.5 | D35: 2 | E35: 0.8 | F35: =CHOOSE(MATCH('Assumptions'!$C$4,{"Base","Upside","Downside"},0),C35,D35,E35) -> 0 | G35: Net hires supporting growth in signed and delivered work.
A36: Delivery/Consulting fully-loaded cost per FTE | B36: $/mo | C36: 12500 | D36: 12500 | E36: 12500 | F36: =CHOOSE(MATCH('Assumptions'!$C$4,{"Base","Upside","Downside"},0),C36,D36,E36) -> 0 | G36: Salary, benefits, payroll tax, and bonus accrual.
A38: Headcount — Delivery Management / Solutions (COGS)
A39: Starting Delivery Management / Solutions FTEs | B39: # | C39: 1.5 | D39: 2 | E39: 1 | F39: =CHOOSE(MATCH('Assumptions'!$C$4,{"Base","Upside","Downside"},0),C39,D39,E39) -> 0 | G39: Classified in COGS because this team is directly tied to project oversight and solution delivery.
A40: Delivery Management / Solutions net adds per quarter | B40: # | C40: 0.5 | D40: 0.8 | E40: 0.2 | F40: =CHOOSE(MATCH('Assumptions'!$C$4,{"Base","Upside","Downside"},0),C40,D40,E40) -> 0 | G40: Staffing added as project volume and delivery complexity increase.
A41: Delivery Management / Solutions fully-loaded cost per FTE | B41: $/mo | C41: 15500 | D41: 15500 | E41: 15500 | F41: =CHOOSE(MATCH('Assumptions'!$C$4,{"Base","Upside","Downside"},0),C41,D41,E41) -> 0 | G41: Higher-cost solution leads / delivery managers.
A43: Headcount — Sales / BD (Opex)
A44: Starting Sales / BD FTEs | B44: # | C44: 2 | D44: 2 | E44: 2 | F44: =CHOOSE(MATCH('Assumptions'!$C$4,{"Base","Upside","Downside"},0),C44,D44,E44) -> 0 | G44: Quota-carrying sales and business development reps.
A45: Sales / BD net adds per quarter | B45: # | C45: 0.75 | D45: 1 | E45: 0.4 | F45: =CHOOSE(MATCH('Assumptions'!$C$4,{"Base","Upside","Downside"},0),C45,D45,E45) -> 0 | G45: Net rep additions supporting pipeline generation.
A46: Sales / BD fully-loaded cost per FTE | B46: $/mo | C46: 13500 | D46: 13500 | E46: 13500 | F46: =CHOOSE(MATCH('Assumptions'!$C$4,{"Base","Upside","Downside"},0),C46,D46,E46) -> 0 | G46: Base pay, benefits, payroll tax, and bonus accrual before commissions.
A48: Headcount — G&A (Opex)
A49: Starting G&A FTEs | B49: # | C49: 2 | D49: 2 | E49: 2 | F49: =CHOOSE(MATCH('Assumptions'!$C$4,{"Base","Upside","Downside"},0),C49,D49,E49) -> 0 | G49: Finance, ops, recruiting, and admin.
...

Sheet Headcount
A1: AI-Enabled Services — 3-Year Financial Model — Headcount
A2: Fully-loaded FTE ramps by role — flows into COGS or Opex by classification.
A5: Line item | B5: Units / source | C5: Monthly (36 months) | AN5: Quarterly | BA5: Annual
C6: 46023 | D6: 46054 | E6: 46082 | F6: 46113 | G6: 46143 | H6: 46174 | I6: 46204 | J6: 46235 | K6: 46266 | L6: 46296 | M6: 46327 | N6: 46357 | O6: 46388 | P6: 46419 | Q6: 46447 | R6: 46478 | S6: 46508 | T6: 46539 | U6: 46569 | V6: 46600 | W6: 46631 | X6: 46661 | Y6: 46692 | Z6: 46722 | AA6: 46753 | AB6: 46784 | AC6: 46813 | AD6: 46844 | AE6: 46874 | AF6: 46905 | AG6: 46935 | AH6: 46966 | AI6: 46997 | AJ6: 47027 | AK6: 47058 | AL6: 47088 | AN6: Q1 | AO6: Q2 | AP6: Q3 | AQ6: Q4 | AR6: Q5 | AS6: Q6 | AT6: Q7 | AU6: Q8 | AV6: Q9 | AW6: Q10 | AX6: Q11 | AY6: Q12 | BA6: FY1 | BB6: FY2 | BC6: FY3
A7: Cost of Goods Sold headcount (COGS-classified)
A8: Delivery / Consulting — headcount (FTE) | B8: Delivery · start + net adds/qtr ÷ 3 | C8: =ROUND('Assumptions'!$F$34,1) -> 0 | D8: =ROUND(C8+'Assumptions'!$F$35/3,1) -> 0 | E8: =ROUND(D8+'Assumptions'!$F$35/3,1) -> 0 | F8: =ROUND(E8+'Assumptions'!$F$35/3,1) -> 0 | G8: =ROUND(F8+'Assumptions'!$F$35/3,1) -> 0 | H8: =ROUND(G8+'Assumptions'!$F$35/3,1) -> 0 | I8: =ROUND(H8+'Assumptions'!$F$35/3,1) -> 0 | J8: =ROUND(I8+'Assumptions'!$F$35/3,1) -> 0 | K8: =ROUND(J8+'Assumptions'!$F$35/3,1) -> 0 | ... AL8: =ROUND(AK8+'Assumptions'!$F$35/3,1) -> 0 | AN8: =E8 -> 0 | AO8: =H8 -> 0 | AP8: =K8 -> 0 | AQ8: =N8 -> 0 | AR8: =Q8 -> 0 | AS8: =T8 -> 0 | AT8: =W8 -> 0 | AU8: =Z8 -> 0 | AV8: =AC8 -> 0 | AW8: =AF8 -> 0 | AX8: =AI8 -> 0 | AY8: =AL8 -> 0 | BA8: =N8 -> 0 | BB8: =Z8 -> 0 | BC8: =AL8 -> 0
A9: Delivery / Consulting — fully-loaded cost | B9: Headcount × monthly fully-loaded cost/FTE | C9: =C8*'Assumptions'!$F$36 -> 0 | D9: =D8*'Assumptions'!$F$36 -> 0 | E9: =E8*'Assumptions'!$F$36 -> 0 | F9: =F8*'Assumptions'!$F$36 -> 0 | G9: =G8*'Assumptions'!$F$36 -> 0 | H9: =H8*'Assumptions'!$F$36 -> 0 | I9: =I8*'Assumptions'!$F$36 -> 0 | J9: =J8*'Assumptions'!$F$36 -> 0 | ... AL9: =AL8*'Assumptions'!$F$36 -> 0 | AN9: =SUM(C9:E9) -> 0 | AO9: =SUM(F9:H9) -> 0 | AP9: =SUM(I9:K9) -> 0 | AQ9: =SUM(L9:N9) -> 0 | AR9: =SUM(O9:Q9) -> 0 | AS9: =SUM(R9:T9) -> 0 | AT9: =SUM(U9:W9) -> 0 | AU9: =SUM(X9:Z9) -> 0 | AV9: =SUM(AA9:AC9) -> 0 | AW9: =SUM(AD9:AF9) -> 0 | AX9: =SUM(AG9:AI9) -> 0 | AY9: =SUM(AJ9:AL9) -> 0 | BA9: =SUM(C9:N9) -> 0 | BB9: =SUM(O9:Z9) -> 0 | BC9: =SUM(AA9:AL9) -> 0
A10: Delivery Management / Solutions — headcount (FTE) | B10: Delivery · start + net adds/qtr ÷ 3 | C10: =ROUND('Assumptions'!$F$39,1) -> 0 | D10: =ROUND(C10+'Assumptions'!$F$40/3,1) -> 0 | E10: =ROUND(D10+'Assumptions'!$F$40/3,1) -> 0 | F10: =ROUND(E10+'Assumptions'!$F$40/3,1) -> 0 | G10: =ROUND(F10+'Assumptions'!$F$40/3,1) -> 0 | H10: =ROUND(G10+'Assumptions'!$F$40/3,1) -> 0 | I10: =ROUND(H10+'Assumptions'!$F$40/3,1) -> 0 | J10: =ROUND(I10+'Assumptions'!$F$40/3,1) -> 0 | K10: =ROUND(J10+'Assumptions'!$F$40/3,1) -> 0 | ... AL10: =ROUND(AK10+'Assumptions'!$F$40/3,1) -> 0 | AN10: =E10 -> 0 | AO10: =H10 -> 0 | AP10: =K10 -> 0 | AQ10: =N10 -> 0 | AR10: =Q10 -> 0 | AS10: =T10 -> 0 | AT10: =W10 -> 0 | AU10: =Z10 -> 0 | AV10: =AC10 -> 0 | AW10: =AF10 -> 0 | AX10: =AI10 -> 0 | AY10: =AL10 -> 0 | BA10: =N10 -> 0 | BB10: =Z10 -> 0 | BC10: =AL10 -> 0
A11: Delivery Management / Solutions — fully-loaded cost | B11: Headcount × monthly fully-loaded cost/FTE | C11: =C10*'Assumptions'!$F$41 -> 0 | D11: =D10*'Assumptions'!$F$41 -> 0 | E11: =E10*'Assumptions'!$F$41 -> 0 | F11: =F10*'Assumptions'!$F$41 -> 0 | G11: =G10*'Assumptions'!$F$41 -> 0 | H11: =H10*'Assumptions'!$F$41 -> 0 | I11: =I10*'Assumptions'!$F$41 -> 0 | J11: =J10*'Assumptions'!$F$41 -> 0 | ... AL11: =AL10*'Assumptions'!$F$41 -> 0 | AN11: =SUM(C11:E11) -> 0 | AO11: =SUM(F11:H11) -> 0 | AP11: =SUM(I11:K11) -> 0 | AQ11: =SUM(L11:N11) -> 0 | AR11: =SUM(O11:Q11) -> 0 | AS11: =SUM(R11:T11) -> 0 | AT11: =SUM(U11:W11) -> 0 | AU11: =SUM(X11:Z11) -> 0 | AV11: =SUM(AA11:AC11) -> 0 | AW11: =SUM(AD11:AF11) -> 0 | AX11: =SUM(AG11:AI11) -> 0 | AY11: =SUM(AJ11:AL11) -> 0 | BA11: =SUM(C11:N11) -> 0 | BB11: =SUM(O11:Z11) -> 0 | BC11: =SUM(AA11:AL11) -> 0
A13: Operating expense headcount (Opex-classified)
A14: Sales / Business Development — headcount (FTE) | B14: Sales & Marketing · start + net adds/qtr ÷ 3 | C14: =ROUND('Assumptions'!$F$44,1) -> 0 | D14: =ROUND(C14+'Assumptions'!$F$45/3,1) -> 0 | E14: =ROUND(D14+'Assumptions'!$F$45/3,1) -> 0 | F14: =ROUND(E14+'Assumptions'!$F$45/3,1) -> 0 | G14: =ROUND(F14+'Assumptions'!$F$45/3,1) -> 0 | H14: =ROUND(G14+'Assumptions'!$F$45/3,1) -> 0 | I14: =ROUND(H14+'Assumptions'!$F$45/3,1) -> 0 | J14: =ROUND(I14+'Assumptions'!$F$45/3,1) -> 0 | K14: =ROUND(J14+'Assumptions'!$F$45/3,1) -> 0 | ... AL14: =ROUND(AK14+'Assumptions'!$F$45/3,1) -> 0 | AN14: =E14 -> 0 | AO14: =H14 -> 0 | AP14: =K14 -> 0 | AQ14: =N14 -> 0 | AR14: =Q14 -> 0 | AS14: =T14 -> 0 | AT14: =W14 -> 0 | AU14: =Z14 -> 0 | AV14: =AC14 -> 0 | AW14: =AF14 -> 0 | AX14: =AI14 -> 0 | AY14: =AL14 -> 0 | BA14: =N14 -> 0 | BB14: =Z14 -> 0 | BC14: =AL14 -> 0
A15: Sales / Business Development — fully-loaded cost | B15: Headcount × monthly fully-loaded cost/FTE | C15: =C14*'Assumptions'!$F$46 -> 0 | D15: =D14*'Assumptions'!$F$46 -> 0 | E15: =E14*'Assumptions'!$F$46 -> 0 | F15: =F14*'Assumptions'!$F$46 -> 0 | G15: =G14*'Assumptions'!$F$46 -> 0 | H15: =H14*'Assumptions'!$F$46 -> 0 | I15: =I14*'Assumptions'!$F$46 -> 0 | J15: =J14*'Assumptions'!$F$46 -> 0 | ... AL15: =AL14*'Assumptions'!$F$46 -> 0 | AN15: =SUM(C15:E15) -> 0 | AO15: =SUM(F15:H15) -> 0 | AP15: =SUM(I15:K15) -> 0 | AQ15: =SUM(L15:N15) -> 0 | AR15: =SUM(O15:Q15) -> 0 | AS15: =SUM(R15:T15) -> 0 | AT15: =SUM(U15:W15) -> 0 | AU15: =SUM(X15:Z15) -> 0 | AV15: =SUM(AA15:AC15) -> 0 | AW15: =SUM(AD15:AF15) -> 0 | AX15: =SUM(AG15:AI15) -> 0 | AY15: =SUM(AJ15:AL15) -> 0 | BA15: =SUM(C15:N15) -> 0 | BB15: =SUM(O15:Z15) -> 0 | BC15: =SUM(AA15:AL15) -> 0
A16: General & Administrative — headcount (FTE) | B16: General & Administrative · start + net adds/qtr ÷ 3 | C16: =ROUND('Assumptions'!$F$49,1) -> 0 | D16: =ROUND(C16+'Assumptions'!$F$50/3,1) -> 0 | E16: =ROUND(D16+'Assumptions'!$F$50/3,1) -> 0 | F16: =ROUND(E16+'Assumptions'!$F$50/3,1) -> 0 | G16: =ROUND(F16+'Assumptions'!$F$50/3,1) -> 0 | H16: =ROUND(G16+'Assumptions'!$F$50/3,1) -> 0 | I16: =ROUND(H16+'Assumptions'!$F$50/3,1) -> 0 | J16: =ROUND(I16+'Assumptions'!$F$50/3,1) -> 0 | K16: =ROUND(J16+'Assumptions'!$F$50/3,1) -> 0 | ... AL16: =ROUND(AK16+'Assumptions'!$F$50/3,1) -> 0 | AN16: =E16 -> 0 | AO16: =H16 -> 0 | AP16: =K16 -> 0 | AQ16: =N16 -> 0 | AR16: =Q16 -> 0 | AS16: =T16 -> 0 | AT16: =W16 -> 0 | AU16: =Z16 -> 0 | AV16: =AC16 -> 0 | AW16: =AF16 -> 0 | AX16: =AI16 -> 0 | AY16: =AL16 -> 0 | BA16: =N16 -> 0 | BB16: =Z16 -> 0 | BC16: =AL16 -> 0
A17: General & Administrative — fully-loaded cost | B17: Headcount × monthly fully-loaded cost/FTE | C17: =C16*'Assumptions'!$F$51 -> 0 | D17: =D16*'Assumptions'!$F$51 -> 0 | E17: =E16*'Assumptions'!$F$51 -> 0 | F17: =F16*'Assumptions'!$F$51 -> 0 | G17: =G16*'Assumptions'!$F$51 -> 0 | H17: =H16*'Assumptions'!$F$51 -> 0 | I17: =I16*'Assumptions'!$F$51 -> 0 | J17: =J16*'Assumptions'!$F$51 -> 0 | ... AL17: =AL16*'Assumptions'!$F$51 -> 0 | AN17: =SUM(C17:E17) -> 0 | AO17: =SUM(F17:H17) -> 0 | AP17: =SUM(I17:K17) -> 0 | AQ17: =SUM(L17:N17) -> 0 | AR17: =SUM(O17:Q17) -> 0 | AS17: =SUM(R17:T17) -> 0 | AT17: =SUM(U17:W17) -> 0 | AU17: =SUM(X17:Z17) -> 0 | AV17: =SUM(AA17:AC17) -> 0 | AW17: =SUM(AD17:AF17) -> 0 | AX17: =SUM(AG17:AI17) -> 0 | AY17: =SUM(AJ17:AL17) -> 0 | BA17: =SUM(C17:N17) -> 0 | BB17: =SUM(O17:Z17) -> 0 | BC17: =SUM(AA17:AL17) -> 0
A19: Totals
A20: Total headcount (FTE) | B20: Sum of all roles | C20: =C8+C10+C14+C16 -> 0 | D20: =D8+D10+D14+D16 -> 0 | E20: =E8+E10+E14+E16 -> 0 | F20: =F8+F10+F14+F16 -> 0 | G20: =G8+G10+G14+G16 -> 0 | H20: =H8+H10+H14+H16 -> 0 | I20: =I8+I10+I14+I16 -> 0 | J20: =J8+J10+J14+J16 -> 0 | ... AL20: =AL8+AL10+AL14+AL16 -> 0 | AN20: =E20 -> 0 | AO20: =H20 -> 0 | AP20: =K20 -> 0 | AQ20: =N20 -> 0 | AR20: =Q20 -> 0 | AS20: =T20 -> 0 | AT20: =W20 -> 0 | AU20: =Z20 -> 0 | AV20: =AC20 -> 0 | AW20: =AF20 -> 0 | AX20: =AI20 -> 0 | AY20: =AL20 -> 0 | BA20: =N20 -> 0 | BB20: =Z20 -> 0 | BC20: =AL20 -> 0
A21: Total COGS-classified people cost | B21: Feeds COGS & GM tab | C21: =C9+C11 -> 0 | D21: =D9+D11 -> 0 | E21: =E9+E11 -> 0 | F21: =F9+F11 -> 0 | G21: =G9+G11 -> 0 | H21: =H9+H11 -> 0 | I21: =I9+I11 -> 0 | J21: =J9+J11 -> 0 | ... AL21: =AL9+AL11 -> 0 | AN21: =SUM(C21:E21) -> 0 | AO21: =SUM(F21:H21) -> 0 | AP21: =SUM(I21:K21) -> 0 | AQ21: =SUM(L21:N21) -> 0 | AR21: =SUM(O21:Q21) -> 0 | AS21: =SUM(R21:T21) -> 0 | AT21: =SUM(U21:W21) -> 0 | AU21: =SUM(X21:Z21) -> 0 | AV21: =SUM(AA21:AC21) -> 0 | AW21: =SUM(AD21:AF21) -> 0 | AX21: =SUM(AG21:AI21) -> 0 | AY21: =SUM(AJ21:AL21) -> 0 | BA21: =SUM(C21:N21) -> 0 | BB21: =SUM(O21:Z21) -> 0 | BC21: =SUM(AA21:AL21) -> 0
A22: Total Opex-classified people cost | B22: Feeds Opex tab | C22: =C15+C17 -> 0 | D22: =D15+D17 -> 0 | E22: =E15+E17 -> 0 | F22: =F15+F17 -> 0 | G22: =G15+G17 -> 0 | H22: =H15+H17 -> 0 | I22: =I15+I17 -> 0 | J22: =J15+J17 -> 0 | ... AL22: =AL15+AL17 -> 0 | AN22: =SUM(C22:E22) -> 0 | AO22: =SUM(F22:H22) -> 0 | AP22: =SUM(I22:K22) -> 0 | AQ22: =SUM(L22:N22) -> 0 | AR22: =SUM(O22:Q22) -> 0 | AS22: =SUM(R22:T22) -> 0 | AT22: =SUM(U22:W22) -> 0 | AU22: =SUM(X22:Z22) -> 0 | AV22: =SUM(AA22:AC22) -> 0 | AW22: =SUM(AD22:AF22) -> 0 | AX22: =SUM(AG22:AI22) -> 0 | AY22: =SUM(AJ22:AL22) -> 0 | BA22: =SUM(C22:N22) -> 0 | BB22: =SUM(O22:Z22) -> 0 | BC22: =SUM(AA22:AL22) -> 0
A23: General & Administrative people cost | C23: =C17 -> 0 | D23: =D17 -> 0 | E23: =E17 -> 0 | F23: =F17 -> 0 | G23: =G17 -> 0 | H23: =H17 -> 0 | I23: =I17 -> 0 | J23: =J17 -> 0 | ... AL23: =AL17 -> 0 | AN23: =SUM(C23:E23) -> 0 | AO23: =SUM(F23:H23) -> 0 | AP23: =SUM(I23:K23) -> 0 | AQ23: =SUM(L23:N23) -> 0 | AR23: =SUM(O23:Q23) -> 0 | AS23: =SUM(R23:T23) -> 0 | AT23: =SUM(U23:W23) -> 0 | AU23: =SUM(X23:Z23) -> 0 | AV23: =SUM(AA23:AC23) -> 0 | AW23: =SUM(AD23:AF23) -> 0 | AX23: =SUM(AG23:AI23) -> 0 | AY23: =SUM(AJ23:AL23) -> 0 | BA23: =SUM(C23:N23) -> 0 | BB23: =SUM(O23:Z23) -> 0 | BC23: =SUM(AA23:AL23) -> 0
A24: Sales & Marketing people cost | C24: =C15 -> 0 | D24: =D15 -> 0 | E24: =E15 -> 0 | F24: =F15 -> 0 | G24: =G15 -> 0 | H24: =H15 -> 0 | I24: =I15 -> 0 | J24: =J15 -> 0 | ... AL24: =AL15 -> 0 | AN24: =SUM(C24:E24) -> 0 | AO24: =SUM(F24:H24) -> 0 | AP24: =SUM(I24:K24) -> 0 | AQ24: =SUM(L24:N24) -> 0 | AR24: =SUM(O24:Q24) -> 0 | AS24: =SUM(R24:T24) -> 0 | AT24: =SUM(U24:W24) -> 0 | AU24: =SUM(X24:Z24) -> 0 | AV24: =SUM(AA24:AC24) -> 0 | AW24: =SUM(AD24:AF24) -> 0 | AX24: =SUM(AG24:AI24) -> 0 | AY24: =SUM(AJ24:AL24) -> 0 | BA24: =SUM(C24:N24) -> 0 | BB24: =SUM(O24:Z24) -> 0 | BC24: =SUM(AA24:AL24) -> 0

Sheet Revenue
A1: AI-Enabled Services — 3-Year Financial Model — Revenue
A2: Pipeline -> bookings -> backlog -> revenue recognized as projects are delivered against capacity.
A5: Line item | B5: Units / source | C5: Monthly (36 months) | AN5: Quarterly | BA5: Annual
C6: 46023 | D6: 46054 | E6: 46082 | F6: 46113 | G6: 46143 | H6: 46174 | I6: 46204 | J6: 46235 | K6: 46266 | L6: 46296 | M6: 46327 | N6: 46357 | O6: 46388 | P6: 46419 | Q6: 46447 | R6: 46478 | S6: 46508 | T6: 46539 | U6: 46569 | V6: 46600 | W6: 46631 | X6: 46661 | Y6: 46692 | Z6: 46722 | AA6: 46753 | AB6: 46784 | AC6: 46813 | AD6: 46844 | AE6: 46874 | AF6: 46905 | AG6: 46935 | AH6: 46966 | AI6: 46997 | AJ6: 47027 | AK6: 47058 | AL6: 47088 | AN6: Q1 | AO6: Q2 | AP6: Q3 | AQ6: Q4 | AR6: Q5 | AS6: Q6 | AT6: Q7 | AU6: Q8 | AV6: Q9 | AW6: Q10 | AX6: Q11 | AY6: Q12 | BA6: FY1 | BB6: FY2 | BC6: FY3
A7: Pipeline & Bookings
A8: Sales / BD FTE | B8: Linked from Headcount tab | C8: ='Headcount'!$C$14 -> 0 | D8: ='Headcount'!$D$14 -> 0 | E8: ='Headcount'!$E$14 -> 0 | F8: ='Headcount'!$F$14 -> 0 | G8: ='Headcount'!$G$14 -> 0 | H8: ='Headcount'!$H$14 -> 0 | I8: ='Headcount'!$I$14 -> 0 | J8: ='Headcount'!$J$14 -> 0 | K8: ='Headcount'!$K$14 -> 0 | L8: ='Headcount'!$L$14 -> 0 | M8: ='Headcount'!$M$14 -> 0 | N8: ='Headcount'!$N$14 -> 0 | O8: ='Headcount'!$O$14 -> 0 | P8: ='Headcount'!$P$14 -> 0 | Q8: ='Headcount'!$Q$14 -> 0 | R8: ='Headcount'!$R$14 -> 0 | S8: ='Headcount'!$S$14 -> 0 | T8: ='Headcount'!$T$14 -> 0 | U8: ='Headcount'!$U$14 -> 0 | V8: ='Headcount'!$V$14 -> 0 | W8: ='Headcount'!$W$14 -> 0 | X8: ='Headcount'!$X$14 -> 0 | Y8: ='Headcount'!$Y$14 -> 0 | Z8: ='Headcount'!$Z$14 -> 0 | AA8: ='Headcount'!$AA$14 -> 0 | AB8: ='Headcount'!$AB$14 -> 0 | AC8: ='Headcount'!$AC$14 -> 0 | AD8: ='Headcount'!$AD$14 -> 0 | AE8: ='Headcount'!$AE$14 -> 0 | AF8: ='Headcount'!$AF$14 -> 0 | AG8: ='Headcount'!$AG$14 -> 0 | AH8: ='Headcount'!$AH$14 -> 0 | AI8: ='Headcount'!$AI$14 -> 0 | AJ8: ='Headcount'!$AJ$14 -> 0 | AK8: ='Headcount'!$AK$14 -> 0 | AL8: ='Headcount'!$AL$14 -> 0 | AN8: =E8 -> 0 | AO8: =H8 -> 0 | AP8: =K8 -> 0 | AQ8: =N8 -> 0 | AR8: =Q8 -> 0 | AS8: =T8 -> 0 | AT8: =W8 -> 0 | AU8: =Z8 -> 0 | AV8: =AC8 -> 0 | AW8: =AF8 -> 0 | AX8: =AI8 -> 0 | AY8: =AL8 -> 0 | BA8: =N8 -> 0 | BB8: =Z8 -> 0 | BC8: =AL8 -> 0
A9: Qualified pipeline opportunities / Sales FTE | B9: Starts from month-1 assumption and compounds with go-to-market efficiency gains | C9: ='Assumptions'!$F$14 -> 0 | D9: =C9*(1+'Assumptions'!$F$15) -> 0 | E9: =D9*(1+'Assumptions'!$F$15) -> 0 | F9: =E9*(1+'Assumptions'!$F$15) -> 0 | G9: =F9*(1+'Assumptions'!$F$15) -> 0 | H9: =G9*(1+'Assumptions'!$F$15) -> 0 | I9: =H9*(1+'Assumptions'!$F$15) -> 0 | J9: =I9*(1+'Assumptions'!$F$15) -> 0 | K9: =J9*(1+'Assumptions'!$F$15) -> 0 | ... AL9: =AK9*(1+'Assumptions'!$F$15) -> 0 | AN9: =AVERAGE(C9:E9) -> 0 | AO9: =AVERAGE(F9:H9) -> 0 | AP9: =AVERAGE(I9:K9) -> 0 | AQ9: =AVERAGE(L9:N9) -> 0 | AR9: =AVERAGE(O9:Q9) -> 0 | AS9: =AVERAGE(R9:T9) -> 0 | AT9: =AVERAGE(U9:W9) -> 0 | AU9: =AVERAGE(X9:Z9) -> 0 | AV9: =AVERAGE(AA9:AC9) -> 0 | AW9: =AVERAGE(AD9:AF9) -> 0 | AX9: =AVERAGE(AG9:AI9) -> 0 | AY9: =AVERAGE(AJ9:AL9) -> 0 | BA9: =AVERAGE(C9:N9) -> 0 | BB9: =AVERAGE(O9:Z9) -> 0 | BC9: =AVERAGE(AA9:AL9) -> 0
A10: Qualified pipeline opportunities | B10: Sales FTE x qualified opportunities per Sales FTE | C10: =C8*C9 -> 0 | D10: =D8*D9 -> 0 | E10: =E8*E9 -> 0 | F10: =F8*F9 -> 0 | G10: =G8*G9 -> 0 | H10: =H8*H9 -> 0 | I10: =I8*I9 -> 0 | J10: =J8*J9 -> 0 | ... AL10: =AL8*AL9 -> 0 | AN10: =SUM(C10:E10) -> 0 | AO10: =SUM(F10:H10) -> 0 | AP10: =SUM(I10:K10) -> 0 | AQ10: =SUM(L10:N10) -> 0 | AR10: =SUM(O10:Q10) -> 0 | AS10: =SUM(R10:T10) -> 0 | AT10: =SUM(U10:W10) -> 0 | AU10: =SUM(X10:Z10) -> 0 | AV10: =SUM(AA10:AC10) -> 0 | AW10: =SUM(AD10:AF10) -> 0 | AX10: =SUM(AG10:AI10) -> 0 | AY10: =SUM(AJ10:AL10) -> 0 | BA10: =SUM(C10:N10) -> 0 | BB10: =SUM(O10:Z10) -> 0 | BC10: =SUM(AA10:AL10) -> 0
A11: Proposal win rate | B11: Active scenario assumption | C11: ='Assumptions'!$F$16 -> 0 | D11: ='Assumptions'!$F$16 -> 0 | E11: ='Assumptions'!$F$16 -> 0 | F11: ='Assumptions'!$F$16 -> 0 | G11: ='Assumptions'!$F$16 -> 0 | H11: ='Assumptions'!$F$16 -> 0 | I11: ='Assumptions'!$F$16 -> 0 | J11: ='Assumptions'!$F$16 -> 0 | ... AL11: ='Assumptions'!$F$16 -> 0 | AN11: =AVERAGE(C11:E11) -> 0 | AO11: =AVERAGE(F11:H11) -> 0 | AP11: =AVERAGE(I11:K11) -> 0 | AQ11: =AVERAGE(L11:N11) -> 0 | AR11: =AVERAGE(O11:Q11) -> 0 | AS11: =AVERAGE(R11:T11) -> 0 | AT11: =AVERAGE(U11:W11) -> 0 | AU11: =AVERAGE(X11:Z11) -> 0 | AV11: =AVERAGE(AA11:AC11) -> 0 | AW11: =AVERAGE(AD11:AF11) -> 0 | AX11: =AVERAGE(AG11:AI11) -> 0 | AY11: =AVERAGE(AJ11:AL11) -> 0 | BA11: =AVERAGE(C11:N11) -> 0 | BB11: =AVERAGE(O11:Z11) -> 0 | BC11: =AVERAGE(AA11:AL11) -> 0
A12: New projects booked | B12: Qualified pipeline x win rate | C12: =C10*C11 -> 0 | D12: =D10*D11 -> 0 | E12: =E10*E11 -> 0 | F12: =F10*F11 -> 0 | G12: =G10*G11 -> 0 | H12: =H10*H11 -> 0 | I12: =I10*I11 -> 0 | J12: =J10*J11 -> 0 | ... AL12: =AL10*AL11 -> 0 | AN12: =SUM(C12:E12) -> 0 | AO12: =SUM(F12:H12) -> 0 | AP12: =SUM(I12:K12) -> 0 | AQ12: =SUM(L12:N12) -> 0 | AR12: =SUM(O12:Q12) -> 0 | AS12: =SUM(R12:T12) -> 0 | AT12: =SUM(U12:W12) -> 0 | AU12: =SUM(X12:Z12) -> 0 | AV12: =SUM(AA12:AC12) -> 0 | AW12: =SUM(AD12:AF12) -> 0 | AX12: =SUM(AG12:AI12) -> 0 | AY12: =SUM(AJ12:AL12) -> 0 | BA12: =SUM(C12:N12) -> 0 | BB12: =SUM(O12:Z12) -> 0 | BC12: =SUM(AA12:AL12) -> 0
A13: Average project contract value | B13: Fixed-fee project equivalent; grows with pricing and mix | C13: ='Assumptions'!$F$17 -> 0 | D13: =C13*(1+'Assumptions'!$F$18) -> 0 | E13: =D13*(1+'Assumptions'!$F$18) -> 0 | F13: =E13*(1+'Assumptions'!$F$18) -> 0 | G13: =F13*(1+'Assumptions'!$F$18) -> 0 | H13: =G13*(1+'Assumptions'!$F$18) -> 0 | I13: =H13*(1+'Assumptions'!$F$18) -> 0 | J13: =I13*(1+'Assumptions'!$F$18) -> 0 | K13: =J13*(1+'Assumptions'!$F$18) -> 0 | ... AL13: =AK13*(1+'Assumptions'!$F$18) -> 0 | AN13: =AVERAGE(C13:E13) -> 0 | AO13: =AVERAGE(F13:H13) -> 0 | AP13: =AVERAGE(I13:K13) -> 0 | AQ13: =AVERAGE(L13:N13) -> 0 | AR13: =AVERAGE(O13:Q13) -> 0 | AS13: =AVERAGE(R13:T13) -> 0 | AT13: =AVERAGE(U13:W13) -> 0 | AU13: =AVERAGE(X13:Z13) -> 0 | AV13: =AVERAGE(AA13:AC13) -> 0 | AW13: =AVERAGE(AD13:AF13) -> 0 | AX13: =AVERAGE(AG13:AI13) -> 0 | AY13: =AVERAGE(AJ13:AL13) -> 0 | BA13: =AVERAGE(C13:N13) -> 0 | BB13: =AVERAGE(O13:Z13) -> 0 | BC13: =AVERAGE(AA13:AL13) -> 0
A14: New Bookings | B14: New projects booked x average project value | C14: =C12*C13 -> 0 | D14: =D12*D13 -> 0 | E14: =E12*E13 -> 0 | F14: =F12*F13 -> 0 | G14: =G12*G13 -> 0 | H14: =H12*H13 -> 0 | I14: =I12*I13 -> 0 | J14: =J12*J13 -> 0 | ... AL14: =AL12*AL13 -> 0 | AN14: =SUM(C14:E14) -> 0 | AO14: =SUM(F14:H14) -> 0 | AP14: =SUM(I14:K14) -> 0 | AQ14: =SUM(L14:N14) -> 0 | AR14: =SUM(O14:Q14) -> 0 | AS14: =SUM(R14:T14) -> 0 | AT14: =SUM(U14:W14) -> 0 | AU14: =SUM(X14:Z14) -> 0 | AV14: =SUM(AA14:AC14) -> 0 | AW14: =SUM(AD14:AF14) -> 0 | AX14: =SUM(AG14:AI14) -> 0 | AY14: =SUM(AJ14:AL14) -> 0 | BA14: =SUM(C14:N14) -> 0 | BB14: =SUM(O14:Z14) -> 0 | BC14: =SUM(AA14:AL14) -> 0
A16: Delivery Capacity
A17: Delivery / Consulting FTE | B17: Linked from Headcount tab | C17: ='Headcount'!$C$8 -> 0 | D17: ='Headcount'!$D$8 -> 0 | E17: ='Headcount'!$E$8 -> 0 | F17: ='Headcount'!$F$8 -> 0 | G17: ='Headcount'!$G$8 -> 0 | H17: ='Headcount'!$H$8 -> 0 | I17: ='Headcount'!$I$8 -> 0 | J17: ='Headcount'!$J$8 -> 0 | K17: ='Headcount'!$K$8 -> 0 | L17: ='Headcount'!$L$8 -> 0 | M17: ='Headcount'!$M$8 -> 0 | N17: ='Headcount'!$N$8 -> 0 | O17: ='Headcount'!$O$8 -> 0 | P17: ='Headcount'!$P$8 -> 0 | Q17: ='Headcount'!$Q$8 -> 0 | R17: ='Headcount'!$R$8 -> 0 | S17: ='Headcount'!$S$8 -> 0 | T17: ='Headcount'!$T$8 -> 0 | U17: ='Headcount'!$U$8 -> 0 | V17: ='Headcount'!$V$8 -> 0 | W17: ='Headcount'!$W$8 -> 0 | X17: ='Headcount'!$X$8 -> 0 | Y17: ='Headcount'!$Y$8 -> 0 | Z17: ='Headcount'!$Z$8 -> 0 | AA17: ='Headcount'!$AA$8 -> 0 | AB17: ='Headcount'!$AB$8 -> 0 | AC17: ='Headcount'!$AC$8 -> 0 | AD17: ='Headcount'!$AD$8 -> 0 | AE17: ='Headcount'!$AE$8 -> 0 | AF17: ='Headcount'!$AF$8 -> 0 | AG17: ='Headcount'!$AG$8 -> 0 | AH17: ='Headcount'!$AH$8 -> 0 | AI17: ='Headcount'!$AI$8 -> 0 | AJ17: ='Headcount'!$AJ$8 -> 0 | AK17: ='Headcount'!$AK$8 -> 0 | AL17: ='Headcount'!$AL$8 -> 0 | AN17: =E17 -> 0 | AO17: =H17 -> 0 | AP17: =K17 -> 0 | AQ17: =N17 -> 0 | AR17: =Q17 -> 0 | AS17: =T17 -> 0 | AT17: =W17 -> 0 | AU17: =Z17 -> 0 | AV17: =AC17 -> 0 | AW17: =AF17 -> 0 | AX17: =AI17 -> 0 | AY17: =AL17 -> 0 | BA17: =N17 -> 0 | BB17: =Z17 -> 0 | BC17: =AL17 -> 0
A18: Standard billable-hours capacity / Delivery FTE | B18: Per-FTE monthly capacity before AI uplift and utilization | C18: ='Assumptions'!$F$22 -> 0 | D18: ='Assumptions'!$F$22 -> 0 | E18: ='Assumptions'!$F$22 -> 0 | F18: ='Assumptions'!$F$22 -> 0 | G18: ='Assumptions'!$F$22 -> 0 | H18: ='Assumptions'!$F$22 -> 0 | I18: ='Assumptions'!$F$22 -> 0 | J18: ='Assumptions'!$F$22 -> 0 | ... AL18: ='Assumptions'!$F$22 -> 0 | AN18: =AVERAGE(C18:E18) -> 0 | AO18: =AVERAGE(F18:H18) -> 0 | AP18: =AVERAGE(I18:K18) -> 0 | AQ18: =AVERAGE(L18:N18) -> 0 | AR18: =AVERAGE(O18:Q18) -> 0 | AS18: =AVERAGE(R18:T18) -> 0 | AT18: =AVERAGE(U18:W18) -> 0 | AU18: =AVERAGE(X18:Z18) -> 0 | AV18: =AVERAGE(AA18:AC18) -> 0 | AW18: =AVERAGE(AD18:AF18) -> 0 | AX18: =AVERAGE(AG18:AI18) -> 0 | AY18: =AVERAGE(AJ18:AL18) -> 0 | BA18: =AVERAGE(C18:N18) -> 0 | BB18: =AVERAGE(O18:Z18) -> 0 | BC18: =AVERAGE(AA18:AL18) -> 0
A19: Standard delivery capacity hours | B19: Delivery FTE x standard billable-hours capacity | C19: =C17*C18 -> 0 | D19: =D17*D18 -> 0 | E19: =E17*E18 -> 0 | F19: =F17*F18 -> 0 | G19: =G17*G18 -> 0 | H19: =H17*H18 -> 0 | I19: =I17*I18 -> 0 | J19: =J17*J18 -> 0 | ... AL19: =AL17*AL18 -> 0 | AN19: =SUM(C19:E19) -> 0 | AO19: =SUM(F19:H19) -> 0 | AP19: =SUM(I19:K19) -> 0 | AQ19: =SUM(L19:N19) -> 0 | AR19: =SUM(O19:Q19) -> 0 | AS19: =SUM(R19:T19) -> 0 | AT19: =SUM(U19:W19) -> 0 | AU19: =SUM(X19:Z19) -> 0 | AV19: =SUM(AA19:AC19) -> 0 | AW19: =SUM(AD19:AF19) -> 0 | AX19: =SUM(AG19:AI19) -> 0 | AY19: =SUM(AJ19:AL19) -> 0 | BA19: =SUM(C19:N19) -> 0 | BB19: =SUM(O19:Z19) -> 0 | BC19: =SUM(AA19:AL19) -> 0
A20: AI productivity uplift | B20: AI-assisted hours improve effective delivery capacity | C20: ='Assumptions'!$F$27 -> 0 | D20: ='Assumptions'!$F$27 -> 0 | E20: ='Assumptions'!$F$27 -> 0 | F20: ='Assumptions'!$F$27 -> 0 | G20: ='Assumptions'!$F$27 -> 0 | H20: ='Assumptions'!$F$27 -> 0 | I20: ='Assumptions'!$F$27 -> 0 | J20: ='Assumptions'!$F$27 -> 0 | ... AL20: ='Assumptions'!$F$27 -> 0 | AN20: =AVERAGE(C20:E20) -> 0 | AO20: =AVERAGE(F20:H20) -> 0 | AP20: =AVERAGE(I20:K20) -> 0 | AQ20: =AVERAGE(L20:N20) -> 0 | AR20: =AVERAGE(O20:Q20) -> 0 | AS20: =AVERAGE(R20:T20) -> 0 | AT20: =AVERAGE(U20:W20) -> 0 | AU20: =AVERAGE(X20:Z20) -> 0 | AV20: =AVERAGE(AA20:AC20) -> 0 | AW20: =AVERAGE(AD20:AF20) -> 0 | AX20: =AVERAGE(AG20:AI20) -> 0 | AY20: =AVERAGE(AJ20:AL20) -> 0 | BA20: =AVERAGE(C20:N20) -> 0 | BB20: =AVERAGE(O20:Z20) -> 0 | BC20: =AVERAGE(AA20:AL20) -> 0
A21: Effective capacity hours (post-AI) | B21: Standard capacity x (1 + AI productivity uplift) | C21: =C19*(1+C20) -> 0 | D21: =D19*(1+D20) -> 0 | E21: =E19*(1+E20) -> 0 | F21: =F19*(1+F20) -> 0 | G21: =G19*(1+G20) -> 0 | H21: =H19*(1+H20) -> 0 | I21: =I19*(1+I20) -> 0 | J21: =J19*(1+J20) -> 0 | ... AL21: =AL19*(1+AL20) -> 0 | AN21: =SUM(C21:E21) -> 0 | AO21: =SUM(F21:H21) -> 0 | AP21: =SUM(I21:K21) -> 0 | AQ21: =SUM(L21:N21) -> 0 | AR21: =SUM(O21:Q21) -> 0 | AS21: =SUM(R21:T21) -> 0 | AT21: =SUM(U21:W21) -> 0 | AU21: =SUM(X21:Z21) -> 0 | AV21: =SUM(AA21:AC21) -> 0 | AW21: =SUM(AD21:AF21) -> 0 | AX21: =SUM(AG21:AI21) -> 0 | AY21: =SUM(AJ21:AL21) -> 0 | BA21: =SUM(C21:N21) -> 0 | BB21: =SUM(O21:Z21) -> 0 | BC21: =SUM(AA21:AL21) -> 0
A22: Target utilization | B22: Share of effective capacity expected to be client-billable | C22: ='Assumptions'!$F$23 -> 0 | D22: ='Assumptions'!$F$23 -> 0 | E22: ='Assumptions'!$F$23 -> 0 | F22: ='Assumptions'!$F$23 -> 0 | G22: ='Assumptions'!$F$23 -> 0 | H22: ='Assumptions'!$F$23 -> 0 | I22: ='Assumptions'!$F$23 -> 0 | J22: ='Assumptions'!$F$23 -> 0 | ... AL22: ='Assumptions'!$F$23 -> 0 | AN22: =AVERAGE(C22:E22) -> 0 | AO22: =AVERAGE(F22:H22) -> 0 | AP22: =AVERAGE(I22:K22) -> 0 | AQ22: =AVERAGE(L22:N22) -> 0 | AR22: =AVERAGE(O22:Q22) -> 0 | AS22: =AVERAGE(R22:T22) -> 0 | AT22: =AVERAGE(U22:W22) -> 0 | AU22: =AVERAGE(X22:Z22) -> 0 | AV22: =AVERAGE(AA22:AC22) -> 0 | AW22: =AVERAGE(AD22:AF22) -> 0 | AX22: =AVERAGE(AG22:AI22) -> 0 | AY22: =AVERAGE(AJ22:AL22) -> 0 | BA22: =AVERAGE(C22:N22) -> 0 | BB22: =AVERAGE(O22:Z22) -> 0 | BC22: =AVERAGE(AA22:AL22) -> 0
A23: Standard blended billing rate | B23: Starting rate grown by monthly price/mix improvement | C23: ='Assumptions'!$F$25 -> 0 | D23: =C23*(1+'Assumptions'!$F$26) -> 0 | E23: =D23*(1+'Assumptions'!$F$26) -> 0 | F23: =E23*(1+'Assumptions'!$F$26) -> 0 | G23: =F23*(1+'Assumptions'!$F$26) -> 0 | H23: =G23*(1+'Assumptions'!$F$26) -> 0 | I23: =H23*(1+'Assumptions'!$F$26) -> 0 | J23: =I23*(1+'Assumptions'!$F$26) -> 0 | K23: =J23*(1+'Assumptions'!$F$26) -> 0 | ... AL23: =AK23*(1+'Assumptions'!$F$26) -> 0 | AN23: =AVERAGE(C23:E23) -> 0 | AO23: =AVERAGE(F23:H23) -> 0 | AP23: =AVERAGE(I23:K23) -> 0 | AQ23: =AVERAGE(L23:N23) -> 0 | AR23: =AVERAGE(O23:Q23) -> 0 | AS23: =AVERAGE(R23:T23) -> 0 | AT23: =AVERAGE(U23:W23) -> 0 | AU23: =AVERAGE(X23:Z23) -> 0 | AV23: =AVERAGE(AA23:AC23) -> 0 | AW23: =AVERAGE(AD23:AF23) -> 0 | AX23: =AVERAGE(AG23:AI23) -> 0 | AY23: =AVERAGE(AJ23:AL23) -> 0 | BA23: =AVERAGE(C23:N23) -> 0 | BB23: =AVERAGE(O23:Z23) -> 0 | BC23: =AVERAGE(AA23:AL23) -> 0
A24: Realization rate | B24: Collected / billed rate versus standard rate | C24: ='Assumptions'!$F$24 -> 0 | D24: ='Assumptions'!$F$24 -> 0 | E24: ='Assumptions'!$F$24 -> 0 | F24: ='Assumptions'!$F$24 -> 0 | G24: ='Assumptions'!$F$24 -> 0 | H24: ='Assumptions'!$F$24 -> 0 | I24: ='Assumptions'!$F$24 -> 0 | J24: ='Assumptions'!$F$24 -> 0 | ... AL24: ='Assumptions'!$F$24 -> 0 | AN24: =AVERAGE(C24:E24) -> 0 | AO24: =AVERAGE(F24:H24) -> 0 | AP24: =AVERAGE(I24:K24) -> 0 | AQ24: =AVERAGE(L24:N24) -> 0 | AR24: =AVERAGE(O24:Q24) -> 0 | AS24: =AVERAGE(R24:T24) -> 0 | AT24: =AVERAGE(U24:W24) -> 0 | AU24: =AVERAGE(X24:Z24) -> 0 | AV24: =AVERAGE(AA24:AC24) -> 0 | AW24: =AVERAGE(AD24:AF24) -> 0 | AX24: =AVERAGE(AG24:AI24) -> 0 | AY24: =AVERAGE(AJ24:AL24) -> 0 | BA24: =AVERAGE(C24:N24) -> 0 | BB24: =AVERAGE(O24:Z24) -> 0 | BC24: =AVERAGE(AA24:AL24) -> 0
A25: Realized billing rate | B25: Standard blended rate x realization rate | C25: =C23*C24 -> 0 | D25: =D23*D24 -> 0 | E25: =E23*E24 -> 0 | F25: =F23*F24 -> 0 | G25: =G23*G24 -> 0 | H25: =H23*H24 -> 0 | I25: =I23*I24 -> 0 | J25: =J23*J24 -> 0 | ... AL25: =AL23*AL24 -> 0 | AN25: =AVERAGE(C25:E25) -> 0 | AO25: =AVERAGE(F25:H25) -> 0 | AP25: =AVERAGE(I25:K25) -> 0 | AQ25: =AVERAGE(L25:N25) -> 0 | AR25: =AVERAGE(O25:Q25) -> 0 | AS25: =AVERAGE(R25:T25) -> 0 | AT25: =AVERAGE(U25:W25) -> 0 | AU25: =AVERAGE(X25:Z25) -> 0 | AV25: =AVERAGE(AA25:AC25) -> 0 | AW25: =AVERAGE(AD25:AF25) -> 0 | AX25: =AVERAGE(AG25:AI25) -> 0 | AY25: =AVERAGE(AJ25:AL25) -> 0 | BA25: =AVERAGE(C25:N25) -> 0 | BB25: =AVERAGE(O25:Z25) -> 0 | BC25: =AVERAGE(AA25:AL25) -> 0
A26: Revenue capacity at target utilization | B26: Effective capacity hours x utilization x realized rate | C26: =C21*C22*C25 -> 0 | D26: =D21*D22*D25 -> 0 | E26: =E21*E22*E25 -> 0 | F26: =F21*F22*F25 -> 0 | G26: =G21*G22*G25 -> 0 | H26: =H21*H22*H25 -> 0 | I26: =I21*I22*I25 -> 0 | J26: =J21*J22*J25 -> 0 | ... AL26: =AL21*AL22*AL25 -> 0 | AN26: =SUM(C26:E26) -> 0 | AO26: =SUM(F26:H26) -> 0 | AP26: =SUM(I26:K26) -> 0 | AQ26: =SUM(L26:N26) -> 0 | AR26: =SUM(O26:Q26) -> 0 | AS26: =SUM(R26:T26) -> 0 | AT26: =SUM(U26:W26) -> 0 | AU26: =SUM(X26:Z26) -> 0 | AV26: =SUM(AA26:AC26) -> 0 | AW26: =SUM(AD26:AF26) -> 0 | AX26: =SUM(AG26:AI26) -> 0 | AY26: =SUM(AJ26:AL26) -> 0 | BA26: =SUM(C26:N26) -> 0 | BB26: =SUM(O26:Z26) -> 0 | BC26: =SUM(AA26:AL26) -> 0
A28: Backlog & Revenue Recognition
A29: Beginning Backlog | B29: Prior month ending backlog; month 1 seeded from assumptions | C29: ='Assumptions'!$F$13 -> 0 | D29: =C35 -> 0 | E29: =D35 -> 0 | F29: =E35 -> 0 | G29: =F35 -> 0 | H29: =G35 -> 0 | I29: =H35 -> 0 | J29: =I35 -> 0 | K29: =J35 -> 0 | ... AL29: =AK35 -> 0 | AN29: =E29 -> 0 | AO29: =H29 -> 0 | AP29: =K29 -> 0 | AQ29: =N29 -> 0 | AR29: =Q29 -> 0 | AS29: =T29 -> 0 | AT29: =W29 -> 0 | AU29: =Z29 -> 0 | AV29: =AC29 -> 0 | AW29: =AF29 -> 0 | AX29: =AI29 -> 0 | AY29: =AL29 -> 0 | BA29: =N29 -> 0 | BB29: =Z29 -> 0 | BC29: =AL29 -> 0
A30: + New Bookings | B30: Linked from Pipeline & Bookings above | C30: ='Revenue'!$C$14 -> 0 | D30: ='Revenue'!$D$14 -> 0 | E30: ='Revenue'!$E$14 -> 0 | F30: ='Revenue'!$F$14 -> 0 | G30: ='Revenue'!$G$14 -> 0 | H30: ='Revenue'!$H$14 -> 0 | I30: ='Revenue'!$I$14 -> 0 | J30: ='Revenue'!$J$14 -> 0 | K30: ='Revenue'!$K$14 -> 0 | L30: ='Revenue'!$L$14 -> 0 | M30: ='Revenue'!$M$14 -> 0 | N30: ='Revenue'!$N$14 -> 0 | O30: ='Revenue'!$O$14 -> 0 | P30: ='Revenue'!$P$14 -> 0 | Q30: ='Revenue'!$Q$14 -> 0 | R30: ='Revenue'!$R$14 -> 0 | S30: ='Revenue'!$S$14 -> 0 | T30: ='Revenue'!$T$14 -> 0 | U30: ='Revenue'!$U$14 -> 0 | V30: ='Revenue'!$V$14 -> 0 | W30: ='Revenue'!$W$14 -> 0 | X30: ='Revenue'!$X$14 -> 0 | Y30: ='Revenue'!$Y$14 -> 0 | Z30: ='Revenue'!$Z$14 -> 0 | AA30: ='Revenue'!$AA$14 -> 0 | AB30: ='Revenue'!$AB$14 -> 0 | AC30: ='Revenue'!$AC$14 -> 0 | AD30: ='Revenue'!$AD$14 -> 0 | AE30: ='Revenue'!$AE$14 -> 0 | AF30: ='Revenue'!$AF$14 -> 0 | AG30: ='Revenue'!$AG$14 -> 0 | AH30: ='Revenue'!$AH$14 -> 0 | AI30: ='Revenue'!$AI$14 -> 0 | AJ30: ='Revenue'!$AJ$14 -> 0 | AK30: ='Revenue'!$AK$14 -> 0 | AL30: ='Revenue'!$AL$14 -> 0 | AN30: =SUM(C30:E30) -> 0 | AO30: =SUM(F30:H30) -> 0 | AP30: =SUM(I30:K30) -> 0 | AQ30: =SUM(L30:N30) -> 0 | AR30: =SUM(O30:Q30) -> 0 | AS30: =SUM(R30:T30) -> 0 | AT30: =SUM(U30:W30) -> 0 | AU30: =SUM(X30:Z30) -> 0 | AV30: =SUM(AA30:AC30) -> 0 | AW30: =SUM(AD30:AF30) -> 0 | AX30: =SUM(AG30:AI30) -> 0 | AY30: =SUM(AJ30:AL30) -> 0 | BA30: =SUM(C30:N30) -> 0 | BB30: =SUM(O30:Z30) -> 0 | BC30: =SUM(AA30:AL30) -> 0
A31: Backlog available to deliver | B31: Beginning backlog + new bookings | C31: =C29+'Revenue'!C14 -> 0 | D31: =D29+'Revenue'!D14 -> 0 | E31: =E29+'Revenue'!E14 -> 0 | F31: =F29+'Revenue'!F14 -> 0 | G31: =G29+'Revenue'!G14 -> 0 | H31: =H29+'Revenue'!H14 -> 0 | I31: =I29+'Revenue'!I14 -> 0 | J31: =J29+'Revenue'!J14 -> 0 | ... AL31: =AL29+'Revenue'!AL14 -> 0 | AN31: =E31 -> 0 | AO31: =H31 -> 0 | AP31: =K31 -> 0 | AQ31: =N31 -> 0 | AR31: =Q31 -> 0 | AS31: =T31 -> 0 | AT31: =W31 -> 0 | AU31: =Z31 -> 0 | AV31: =AC31 -> 0 | AW31: =AF31 -> 0 | AX31: =AI31 -> 0 | AY31: =AL31 -> 0 | BA31: =N31 -> 0 | BB31: =Z31 -> 0 | BC31: =AL31 -> 0
A32: Revenue recognized at project-duration pace | B32: Backlog available / average project duration | C32: =C31/MAX(1,'Assumptions'!$F$19) -> 0 | D32: =D31/MAX(1,'Assumptions'!$F$19) -> 0 | E32: =E31/MAX(1,'Assumptions'!$F$19) -> 0 | F32: =F31/MAX(1,'Assumptions'!$F$19) -> 0 | G32: =G31/MAX(1,'Assumptions'!$F$19) -> 0 | H32: =H31/MAX(1,'Assumptions'!$F$19) -> 0 | I32: =I31/MAX(1,'Assumptions'!$F$19) -> 0 | J32: =J31/MAX(1,'Assumptions'!$F$19) -> 0 | ... AL32: =AL31/MAX(1,'Assumptions'!$F$19) -> 0 | AN32: =SUM(C32:E32) -> 0 | AO32: =SUM(F32:H32) -> 0 | AP32: =SUM(I32:K32) -> 0 | AQ32: =SUM(L32:N32) -> 0 | AR32: =SUM(O32:Q32) -> 0 | AS32: =SUM(R32:T32) -> 0 | AT32: =SUM(U32:W32) -> 0 | AU32: =SUM(X32:Z32) -> 0 | AV32: =SUM(AA32:AC32) -> 0 | AW32: =SUM(AD32:AF32) -> 0 | AX32: =SUM(AG32:AI32) -> 0 | AY32: =SUM(AJ32:AL32) -> 0 | BA32: =SUM(C32:N32) -> 0 | BB32: =SUM(O32:Z32) -> 0 | BC32: =SUM(AA32:AL32) -> 0
A33: Revenue recognized at delivery capacity | B33: Linked from delivery-capacity calculation above | C33: ='Revenue'!$C$26 -> 0 | D33: ='Revenue'!$D$26 -> 0 | E33: ='Revenue'!$E$26 -> 0 | F33: ='Revenue'!$F$26 -> 0 | G33: ='Revenue'!$G$26 -> 0 | H33: ='Revenue'!$H$26 -> 0 | I33: ='Revenue'!$I$26 -> 0 | J33: ='Revenue'!$J$26 -> 0 | K33: ='Revenue'!$K$26 -> 0 | L33: ='Revenue'!$L$26 -> 0 | M33: ='Revenue'!$M$26 -> 0 | N33: ='Revenue'!$N$26 -> 0 | O33: ='Revenue'!$O$26 -> 0 | P33: ='Revenue'!$P$26 -> 0 | Q33: ='Revenue'!$Q$26 -> 0 | R33: ='Revenue'!$R$26 -> 0 | S33: ='Revenue'!$S$26 -> 0 | T33: ='Revenue'!$T$26 -> 0 | U33: ='Revenue'!$U$26 -> 0 | V33: ='Revenue'!$V$26 -> 0 | W33: ='Revenue'!$W$26 -> 0 | X33: ='Revenue'!$X$26 -> 0 | Y33: ='Revenue'!$Y$26 -> 0 | Z33: ='Revenue'!$Z$26 -> 0 | AA33: ='Revenue'!$AA$26 -> 0 | AB33: ='Revenue'!$AB$26 -> 0 | AC33: ='Revenue'!$AC$26 -> 0 | AD33: ='Revenue'!$AD$26 -> 0 | AE33: ='Revenue'!$AE$26 -> 0 | AF33: ='Revenue'!$AF$26 -> 0 | AG33: ='Revenue'!$AG$26 -> 0 | AH33: ='Revenue'!$AH$26 -> 0 | AI33: ='Revenue'!$AI$26 -> 0 | AJ33: ='Revenue'!$AJ$26 -> 0 | AK33: ='Revenue'!$AK$26 -> 0 | AL33: ='Revenue'!$AL$26 -> 0 | AN33: =SUM(C33:E33) -> 0 | AO33: =SUM(F33:H33) -> 0 | AP33: =SUM(I33:K33) -> 0 | AQ33: =SUM(L33:N33) -> 0 | AR33: =SUM(O33:Q33) -> 0 | AS33: =SUM(R33:T33) -> 0 | AT33: =SUM(U33:W33) -> 0 | AU33: =SUM(X33:Z33) -> 0 | AV33: =SUM(AA33:AC33) -> 0 | AW33: =SUM(AD33:AF33) -> 0 | AX33: =SUM(AG33:AI33) -> 0 | AY33: =SUM(AJ33:AL33) -> 0 | BA33: =SUM(C33:N33) -> 0 | BB33: =SUM(O33:Z33) -> 0 | BC33: =SUM(AA33:AL33) -> 0
A34: Revenue Recognized | B34: The lower of backlog runoff pace and delivery capacity | C34: =MIN(C32,C33) -> 0 | D34: =MIN(D32,D33) -> 0 | E34: =MIN(E32,E33) -> 0 | F34: =MIN(F32,F33) -> 0 | G34: =MIN(G32,G33) -> 0 | H34: =MIN(H32,H33) -> 0 | I34: =MIN(I32,I33) -> 0 | J34: =MIN(J32,J33) -> 0 | ... AL34: =MIN(AL32,AL33) -> 0 | AN34: =SUM(C34:E34) -> 0 | AO34: =SUM(F34:H34) -> 0 | AP34: =SUM(I34:K34) -> 0 | AQ34: =SUM(L34:N34) -> 0 | AR34: =SUM(O34:Q34) -> 0 | AS34: =SUM(R34:T34) -> 0 | AT34: =SUM(U34:W34) -> 0 | AU34: =SUM(X34:Z34) -> 0 | AV34: =SUM(AA34:AC34) -> 0 | AW34: =SUM(AD34:AF34) -> 0 | AX34: =SUM(AG34:AI34) -> 0 | AY34: =SUM(AJ34:AL34) -> 0 | BA34: =SUM(C34:N34) -> 0 | BB34: =SUM(O34:Z34) -> 0 | BC34: =SUM(AA34:AL34) -> 0
A35: Ending Backlog | B35: Backlog available to deliver - revenue recognized | C35: =C31-C34 -> 0 | D35: =D31-D34 -> 0 | E35: =E31-E34 -> 0 | F35: =F31-F34 -> 0 | G35: =G31-G34 -> 0 | H35: =H31-H34 -> 0 | I35: =I31-I34 -> 0 | J35: =J31-J34 -> 0 | ... AL35: =AL31-AL34 -> 0 | AN35: =E35 -> 0 | AO35: =H35 -> 0 | AP35: =K35 -> 0 | AQ35: =N35 -> 0 | AR35: =Q35 -> 0 | AS35: =T35 -> 0 | AT35: =W35 -> 0 | AU35: =Z35 -> 0 | AV35: =AC35 -> 0 | AW35: =AF35 -> 0 | AX35: =AI35 -> 0 | AY35: =AL35 -> 0 | BA35: =N35 -> 0 | BB35: =Z35 -> 0 | BC35: =AL35 -> 0
A36: Total Revenue | B36: Services revenue equals recognized project delivery | C36: ='Revenue'!$C$34 -> 0 | D36: ='Revenue'!$D$34 -> 0 | E36: ='Revenue'!$E$34 -> 0 | F36: ='Revenue'!$F$34 -> 0 | G36: ='Revenue'!$G$34 -> 0 | H36: ='Revenue'!$H$34 -> 0 | I36: ='Revenue'!$I$34 -> 0 | J36: ='Revenue'!$J$34 -> 0 | K36: ='Revenue'!$K$34 -> 0 | L36: ='Revenue'!$L$34 -> 0 | M36: ='Revenue'!$M$34 -> 0 | N36: ='Revenue'!$N$34 -> 0 | O36: ='Revenue'!$O$34 -> 0 | P36: ='Revenue'!$P$34 -> 0 | Q36: ='Revenue'!$Q$34 -> 0 | R36: ='Revenue'!$R$34 -> 0 | S36: ='Revenue'!$S$34 -> 0 | T36: ='Revenue'!$T$34 -> 0 | U36: ='Revenue'!$U$34 -> 0 | V36: ='Revenue'!$V$34 -> 0 | W36: ='Revenue'!$W$34 -> 0 | X36: ='Revenue'!$X$34 -> 0 | Y36: ='Revenue'!$Y$34 -> 0 | Z36: ='Revenue'!$Z$34 -> 0 | AA36: ='Revenue'!$AA$34 -> 0 | AB36: ='Revenue'!$AB$34 -> 0 | AC36: ='Revenue'!$AC$34 -> 0 | AD36: ='Revenue'!$AD$34 -> 0 | AE36: ='Revenue'!$AE$34 -> 0 | AF36: ='Revenue'!$AF$34 -> 0 | AG36: ='Revenue'!$AG$34 -> 0 | AH36: ='Revenue'!$AH$34 -> 0 | AI36: ='Revenue'!$AI$34 -> 0 | AJ36: ='Revenue'!$AJ$34 -> 0 | AK36: ='Revenue'!$AK$34 -> 0 | AL36: ='Revenue'!$AL$34 -> 0 | AN36: =SUM(C36:E36) -> 0 | AO36: =SUM(F36:H36) -> 0 | AP36: =SUM(I36:K36) -> 0 | AQ36: =SUM(L36:N36) -> 0 | AR36: =SUM(O36:Q36) -> 0 | AS36: =SUM(R36:T36) -> 0 | AT36: =SUM(U36:W36) -> 0 | AU36: =SUM(X36:Z36) -> 0 | AV36: =SUM(AA36:AC36) -> 0 | AW36: =SUM(AD36:AF36) -> 0 | AX36: =SUM(AG36:AI36) -> 0 | AY36: =SUM(AJ36:AL36) -> 0 | BA36: =SUM(C36:N36) -> 0 | BB36: =SUM(O36:Z36) -> 0 | BC36: =SUM(AA36:AL36) -> 0
A38: Service Delivery KPIs
A39: Billable hours delivered | B39: Revenue recognized / realized billing rate | C39: =IFERROR(C34/C25,0) -> 0 | D39: =IFERROR(D34/D25,0) -> 0 | E39: =IFERROR(E34/E25,0) -> 0 | F39: =IFERROR(F34/F25,0) -> 0 | G39: =IFERROR(G34/G25,0) -> 0 | H39: =IFERROR(H34/H25,0) -> 0 | I39: =IFERROR(I34/I25,0) -> 0 | J39: =IFERROR(J34/J25,0) -> 0 | ... AL39: =IFERROR(AL34/AL25,0) -> 0 | AN39: =SUM(C39:E39) -> 0 | AO39: =SUM(F39:H39) -> 0 | AP39: =SUM(I39:K39) -> 0 | AQ39: =SUM(L39:N39) -> 0 | AR39: =SUM(O39:Q39) -> 0 | AS39: =SUM(R39:T39) -> 0 | AT39: =SUM(U39:W39) -> 0 | AU39: =SUM(X39:Z39) -> 0 | AV39: =SUM(AA39:AC39) -> 0 | AW39: =SUM(AD39:AF39) -> 0 | AX39: =SUM(AG39:AI39) -> 0 | AY39: =SUM(AJ39:AL39) -> 0 | BA39: =SUM(C39:N39) -> 0 | BB39: =SUM(O39:Z39) -> 0 | BC39: =SUM(AA39:AL39) -> 0
A40: Utilization % | B40: Billable hours delivered / effective capacity hours | C40: =IFERROR(C39/C21,0) -> 0 | D40: =IFERROR(D39/D21,0) -> 0 | E40: =IFERROR(E39/E21,0) -> 0 | F40: =IFERROR(F39/F21,0) -> 0 | G40: =IFERROR(G39/G21,0) -> 0 | H40: =IFERROR(H39/H21,0) -> 0 | I40: =IFERROR(I39/I21,0) -> 0 | J40: =IFERROR(J39/J21,0) -> 0 | ... AL40: =IFERROR(AL39/AL21,0) -> 0 | AN40: =AVERAGE(C40:E40) -> 0 | AO40: =AVERAGE(F40:H40) -> 0 | AP40: =AVERAGE(I40:K40) -> 0 | AQ40: =AVERAGE(L40:N40) -> 0 | AR40: =AVERAGE(O40:Q40) -> 0 | AS40: =AVERAGE(R40:T40) -> 0 | AT40: =AVERAGE(U40:W40) -> 0 | AU40: =AVERAGE(X40:Z40) -> 0 | AV40: =AVERAGE(AA40:AC40) -> 0 | AW40: =AVERAGE(AD40:AF40) -> 0 | AX40: =AVERAGE(AG40:AI40) -> 0 | AY40: =AVERAGE(AJ40:AL40) -> 0 | BA40: =AVERAGE(C40:N40) -> 0 | BB40: =AVERAGE(O40:Z40) -> 0 | BC40: =AVERAGE(AA40:AL40) -> 0
A41: Realization % | B41: Realized rate / standard blended billing rate | C41: =IFERROR(C25/C23,0) -> 0 | D41: =IFERROR(D25/D23,0) -> 0 | E41: =IFERROR(E25/E23,0) -> 0 | F41: =IFERROR(F25/F23,0) -> 0 | G41: =IFERROR(G25/G23,0) -> 0 | H41: =IFERROR(H25/H23,0) -> 0 | I41: =IFERROR(I25/I23,0) -> 0 | J41: =IFERROR(J25/J23,0) -> 0 | ... AL41: =IFERROR(AL25/AL23,0) -> 0 | AN41: =AVERAGE(C41:E41) -> 0 | AO41: =AVERAGE(F41:H41) -> 0 | AP41: =AVERAGE(I41:K41) -> 0 | AQ41: =AVERAGE(L41:N41) -> 0 | AR41: =AVERAGE(O41:Q41) -> 0 | AS41: =AVERAGE(R41:T41) -> 0 | AT41: =AVERAGE(U41:W41) -> 0 | AU41: =AVERAGE(X41:Z41) -> 0 | AV41: =AVERAGE(AA41:AC41) -> 0 | AW41: =AVERAGE(AD41:AF41) -> 0 | AX41: =AVERAGE(AG41:AI41) -> 0 | AY41: =AVERAGE(AJ41:AL41) -> 0 | BA41: =AVERAGE(C41:N41) -> 0 | BB41: =AVERAGE(O41:Z41) -> 0 | BC41: =AVERAGE(AA41:AL41) -> 0
A42: Revenue per Delivery FTE | B42: Total revenue / delivery FTE | C42: =IFERROR(C36/C17,0) -> 0 | D42: =IFERROR(D36/D17,0) -> 0 | E42: =IFERROR(E36/E17,0) -> 0 | F42: =IFERROR(F36/F17,0) -> 0 | G42: =IFERROR(G36/G17,0) -> 0 | H42: =IFERROR(H36/H17,0) -> 0 | I42: =IFERROR(I36/I17,0) -> 0 | J42: =IFERROR(J36/J17,0) -> 0 | ... AL42: =IFERROR(AL36/AL17,0) -> 0 | AN42: =AVERAGE(C42:E42) -> 0 | AO42: =AVERAGE(F42:H42) -> 0 | AP42: =AVERAGE(I42:K42) -> 0 | AQ42: =AVERAGE(L42:N42) -> 0 | AR42: =AVERAGE(O42:Q42) -> 0 | AS42: =AVERAGE(R42:T42) -> 0 | AT42: =AVERAGE(U42:W42) -> 0 | AU42: =AVERAGE(X42:Z42) -> 0 | AV42: =AVERAGE(AA42:AC42) -> 0 | AW42: =AVERAGE(AD42:AF42) -> 0 | AX42: =AVERAGE(AG42:AI42) -> 0 | AY42: =AVERAGE(AJ42:AL42) -> 0 | BA42: =AVERAGE(C42:N42) -> 0 | BB42: =AVERAGE(O42:Z42) -> 0 | BC42: =AVERAGE(AA42:AL42) -> 0
A43: Trailing 3-month avg revenue | B43: Used for backlog coverage KPI | C43: =AVERAGE(C36:C36) -> 0 | D43: =AVERAGE(C36:D36) -> 0 | E43: =AVERAGE(C36:E36) -> 0 | F43: =AVERAGE(D36:F36) -> 0 | G43: =AVERAGE(E36:G36) -> 0 | H43: =AVERAGE(F36:H36) -> 0 | I43: =AVERAGE(G36:I36) -> 0 | J43: =AVERAGE(H36:J36) -> 0 | K43: =AVERAGE(I36:K36) -> 0 | L43: =AVERAGE(J36:L36) -> 0 | ... AL43: =AVERAGE(AJ36:AL36) -> 0 | AN43: =AVERAGE(C43:E43) -> 0 | AO43: =AVERAGE(F43:H43) -> 0 | AP43: =AVERAGE(I43:K43) -> 0 | AQ43: =AVERAGE(L43:N43) -> 0 | AR43: =AVERAGE(O43:Q43) -> 0 | AS43: =AVERAGE(R43:T43) -> 0 | AT43: =AVERAGE(U43:W43) -> 0 | AU43: =AVERAGE(X43:Z43) -> 0 | AV43: =AVERAGE(AA43:AC43) -> 0 | AW43: =AVERAGE(AD43:AF43) -> 0 | AX43: =AVERAGE(AG43:AI43) -> 0 | AY43: =AVERAGE(AJ43:AL43) -> 0 | BA43: =AVERAGE(C43:N43) -> 0 | BB43: =AVERAGE(O43:Z43) -> 0 | BC43: =AVERAGE(AA43:AL43) -> 0
A44: Backlog coverage (months) | B44: Ending backlog / trailing 3-month revenue run-rate | C44: =IFERROR(C35/C43,0) -> 0 | D44: =IFERROR(D35/D43,0) -> 0 | E44: =IFERROR(E35/E43,0) -> 0 | F44: =IFERROR(F35/F43,0) -> 0 | G44: =IFERROR(G35/G43,0) -> 0 | H44: =IFERROR(H35/H43,0) -> 0 | I44: =IFERROR(I35/I43,0) -> 0 | J44: =IFERROR(J35/J43,0) -> 0 | ... AL44: =IFERROR(AL35/AL43,0) -> 0 | AN44: =AVERAGE(C44:E44) -> 0 | AO44: =AVERAGE(F44:H44) -> 0 | AP44: =AVERAGE(I44:K44) -> 0 | AQ44: =AVERAGE(L44:N44) -> 0 | AR44: =AVERAGE(O44:Q44) -> 0 | AS44: =AVERAGE(R44:T44) -> 0 | AT44: =AVERAGE(U44:W44) -> 0 | AU44: =AVERAGE(X44:Z44) -> 0 | AV44: =AVERAGE(AA44:AC44) -> 0 | AW44: =AVERAGE(AD44:AF44) -> 0 | AX44: =AVERAGE(AG44:AI44) -> 0 | AY44: =AVERAGE(AJ44:AL44) -> 0 | BA44: =AVERAGE(C44:N44) -> 0 | BB44: =AVERAGE(O44:Z44) -> 0 | BC44: =AVERAGE(AA44:AL44) -> 0
A45: AI productivity uplift | B45: Effective capacity / standard capacity - 1 | C45: =IFERROR(C21/C19-1,0) -> 0 | D45: =IFERROR(D21/D19-1,0) -> 0 | E45: =IFERROR(E21/E19-1,0) -> 0 | F45: =IFERROR(F21/F19-1,0) -> 0 | G45: =IFERROR(G21/G19-1,0) -> 0 | H45: =IFERROR(H21/H19-1,0) -> 0 | I45: =IFERROR(I21/I19-1,0) -> 0 | J45: =IFERROR(J21/J19-1,0) -> 0 | ... AL45: =IFERROR(AL21/AL19-1,0) -> 0 | AN45: =AVERAGE(C45:E45) -> 0 | AO45: =AVERAGE(F45:H45) -> 0 | AP45: =AVERAGE(I45:K45) -> 0 | AQ45: =AVERAGE(L45:N45) -> 0 | AR45: =AVERAGE(O45:Q45) -> 0 | AS45: =AVERAGE(R45:T45) -> 0 | AT45: =AVERAGE(U45:W45) -> 0 | AU45: =AVERAGE(X45:Z45) -> 0 | AV45: =AVERAGE(AA45:AC45) -> 0 | AW45: =AVERAGE(AD45:AF45) -> 0 | AX45: =AVERAGE(AG45:AI45) -> 0 | AY45: =AVERAGE(AJ45:AL45) -> 0 | BA45: =AVERAGE(C45:N45) -> 0 | BB45: =AVERAGE(O45:Z45) -> 0 | BC45: =AVERAGE(AA45:AL45) -> 0

Sheet COGS & GM
A1: AI-Enabled Services — 3-Year Financial Model — COGS & GM
A2: Delivery people, subcontractors, and AI tool/API spend roll up into project gross margin.
A5: Line item | B5: Units / source | C5: Monthly (36 months) | AN5: Quarterly | BA5: Annual
C6: 46023 | D6: 46054 | E6: 46082 | F6: 46113 | G6: 46143 | H6: 46174 | I6: 46204 | J6: 46235 | K6: 46266 | L6: 46296 | M6: 46327 | N6: 46357 | O6: 46388 | P6: 46419 | Q6: 46447 | R6: 46478 | S6: 46508 | T6: 46539 | U6: 46569 | V6: 46600 | W6: 46631 | X6: 46661 | Y6: 46692 | Z6: 46722 | AA6: 46753 | AB6: 46784 | AC6: 46813 | AD6: 46844 | AE6: 46874 | AF6: 46905 | AG6: 46935 | AH6: 46966 | AI6: 46997 | AJ6: 47027 | AK6: 47058 | AL6: 47088 | AN6: Q1 | AO6: Q2 | AP6: Q3 | AQ6: Q4 | AR6: Q5 | AS6: Q6 | AT6: Q7 | AU6: Q8 | AV6: Q9 | AW6: Q10 | AX6: Q11 | AY6: Q12 | BA6: FY1 | BB6: FY2 | BC6: FY3
A7: COGS Components
A8: Delivery / Consulting people cost | B8: Linked from Headcount tab | C8: ='Headcount'!$C$9 -> 0 | D8: ='Headcount'!$D$9 -> 0 | E8: ='Headcount'!$E$9 -> 0 | F8: ='Headcount'!$F$9 -> 0 | G8: ='Headcount'!$G$9 -> 0 | H8: ='Headcount'!$H$9 -> 0 | I8: ='Headcount'!$I$9 -> 0 | J8: ='Headcount'!$J$9 -> 0 | K8: ='Headcount'!$K$9 -> 0 | L8: ='Headcount'!$L$9 -> 0 | M8: ='Headcount'!$M$9 -> 0 | N8: ='Headcount'!$N$9 -> 0 | O8: ='Headcount'!$O$9 -> 0 | P8: ='Headcount'!$P$9 -> 0 | Q8: ='Headcount'!$Q$9 -> 0 | R8: ='Headcount'!$R$9 -> 0 | S8: ='Headcount'!$S$9 -> 0 | T8: ='Headcount'!$T$9 -> 0 | U8: ='Headcount'!$U$9 -> 0 | V8: ='Headcount'!$V$9 -> 0 | W8: ='Headcount'!$W$9 -> 0 | X8: ='Headcount'!$X$9 -> 0 | Y8: ='Headcount'!$Y$9 -> 0 | Z8: ='Headcount'!$Z$9 -> 0 | AA8: ='Headcount'!$AA$9 -> 0 | AB8: ='Headcount'!$AB$9 -> 0 | AC8: ='Headcount'!$AC$9 -> 0 | AD8: ='Headcount'!$AD$9 -> 0 | AE8: ='Headcount'!$AE$9 -> 0 | AF8: ='Headcount'!$AF$9 -> 0 | AG8: ='Headcount'!$AG$9 -> 0 | AH8: ='Headcount'!$AH$9 -> 0 | AI8: ='Headcount'!$AI$9 -> 0 | AJ8: ='Headcount'!$AJ$9 -> 0 | AK8: ='Headcount'!$AK$9 -> 0 | AL8: ='Headcount'!$AL$9 -> 0 | AN8: =SUM(C8:E8) -> 0 | AO8: =SUM(F8:H8) -> 0 | AP8: =SUM(I8:K8) -> 0 | AQ8: =SUM(L8:N8) -> 0 | AR8: =SUM(O8:Q8) -> 0 | AS8: =SUM(R8:T8) -> 0 | AT8: =SUM(U8:W8) -> 0 | AU8: =SUM(X8:Z8) -> 0 | AV8: =SUM(AA8:AC8) -> 0 | AW8: =SUM(AD8:AF8) -> 0 | AX8: =SUM(AG8:AI8) -> 0 | AY8: =SUM(AJ8:AL8) -> 0 | BA8: =SUM(C8:N8) -> 0 | BB8: =SUM(O8:Z8) -> 0 | BC8: =SUM(AA8:AL8) -> 0
A9: Delivery Management / Solutions people cost | B9: Linked from Headcount tab | C9: ='Headcount'!$C$11 -> 0 | D9: ='Headcount'!$D$11 -> 0 | E9: ='Headcount'!$E$11 -> 0 | F9: ='Headcount'!$F$11 -> 0 | G9: ='Headcount'!$G$11 -> 0 | H9: ='Headcount'!$H$11 -> 0 | I9: ='Headcount'!$I$11 -> 0 | J9: ='Headcount'!$J$11 -> 0 | K9: ='Headcount'!$K$11 -> 0 | L9: ='Headcount'!$L$11 -> 0 | M9: ='Headcount'!$M$11 -> 0 | N9: ='Headcount'!$N$11 -> 0 | O9: ='Headcount'!$O$11 -> 0 | P9: ='Headcount'!$P$11 -> 0 | Q9: ='Headcount'!$Q$11 -> 0 | R9: ='Headcount'!$R$11 -> 0 | S9: ='Headcount'!$S$11 -> 0 | T9: ='Headcount'!$T$11 -> 0 | U9: ='Headcount'!$U$11 -> 0 | V9: ='Headcount'!$V$11 -> 0 | W9: ='Headcount'!$W$11 -> 0 | X9: ='Headcount'!$X$11 -> 0 | Y9: ='Headcount'!$Y$11 -> 0 | Z9: ='Headcount'!$Z$11 -> 0 | AA9: ='Headcount'!$AA$11 -> 0 | AB9: ='Headcount'!$AB$11 -> 0 | AC9: ='Headcount'!$AC$11 -> 0 | AD9: ='Headcount'!$AD$11 -> 0 | AE9: ='Headcount'!$AE$11 -> 0 | AF9: ='Headcount'!$AF$11 -> 0 | AG9: ='Headcount'!$AG$11 -> 0 | AH9: ='Headcount'!$AH$11 -> 0 | AI9: ='Headcount'!$AI$11 -> 0 | AJ9: ='Headcount'!$AJ$11 -> 0 | AK9: ='Headcount'!$AK$11 -> 0 | AL9: ='Headcount'!$AL$11 -> 0 | AN9: =SUM(C9:E9) -> 0 | AO9: =SUM(F9:H9) -> 0 | AP9: =SUM(I9:K9) -> 0 | AQ9: =SUM(L9:N9) -> 0 | AR9: =SUM(O9:Q9) -> 0 | AS9: =SUM(R9:T9) -> 0 | AT9: =SUM(U9:W9) -> 0 | AU9: =SUM(X9:Z9) -> 0 | AV9: =SUM(AA9:AC9) -> 0 | AW9: =SUM(AD9:AF9) -> 0 | AX9: =SUM(AG9:AI9) -> 0 | AY9: =SUM(AJ9:AL9) -> 0 | BA9: =SUM(C9:N9) -> 0 | BB9: =SUM(O9:Z9) -> 0 | BC9: =SUM(AA9:AL9) -> 0
A10: Subcontractor costs | B10: Total revenue x subcontractor % | C10: ='Revenue'!C36*'Assumptions'!$F$30 -> 0 | D10: ='Revenue'!D36*'Assumptions'!$F$30 -> 0 | E10: ='Revenue'!E36*'Assumptions'!$F$30 -> 0 | F10: ='Revenue'!F36*'Assumptions'!$F$30 -> 0 | G10: ='Revenue'!G36*'Assumptions'!$F$30 -> 0 | H10: ='Revenue'!H36*'Assumptions'!$F$30 -> 0 | I10: ='Revenue'!I36*'Assumptions'!$F$30 -> 0 | J10: ='Revenue'!J36*'Assumptions'!$F$30 -> 0 | ... AL10: ='Revenue'!AL36*'Assumptions'!$F$30 -> 0 | AN10: =SUM(C10:E10) -> 0 | AO10: =SUM(F10:H10) -> 0 | AP10: =SUM(I10:K10) -> 0 | AQ10: =SUM(L10:N10) -> 0 | AR10: =SUM(O10:Q10) -> 0 | AS10: =SUM(R10:T10) -> 0 | AT10: =SUM(U10:W10) -> 0 | AU10: =SUM(X10:Z10) -> 0 | AV10: =SUM(AA10:AC10) -> 0 | AW10: =SUM(AD10:AF10) -> 0 | AX10: =SUM(AG10:AI10) -> 0 | AY10: =SUM(AJ10:AL10) -> 0 | BA10: =SUM(C10:N10) -> 0 | BB10: =SUM(O10:Z10) -> 0 | BC10: =SUM(AA10:AL10) -> 0
A11: AI tool / API delivery costs | B11: Delivery FTE x AI tooling / API spend per FTE | C11: ='Revenue'!C17*'Assumptions'!$F$31 -> 0 | D11: ='Revenue'!D17*'Assumptions'!$F$31 -> 0 | E11: ='Revenue'!E17*'Assumptions'!$F$31 -> 0 | F11: ='Revenue'!F17*'Assumptions'!$F$31 -> 0 | G11: ='Revenue'!G17*'Assumptions'!$F$31 -> 0 | H11: ='Revenue'!H17*'Assumptions'!$F$31 -> 0 | I11: ='Revenue'!I17*'Assumptions'!$F$31 -> 0 | J11: ='Revenue'!J17*'Assumptions'!$F$31 -> 0 | ... AL11: ='Revenue'!AL17*'Assumptions'!$F$31 -> 0 | AN11: =SUM(C11:E11) -> 0 | AO11: =SUM(F11:H11) -> 0 | AP11: =SUM(I11:K11) -> 0 | AQ11: =SUM(L11:N11) -> 0 | AR11: =SUM(O11:Q11) -> 0 | AS11: =SUM(R11:T11) -> 0 | AT11: =SUM(U11:W11) -> 0 | AU11: =SUM(X11:Z11) -> 0 | AV11: =SUM(AA11:AC11) -> 0 | AW11: =SUM(AD11:AF11) -> 0 | AX11: =SUM(AG11:AI11) -> 0 | AY11: =SUM(AJ11:AL11) -> 0 | BA11: =SUM(C11:N11) -> 0 | BB11: =SUM(O11:Z11) -> 0 | BC11: =SUM(AA11:AL11) -> 0
A12: Total COGS | C12: =C8+C9+C10+C11 -> 0 | D12: =D8+D9+D10+D11 -> 0 | E12: =E8+E9+E10+E11 -> 0 | F12: =F8+F9+F10+F11 -> 0 | G12: =G8+G9+G10+G11 -> 0 | H12: =H8+H9+H10+H11 -> 0 | I12: =I8+I9+I10+I11 -> 0 | J12: =J8+J9+J10+J11 -> 0 | ... AL12: =AL8+AL9+AL10+AL11 -> 0 | AN12: =SUM(C12:E12) -> 0 | AO12: =SUM(F12:H12) -> 0 | AP12: =SUM(I12:K12) -> 0 | AQ12: =SUM(L12:N12) -> 0 | AR12: =SUM(O12:Q12) -> 0 | AS12: =SUM(R12:T12) -> 0 | AT12: =SUM(U12:W12) -> 0 | AU12: =SUM(X12:Z12) -> 0 | AV12: =SUM(AA12:AC12) -> 0 | AW12: =SUM(AD12:AF12) -> 0 | AX12: =SUM(AG12:AI12) -> 0 | AY12: =SUM(AJ12:AL12) -> 0 | BA12: =SUM(C12:N12) -> 0 | BB12: =SUM(O12:Z12) -> 0 | BC12: =SUM(AA12:AL12) -> 0
A14: Gross Profit & Service Economics
A15: Gross Profit | C15: ='Revenue'!C36-C12 -> 0 | D15: ='Revenue'!D36-D12 -> 0 | E15: ='Revenue'!E36-E12 -> 0 | F15: ='Revenue'!F36-F12 -> 0 | G15: ='Revenue'!G36-G12 -> 0 | H15: ='Revenue'!H36-H12 -> 0 | I15: ='Revenue'!I36-I12 -> 0 | J15: ='Revenue'!J36-J12 -> 0 | ... AL15: ='Revenue'!AL36-AL12 -> 0 | AN15: =SUM(C15:E15) -> 0 | AO15: =SUM(F15:H15) -> 0 | AP15: =SUM(I15:K15) -> 0 | AQ15: =SUM(L15:N15) -> 0 | AR15: =SUM(O15:Q15) -> 0 | AS15: =SUM(R15:T15) -> 0 | AT15: =SUM(U15:W15) -> 0 | AU15: =SUM(X15:Z15) -> 0 | AV15: =SUM(AA15:AC15) -> 0 | AW15: =SUM(AD15:AF15) -> 0 | AX15: =SUM(AG15:AI15) -> 0 | AY15: =SUM(AJ15:AL15) -> 0 | BA15: =SUM(C15:N15) -> 0 | BB15: =SUM(O15:Z15) -> 0 | BC15: =SUM(AA15:AL15) -> 0
A16: Project Gross Margin % | C16: =IFERROR(C15/'Revenue'!C36,0) -> 0 | D16: =IFERROR(D15/'Revenue'!D36,0) -> 0 | E16: =IFERROR(E15/'Revenue'!E36,0) -> 0 | F16: =IFERROR(F15/'Revenue'!F36,0) -> 0 | G16: =IFERROR(G15/'Revenue'!G36,0) -> 0 | H16: =IFERROR(H15/'Revenue'!H36,0) -> 0 | I16: =IFERROR(I15/'Revenue'!I36,0) -> 0 | J16: =IFERROR(J15/'Revenue'!J36,0) -> 0 | ... AL16: =IFERROR(AL15/'Revenue'!AL36,0) -> 0 | AN16: =AVERAGE(C16:E16) -> 0 | AO16: =AVERAGE(F16:H16) -> 0 | AP16: =AVERAGE(I16:K16) -> 0 | AQ16: =AVERAGE(L16:N16) -> 0 | AR16: =AVERAGE(O16:Q16) -> 0 | AS16: =AVERAGE(R16:T16) -> 0 | AT16: =AVERAGE(U16:W16) -> 0 | AU16: =AVERAGE(X16:Z16) -> 0 | AV16: =AVERAGE(AA16:AC16) -> 0 | AW16: =AVERAGE(AD16:AF16) -> 0 | AX16: =AVERAGE(AG16:AI16) -> 0 | AY16: =AVERAGE(AJ16:AL16) -> 0 | BA16: =AVERAGE(C16:N16) -> 0 | BB16: =AVERAGE(O16:Z16) -> 0 | BC16: =AVERAGE(AA16:AL16) -> 0
A17: Utilization % | B17: Linked from Revenue tab | C17: ='Revenue'!$C$40 -> 0 | D17: ='Revenue'!$D$40 -> 0 | E17: ='Revenue'!$E$40 -> 0 | F17: ='Revenue'!$F$40 -> 0 | G17: ='Revenue'!$G$40 -> 0 | H17: ='Revenue'!$H$40 -> 0 | I17: ='Revenue'!$I$40 -> 0 | J17: ='Revenue'!$J$40 -> 0 | K17: ='Revenue'!$K$40 -> 0 | L17: ='Revenue'!$L$40 -> 0 | M17: ='Revenue'!$M$40 -> 0 | N17: ='Revenue'!$N$40 -> 0 | O17: ='Revenue'!$O$40 -> 0 | P17: ='Revenue'!$P$40 -> 0 | Q17: ='Revenue'!$Q$40 -> 0 | R17: ='Revenue'!$R$40 -> 0 | S17: ='Revenue'!$S$40 -> 0 | T17: ='Revenue'!$T$40 -> 0 | U17: ='Revenue'!$U$40 -> 0 | V17: ='Revenue'!$V$40 -> 0 | W17: ='Revenue'!$W$40 -> 0 | X17: ='Revenue'!$X$40 -> 0 | Y17: ='Revenue'!$Y$40 -> 0 | Z17: ='Revenue'!$Z$40 -> 0 | AA17: ='Revenue'!$AA$40 -> 0 | AB17: ='Revenue'!$AB$40 -> 0 | AC17: ='Revenue'!$AC$40 -> 0 | AD17: ='Revenue'!$AD$40 -> 0 | AE17: ='Revenue'!$AE$40 -> 0 | AF17: ='Revenue'!$AF$40 -> 0 | AG17: ='Revenue'!$AG$40 -> 0 | AH17: ='Revenue'!$AH$40 -> 0 | AI17: ='Revenue'!$AI$40 -> 0 | AJ17: ='Revenue'!$AJ$40 -> 0 | AK17: ='Revenue'!$AK$40 -> 0 | AL17: ='Revenue'!$AL$40 -> 0 | AN17: =AVERAGE(C17:E17) -> 0 | AO17: =AVERAGE(F17:H17) -> 0 | AP17: =AVERAGE(I17:K17) -> 0 | AQ17: =AVERAGE(L17:N17) -> 0 | AR17: =AVERAGE(O17:Q17) -> 0 | AS17: =AVERAGE(R17:T17) -> 0 | AT17: =AVERAGE(U17:W17) -> 0 | AU17: =AVERAGE(X17:Z17) -> 0 | AV17: =AVERAGE(AA17:AC17) -> 0 | AW17: =AVERAGE(AD17:AF17) -> 0 | AX17: =AVERAGE(AG17:AI17) -> 0 | AY17: =AVERAGE(AJ17:AL17) -> 0 | BA17: =AVERAGE(C17:N17) -> 0 | BB17: =AVERAGE(O17:Z17) -> 0 | BC17: =AVERAGE(AA17:AL17) -> 0
