Workbook

Sheet Read Me
A1: B2B SaaS + Usage — 3-Year Financial Model
A2: 36-month integrated financial model — Read Me
A4: Overview
A5: A 36-month, formula-driven financial model for an early-stage B2B SaaS company with a usage/overage component. Start on the Assumptions tab: set your Base/Upside/Downside inputs and pick a scenario. Every other tab recalculates automatically.
A7: How this workbook is organized
A8: Assumptions -> Headcount -> Revenue -> COGS & GM -> Opex -> Working Capital -> P&L -> Balance Sheet -> Cash Flow -> Cash & Runway -> Scenarios -> Visuals -> Checks. Data flows strictly left-to-right through that order: change an assumption, and every downstream tab recalculates automatically (workbook calculation mode is Automatic).
A10: Formatting legend
A11: Blue text on light-blue fill = an input you can edit (Assumptions tab, and scenario selector).
A12: Black text on white = a live formula. Do not hard-code over these cells.
A13: Cells on a light-gray band = a value linked in from another tab.
A15: Color palette
A16: Purple (#7B68EE)
... A35: 36 monthly periods, plus quarterly (12) and annual (3) roll-up columns on each schedule tab. Workbook calculation is set to Automatic — Excel recalculates on every edit. Deterministic, seeded default assumptions are provided so the model is internally consistent out of the box; replace them with your own numbers on the Assumptions tab.

Sheet Assumptions
A1: B2B SaaS + Usage — 3-Year Financial Model — Assumptions
A2: Plain-language inputs. Edit the Base / Upside / Downside columns only — everything else in this workbook is a formula.
A4: Scenario selector: | C4: Base | D4: << Pick Base / Upside / Downside. This one cell drives every formula in the model.
A6: Assumption | B6: Unit | C6: Base | D6: Upside | E6: Downside | F6: Active (used in model) | G6: Notes / definition
A7: Company & Financial
A8: Starting cash balance | B8: $ | C8: 1500000 | D8: 1500000 | E8: 1500000 | F8: =CHOOSE(MATCH('Assumptions'!$C$4,{"Base","Upside","Downside"},0),C8,D8,E8) -> 0 | G8: Cash in the bank on day 1 of the model.
A9: Starting paid-in capital | B9: $ | C9: 1800000 | D9: 1800000 | E9: 1800000 | F9: =CHOOSE(MATCH('Assumptions'!$C$4,{"Base","Upside","Downside"},0),C9,D9,E9) -> 0 | G9: Cumulative equity raised before month 1 (seed round).
A10: Income tax rate | B10: % | C10: 0 | D10: 0 | E10: 0 | F10: =CHOOSE(MATCH('Assumptions'!$C$4,{"Base","Upside","Downside"},0),C10,D10,E10) -> 0 | G10: Applied to positive Earnings Before Tax only; no NOL carryforward modeled.
A12: Customers & Growth
A13: Starting paying customers | B13: # | C13: 40 | D13: 40 | E13: 40 | F13: =CHOOSE(MATCH('Assumptions'!$C$4,{"Base","Upside","Downside"},0),C13,D13,E13) -> 0 | G13: Logos under contract at the start of month 1.
A14: New logos added, month 1 | B14: # | C14: 6 | D14: 8 | E14: 4 | F14: =CHOOSE(MATCH('Assumptions'!$C$4,{"Base","Upside","Downside"},0),C14,D14,E14) -> 0 | G14: New paying customers signed in month 1; grows monthly below.
A15: New-logo growth, month over month | B15: % | C15: 0.0322 | D15: 0.0464 | E15: 0.0039 | F15: =CHOOSE(MATCH('Assumptions'!$C$4,{"Base","Upside","Downside"},0),C15,D15,E15) -> 0 | G15: Compounding growth in the number of new logos signed each month.
A16: Gross logo/dollar churn rate | B16: % | C16: 0.015 | D16: 0.01 | E16: 0.025 | F16: =CHOOSE(MATCH('Assumptions'!$C$4,{"Base","Upside","Downside"},0),C16,D16,E16) -> 0 | G16: Share of beginning customers (and beginning MRR) lost each month.
A17: Expansion (upsell) rate | B17: % | C17: 0.01 | D17: 0.016 | E17: 0.006 | F17: =CHOOSE(MATCH('Assumptions'!$C$4,{"Base","Upside","Downside"},0),C17,D17,E17) -> 0 | G17: Upsell/seat-expansion MRR as % of beginning MRR each month.
A18: Contraction (downgrade) rate | B18: % | C18: 0.004 | D18: 0.002 | E18: 0.008 | F18: =CHOOSE(MATCH('Assumptions'!$C$4,{"Base","Upside","Downside"},0),C18,D18,E18) -> 0 | G18: Downgrade MRR as % of beginning MRR each month.
A20: Pricing & Usage
A21: Starting ARPA (avg MRR per account) | B21: $/mo | C21: 1200 | D21: 1300 | E21: 1100 | F21: =CHOOSE(MATCH('Assumptions'!$C$4,{"Base","Upside","Downside"},0),C21,D21,E21) -> 0 | G21: Average recurring revenue per account at month 1.
A22: ARPA growth, month over month | B22: % | C22: 0.005 | D22: 0.009 | E22: 0.001 | F22: =CHOOSE(MATCH('Assumptions'!$C$4,{"Base","Upside","Downside"},0),C22,D22,E22) -> 0 | G22: Price/packaging/mix improvement applied to ARPA each month.
A23: Usage/overage revenue per customer | B23: $/mo | C23: 150 | D23: 190 | E23: 100 | F23: =CHOOSE(MATCH('Assumptions'!$C$4,{"Base","Upside","Downside"},0),C23,D23,E23) -> 0 | G23: Average metered usage revenue billed on top of subscription, per active account.
A24: Usage revenue growth, month over month | B24: % | C24: 0.01 | D24: 0.018 | E24: 0.003 | F24: =CHOOSE(MATCH('Assumptions'!$C$4,{"Base","Upside","Downside"},0),C24,D24,E24) -> 0 | G24: Growth in metered usage intensity per account each month.
A26: COGS & Gross Margin
A27: Hosting & infrastructure, % of revenue | B27: % | C27: 0.08 | D27: 0.065 | E27: 0.1 | F27: =CHOOSE(MATCH('Assumptions'!$C$4,{"Base","Upside","Downside"},0),C27,D27,E27) -> 0 | G27: Cloud hosting cost to serve, as a % of total revenue.
A28: Third-party data/API costs, % of revenue | B28: % | C28: 0.03 | D28: 0.025 | E28: 0.04 | F28: =CHOOSE(MATCH('Assumptions'!$C$4,{"Base","Upside","Downside"},0),C28,D28,E28) -> 0 | G28: Licensed data feeds / third-party APIs embedded in the product.
A29: Payment processing fees, % of revenue | B29: % | C29: 0.015 | D29: 0.013 | E29: 0.018 | F29: =CHOOSE(MATCH('Assumptions'!$C$4,{"Base","Upside","Downside"},0),C29,D29,E29) -> 0 | G29: Card/ACH processing fees on billed revenue.
A31: Headcount — Customer Success (COGS)
A32: Starting CS/Support FTEs | B32: # | C32: 2 | D32: 2 | E32: 2 | F32: =CHOOSE(MATCH('Assumptions'!$C$4,{"Base","Upside","Downside"},0),C32,D32,E32) -> 0 | G32: Customer Success & Support team.
A33: CS/Support net adds per quarter | B33: # | C33: 1 | D33: 1.5 | E33: 0.5 | F33: =CHOOSE(MATCH('Assumptions'!$C$4,{"Base","Upside","Downside"},0),C33,D33,E33) -> 0
A34: CS/Support fully-loaded cost per FTE | B34: $/mo | C34: 9000 | D34: 9000 | E34: 9000 | F34: =CHOOSE(MATCH('Assumptions'!$C$4,{"Base","Upside","Downside"},0),C34,D34,E34) -> 0 | G34: Salary + benefits + payroll tax, monthly.
A36: Headcount — Sales & Marketing (Opex)
A37: Starting Account Executive FTEs | B37: # | C37: 3 | D37: 3 | E37: 3 | F37: =CHOOSE(MATCH('Assumptions'!$C$4,{"Base","Upside","Downside"},0),C37,D37,E37) -> 0
A38: AE net adds per quarter | B38: # | C38: 1 | D38: 2 | E38: 0.5 | F38: =CHOOSE(MATCH('Assumptions'!$C$4,{"Base","Upside","Downside"},0),C38,D38,E38) -> 0
A39: AE fully-loaded cost per FTE | B39: $/mo | C39: 14000 | D39: 14000 | E39: 14000 | F39: =CHOOSE(MATCH('Assumptions'!$C$4,{"Base","Upside","Downside"},0),C39,D39,E39) -> 0
A40: Starting SDR/BDR FTEs | B40: # | C40: 2 | D40: 2 | E40: 2 | F40: =CHOOSE(MATCH('Assumptions'!$C$4,{"Base","Upside","Downside"},0),C40,D40,E40) -> 0 | G40: Pipeline-generation reps.
A41: SDR/BDR net adds per quarter | B41: # | C41: 1 | D41: 1.5 | E41: 0.5 | F41: =CHOOSE(MATCH('Assumptions'!$C$4,{"Base","Upside","Downside"},0),C41,D41,E41) -> 0
A42: SDR/BDR fully-loaded cost per FTE | B42: $/mo | C42: 8000 | D42: 8000 | E42: 8000 | F42: =CHOOSE(MATCH('Assumptions'!$C$4,{"Base","Upside","Downside"},0),C42,D42,E42) -> 0
A44: Headcount — R&D / Engineering (Opex)
A45: Starting Engineering/Product FTEs | B45: # | C45: 6 | D45: 6 | E45: 6 | F45: =CHOOSE(MATCH('Assumptions'!$C$4,{"Base","Upside","Downside"},0),C45,D45,E45) -> 0
A46: Engineering net adds per quarter | B46: # | C46: 2 | D46: 3 | E46: 1 | F46: =CHOOSE(MATCH('Assumptions'!$C$4,{"Base","Upside","Downside"},0),C46,D46,E46) -> 0
A47: Engineering fully-loaded cost per FTE | B47: $/mo | C47: 15000 | D47: 15000 | E47: 15000 | F47: =CHOOSE(MATCH('Assumptions'!$C$4,{"Base","Upside","Downside"},0),C47,D47,E47) -> 0
A49: Headcount — G&A (Opex)
...

Sheet Headcount
A1: B2B SaaS + Usage — 3-Year Financial Model — Headcount
A2: Fully-loaded FTE ramps by role — flows into COGS or Opex by classification.
A5: Line item | B5: Units / source | C5: Monthly (36 months) | AN5: Quarterly | BA5: Annual
C6: 46023 | D6: 46054 | E6: 46082 | F6: 46113 | G6: 46143 | H6: 46174 | I6: 46204 | J6: 46235 | K6: 46266 | L6: 46296 | M6: 46327 | N6: 46357 | O6: 46388 | P6: 46419 | Q6: 46447 | R6: 46478 | S6: 46508 | T6: 46539 | U6: 46569 | V6: 46600 | W6: 46631 | X6: 46661 | Y6: 46692 | Z6: 46722 | AA6: 46753 | AB6: 46784 | AC6: 46813 | AD6: 46844 | AE6: 46874 | AF6: 46905 | AG6: 46935 | AH6: 46966 | AI6: 46997 | AJ6: 47027 | AK6: 47058 | AL6: 47088 | AN6: Q1 | AO6: Q2 | AP6: Q3 | AQ6: Q4 | AR6: Q5 | AS6: Q6 | AT6: Q7 | AU6: Q8 | AV6: Q9 | AW6: Q10 | AX6: Q11 | AY6: Q12 | BA6: FY1 | BB6: FY2 | BC6: FY3
A7: Cost of Goods Sold headcount (COGS-classified)
A8: Customer Success / Support — headcount (FTE) | B8: Customer Success · start + net adds/qtr ÷ 3 | C8: =ROUND('Assumptions'!$F$32,1) -> 0 | D8: =ROUND(C8+'Assumptions'!$F$33/3,1) -> 0 | E8: =ROUND(D8+'Assumptions'!$F$33/3,1) -> 0 | F8: =ROUND(E8+'Assumptions'!$F$33/3,1) -> 0 | G8: =ROUND(F8+'Assumptions'!$F$33/3,1) -> 0 | H8: =ROUND(G8+'Assumptions'!$F$33/3,1) -> 0 | I8: =ROUND(H8+'Assumptions'!$F$33/3,1) -> 0 | J8: =ROUND(I8+'Assumptions'!$F$33/3,1) -> 0 | K8: =ROUND(J8+'Assumptions'!$F$33/3,1) -> 0 | ... AL8: =ROUND(AK8+'Assumptions'!$F$33/3,1) -> 0 | AN8: =E8 -> 0 | AO8: =H8 -> 0 | AP8: =K8 -> 0 | AQ8: =N8 -> 0 | AR8: =Q8 -> 0 | AS8: =T8 -> 0 | AT8: =W8 -> 0 | AU8: =Z8 -> 0 | AV8: =AC8 -> 0 | AW8: =AF8 -> 0 | AX8: =AI8 -> 0 | AY8: =AL8 -> 0 | BA8: =N8 -> 0 | BB8: =Z8 -> 0 | BC8: =AL8 -> 0
A9: Customer Success / Support — fully-loaded cost | B9: Headcount × monthly fully-loaded cost/FTE | C9: =C8*'Assumptions'!$F$34 -> 0 | D9: =D8*'Assumptions'!$F$34 -> 0 | E9: =E8*'Assumptions'!$F$34 -> 0 | F9: =F8*'Assumptions'!$F$34 -> 0 | G9: =G8*'Assumptions'!$F$34 -> 0 | H9: =H8*'Assumptions'!$F$34 -> 0 | I9: =I8*'Assumptions'!$F$34 -> 0 | J9: =J8*'Assumptions'!$F$34 -> 0 | ... AL9: =AL8*'Assumptions'!$F$34 -> 0 | AN9: =SUM(C9:E9) -> 0 | AO9: =SUM(F9:H9) -> 0 | AP9: =SUM(I9:K9) -> 0 | AQ9: =SUM(L9:N9) -> 0 | AR9: =SUM(O9:Q9) -> 0 | AS9: =SUM(R9:T9) -> 0 | AT9: =SUM(U9:W9) -> 0 | AU9: =SUM(X9:Z9) -> 0 | AV9: =SUM(AA9:AC9) -> 0 | AW9: =SUM(AD9:AF9) -> 0 | AX9: =SUM(AG9:AI9) -> 0 | AY9: =SUM(AJ9:AL9) -> 0 | BA9: =SUM(C9:N9) -> 0 | BB9: =SUM(O9:Z9) -> 0 | BC9: =SUM(AA9:AL9) -> 0
A11: Operating expense headcount (Opex-classified)
A12: Account Executives (Sales) — headcount (FTE) | B12: Sales & Marketing · start + net adds/qtr ÷ 3 | C12: =ROUND('Assumptions'!$F$37,1) -> 0 | D12: =ROUND(C12+'Assumptions'!$F$38/3,1) -> 0 | E12: =ROUND(D12+'Assumptions'!$F$38/3,1) -> 0 | F12: =ROUND(E12+'Assumptions'!$F$38/3,1) -> 0 | G12: =ROUND(F12+'Assumptions'!$F$38/3,1) -> 0 | H12: =ROUND(G12+'Assumptions'!$F$38/3,1) -> 0 | I12: =ROUND(H12+'Assumptions'!$F$38/3,1) -> 0 | J12: =ROUND(I12+'Assumptions'!$F$38/3,1) -> 0 | K12: =ROUND(J12+'Assumptions'!$F$38/3,1) -> 0 | ... AL12: =ROUND(AK12+'Assumptions'!$F$38/3,1) -> 0 | AN12: =E12 -> 0 | AO12: =H12 -> 0 | AP12: =K12 -> 0 | AQ12: =N12 -> 0 | AR12: =Q12 -> 0 | AS12: =T12 -> 0 | AT12: =W12 -> 0 | AU12: =Z12 -> 0 | AV12: =AC12 -> 0 | AW12: =AF12 -> 0 | AX12: =AI12 -> 0 | AY12: =AL12 -> 0 | BA12: =N12 -> 0 | BB12: =Z12 -> 0 | BC12: =AL12 -> 0
A13: Account Executives (Sales) — fully-loaded cost | B13: Headcount × monthly fully-loaded cost/FTE | C13: =C12*'Assumptions'!$F$39 -> 0 | D13: =D12*'Assumptions'!$F$39 -> 0 | E13: =E12*'Assumptions'!$F$39 -> 0 | F13: =F12*'Assumptions'!$F$39 -> 0 | G13: =G12*'Assumptions'!$F$39 -> 0 | H13: =H12*'Assumptions'!$F$39 -> 0 | I13: =I12*'Assumptions'!$F$39 -> 0 | J13: =J12*'Assumptions'!$F$39 -> 0 | ... AL13: =AL12*'Assumptions'!$F$39 -> 0 | AN13: =SUM(C13:E13) -> 0 | AO13: =SUM(F13:H13) -> 0 | AP13: =SUM(I13:K13) -> 0 | AQ13: =SUM(L13:N13) -> 0 | AR13: =SUM(O13:Q13) -> 0 | AS13: =SUM(R13:T13) -> 0 | AT13: =SUM(U13:W13) -> 0 | AU13: =SUM(X13:Z13) -> 0 | AV13: =SUM(AA13:AC13) -> 0 | AW13: =SUM(AD13:AF13) -> 0 | AX13: =SUM(AG13:AI13) -> 0 | AY13: =SUM(AJ13:AL13) -> 0 | BA13: =SUM(C13:N13) -> 0 | BB13: =SUM(O13:Z13) -> 0 | BC13: =SUM(AA13:AL13) -> 0
A14: SDR / BDR (Pipeline) — headcount (FTE) | B14: Sales & Marketing · start + net adds/qtr ÷ 3 | C14: =ROUND('Assumptions'!$F$40,1) -> 0 | D14: =ROUND(C14+'Assumptions'!$F$41/3,1) -> 0 | E14: =ROUND(D14+'Assumptions'!$F$41/3,1) -> 0 | F14: =ROUND(E14+'Assumptions'!$F$41/3,1) -> 0 | G14: =ROUND(F14+'Assumptions'!$F$41/3,1) -> 0 | H14: =ROUND(G14+'Assumptions'!$F$41/3,1) -> 0 | I14: =ROUND(H14+'Assumptions'!$F$41/3,1) -> 0 | J14: =ROUND(I14+'Assumptions'!$F$41/3,1) -> 0 | K14: =ROUND(J14+'Assumptions'!$F$41/3,1) -> 0 | ... AL14: =ROUND(AK14+'Assumptions'!$F$41/3,1) -> 0 | AN14: =E14 -> 0 | AO14: =H14 -> 0 | AP14: =K14 -> 0 | AQ14: =N14 -> 0 | AR14: =Q14 -> 0 | AS14: =T14 -> 0 | AT14: =W14 -> 0 | AU14: =Z14 -> 0 | AV14: =AC14 -> 0 | AW14: =AF14 -> 0 | AX14: =AI14 -> 0 | AY14: =AL14 -> 0 | BA14: =N14 -> 0 | BB14: =Z14 -> 0 | BC14: =AL14 -> 0
A15: SDR / BDR (Pipeline) — fully-loaded cost | B15: Headcount × monthly fully-loaded cost/FTE | C15: =C14*'Assumptions'!$F$42 -> 0 | D15: =D14*'Assumptions'!$F$42 -> 0 | E15: =E14*'Assumptions'!$F$42 -> 0 | F15: =F14*'Assumptions'!$F$42 -> 0 | G15: =G14*'Assumptions'!$F$42 -> 0 | H15: =H14*'Assumptions'!$F$42 -> 0 | I15: =I14*'Assumptions'!$F$42 -> 0 | J15: =J14*'Assumptions'!$F$42 -> 0 | ... AL15: =AL14*'Assumptions'!$F$42 -> 0 | AN15: =SUM(C15:E15) -> 0 | AO15: =SUM(F15:H15) -> 0 | AP15: =SUM(I15:K15) -> 0 | AQ15: =SUM(L15:N15) -> 0 | AR15: =SUM(O15:Q15) -> 0 | AS15: =SUM(R15:T15) -> 0 | AT15: =SUM(U15:W15) -> 0 | AU15: =SUM(X15:Z15) -> 0 | AV15: =SUM(AA15:AC15) -> 0 | AW15: =SUM(AD15:AF15) -> 0 | AX15: =SUM(AG15:AI15) -> 0 | AY15: =SUM(AJ15:AL15) -> 0 | BA15: =SUM(C15:N15) -> 0 | BB15: =SUM(O15:Z15) -> 0 | BC15: =SUM(AA15:AL15) -> 0
A16: Engineering / Product — headcount (FTE) | B16: R&D / Engineering · start + net adds/qtr ÷ 3 | C16: =ROUND('Assumptions'!$F$45,1) -> 0 | D16: =ROUND(C16+'Assumptions'!$F$46/3,1) -> 0 | E16: =ROUND(D16+'Assumptions'!$F$46/3,1) -> 0 | F16: =ROUND(E16+'Assumptions'!$F$46/3,1) -> 0 | G16: =ROUND(F16+'Assumptions'!$F$46/3,1) -> 0 | H16: =ROUND(G16+'Assumptions'!$F$46/3,1) -> 0 | I16: =ROUND(H16+'Assumptions'!$F$46/3,1) -> 0 | J16: =ROUND(I16+'Assumptions'!$F$46/3,1) -> 0 | K16: =ROUND(J16+'Assumptions'!$F$46/3,1) -> 0 | ... AL16: =ROUND(AK16+'Assumptions'!$F$46/3,1) -> 0 | AN16: =E16 -> 0 | AO16: =H16 -> 0 | AP16: =K16 -> 0 | AQ16: =N16 -> 0 | AR16: =Q16 -> 0 | AS16: =T16 -> 0 | AT16: =W16 -> 0 | AU16: =Z16 -> 0 | AV16: =AC16 -> 0 | AW16: =AF16 -> 0 | AX16: =AI16 -> 0 | AY16: =AL16 -> 0 | BA16: =N16 -> 0 | BB16: =Z16 -> 0 | BC16: =AL16 -> 0
A17: Engineering / Product — fully-loaded cost | B17: Headcount × monthly fully-loaded cost/FTE | C17: =C16*'Assumptions'!$F$47 -> 0 | D17: =D16*'Assumptions'!$F$47 -> 0 | E17: =E16*'Assumptions'!$F$47 -> 0 | F17: =F16*'Assumptions'!$F$47 -> 0 | G17: =G16*'Assumptions'!$F$47 -> 0 | H17: =H16*'Assumptions'!$F$47 -> 0 | I17: =I16*'Assumptions'!$F$47 -> 0 | J17: =J16*'Assumptions'!$F$47 -> 0 | ... AL17: =AL16*'Assumptions'!$F$47 -> 0 | AN17: =SUM(C17:E17) -> 0 | AO17: =SUM(F17:H17) -> 0 | AP17: =SUM(I17:K17) -> 0 | AQ17: =SUM(L17:N17) -> 0 | AR17: =SUM(O17:Q17) -> 0 | AS17: =SUM(R17:T17) -> 0 | AT17: =SUM(U17:W17) -> 0 | AU17: =SUM(X17:Z17) -> 0 | AV17: =SUM(AA17:AC17) -> 0 | AW17: =SUM(AD17:AF17) -> 0 | AX17: =SUM(AG17:AI17) -> 0 | AY17: =SUM(AJ17:AL17) -> 0 | BA17: =SUM(C17:N17) -> 0 | BB17: =SUM(O17:Z17) -> 0 | BC17: =SUM(AA17:AL17) -> 0
A18: G&A (Finance/HR/Ops) — headcount (FTE) | B18: General & Administrative · start + net adds/qtr ÷ 3 | C18: =ROUND('Assumptions'!$F$50,1) -> 0 | D18: =ROUND(C18+'Assumptions'!$F$51/3,1) -> 0 | E18: =ROUND(D18+'Assumptions'!$F$51/3,1) -> 0 | F18: =ROUND(E18+'Assumptions'!$F$51/3,1) -> 0 | G18: =ROUND(F18+'Assumptions'!$F$51/3,1) -> 0 | H18: =ROUND(G18+'Assumptions'!$F$51/3,1) -> 0 | I18: =ROUND(H18+'Assumptions'!$F$51/3,1) -> 0 | J18: =ROUND(I18+'Assumptions'!$F$51/3,1) -> 0 | K18: =ROUND(J18+'Assumptions'!$F$51/3,1) -> 0 | ... AL18: =ROUND(AK18+'Assumptions'!$F$51/3,1) -> 0 | AN18: =E18 -> 0 | AO18: =H18 -> 0 | AP18: =K18 -> 0 | AQ18: =N18 -> 0 | AR18: =Q18 -> 0 | AS18: =T18 -> 0 | AT18: =W18 -> 0 | AU18: =Z18 -> 0 | AV18: =AC18 -> 0 | AW18: =AF18 -> 0 | AX18: =AI18 -> 0 | AY18: =AL18 -> 0 | BA18: =N18 -> 0 | BB18: =Z18 -> 0 | BC18: =AL18 -> 0
A19: G&A (Finance/HR/Ops) — fully-loaded cost | B19: Headcount × monthly fully-loaded cost/FTE | C19: =C18*'Assumptions'!$F$52 -> 0 | D19: =D18*'Assumptions'!$F$52 -> 0 | E19: =E18*'Assumptions'!$F$52 -> 0 | F19: =F18*'Assumptions'!$F$52 -> 0 | G19: =G18*'Assumptions'!$F$52 -> 0 | H19: =H18*'Assumptions'!$F$52 -> 0 | I19: =I18*'Assumptions'!$F$52 -> 0 | J19: =J18*'Assumptions'!$F$52 -> 0 | ... AL19: =AL18*'Assumptions'!$F$52 -> 0 | AN19: =SUM(C19:E19) -> 0 | AO19: =SUM(F19:H19) -> 0 | AP19: =SUM(I19:K19) -> 0 | AQ19: =SUM(L19:N19) -> 0 | AR19: =SUM(O19:Q19) -> 0 | AS19: =SUM(R19:T19) -> 0 | AT19: =SUM(U19:W19) -> 0 | AU19: =SUM(X19:Z19) -> 0 | AV19: =SUM(AA19:AC19) -> 0 | AW19: =SUM(AD19:AF19) -> 0 | AX19: =SUM(AG19:AI19) -> 0 | AY19: =SUM(AJ19:AL19) -> 0 | BA19: =SUM(C19:N19) -> 0 | BB19: =SUM(O19:Z19) -> 0 | BC19: =SUM(AA19:AL19) -> 0
A21: Totals
A22: Total headcount (FTE) | B22: Sum of all roles | C22: =C8+C12+C14+C16+C18 -> 0 | D22: =D8+D12+D14+D16+D18 -> 0 | E22: =E8+E12+E14+E16+E18 -> 0 | F22: =F8+F12+F14+F16+F18 -> 0 | G22: =G8+G12+G14+G16+G18 -> 0 | H22: =H8+H12+H14+H16+H18 -> 0 | I22: =I8+I12+I14+I16+I18 -> 0 | J22: =J8+J12+J14+J16+J18 -> 0 | ... AL22: =AL8+AL12+AL14+AL16+AL18 -> 0 | AN22: =E22 -> 0 | AO22: =H22 -> 0 | AP22: =K22 -> 0 | AQ22: =N22 -> 0 | AR22: =Q22 -> 0 | AS22: =T22 -> 0 | AT22: =W22 -> 0 | AU22: =Z22 -> 0 | AV22: =AC22 -> 0 | AW22: =AF22 -> 0 | AX22: =AI22 -> 0 | AY22: =AL22 -> 0 | BA22: =N22 -> 0 | BB22: =Z22 -> 0 | BC22: =AL22 -> 0
A23: Total COGS-classified people cost | B23: Feeds COGS & GM tab | C23: =C9 -> 0 | D23: =D9 -> 0 | E23: =E9 -> 0 | F23: =F9 -> 0 | G23: =G9 -> 0 | H23: =H9 -> 0 | I23: =I9 -> 0 | J23: =J9 -> 0 | ... AL23: =AL9 -> 0 | AN23: =SUM(C23:E23) -> 0 | AO23: =SUM(F23:H23) -> 0 | AP23: =SUM(I23:K23) -> 0 | AQ23: =SUM(L23:N23) -> 0 | AR23: =SUM(O23:Q23) -> 0 | AS23: =SUM(R23:T23) -> 0 | AT23: =SUM(U23:W23) -> 0 | AU23: =SUM(X23:Z23) -> 0 | AV23: =SUM(AA23:AC23) -> 0 | AW23: =SUM(AD23:AF23) -> 0 | AX23: =SUM(AG23:AI23) -> 0 | AY23: =SUM(AJ23:AL23) -> 0 | BA23: =SUM(C23:N23) -> 0 | BB23: =SUM(O23:Z23) -> 0 | BC23: =SUM(AA23:AL23) -> 0
A24: Total Opex-classified people cost | B24: Feeds Opex tab | C24: =C13+C15+C17+C19 -> 0 | D24: =D13+D15+D17+D19 -> 0 | E24: =E13+E15+E17+E19 -> 0 | F24: =F13+F15+F17+F19 -> 0 | G24: =G13+G15+G17+G19 -> 0 | H24: =H13+H15+H17+H19 -> 0 | I24: =I13+I15+I17+I19 -> 0 | J24: =J13+J15+J17+J19 -> 0 | ... AL24: =AL13+AL15+AL17+AL19 -> 0 | AN24: =SUM(C24:E24) -> 0 | AO24: =SUM(F24:H24) -> 0 | AP24: =SUM(I24:K24) -> 0 | AQ24: =SUM(L24:N24) -> 0 | AR24: =SUM(O24:Q24) -> 0 | AS24: =SUM(R24:T24) -> 0 | AT24: =SUM(U24:W24) -> 0 | AU24: =SUM(X24:Z24) -> 0 | AV24: =SUM(AA24:AC24) -> 0 | AW24: =SUM(AD24:AF24) -> 0 | AX24: =SUM(AG24:AI24) -> 0 | AY24: =SUM(AJ24:AL24) -> 0 | BA24: =SUM(C24:N24) -> 0 | BB24: =SUM(O24:Z24) -> 0 | BC24: =SUM(AA24:AL24) -> 0
A25: General & Administrative people cost | C25: =C19 -> 0 | D25: =D19 -> 0 | E25: =E19 -> 0 | F25: =F19 -> 0 | G25: =G19 -> 0 | H25: =H19 -> 0 | I25: =I19 -> 0 | J25: =J19 -> 0 | ... AL25: =AL19 -> 0 | AN25: =SUM(C25:E25) -> 0 | AO25: =SUM(F25:H25) -> 0 | AP25: =SUM(I25:K25) -> 0 | AQ25: =SUM(L25:N25) -> 0 | AR25: =SUM(O25:Q25) -> 0 | AS25: =SUM(R25:T25) -> 0 | AT25: =SUM(U25:W25) -> 0 | AU25: =SUM(X25:Z25) -> 0 | AV25: =SUM(AA25:AC25) -> 0 | AW25: =SUM(AD25:AF25) -> 0 | AX25: =SUM(AG25:AI25) -> 0 | AY25: =SUM(AJ25:AL25) -> 0 | BA25: =SUM(C25:N25) -> 0 | BB25: =SUM(O25:Z25) -> 0 | BC25: =SUM(AA25:AL25) -> 0
A26: R&D / Engineering people cost | C26: =C17 -> 0 | D26: =D17 -> 0 | E26: =E17 -> 0 | F26: =F17 -> 0 | G26: =G17 -> 0 | H26: =H17 -> 0 | I26: =I17 -> 0 | J26: =J17 -> 0 | ... AL26: =AL17 -> 0 | AN26: =SUM(C26:E26) -> 0 | AO26: =SUM(F26:H26) -> 0 | AP26: =SUM(I26:K26) -> 0 | AQ26: =SUM(L26:N26) -> 0 | AR26: =SUM(O26:Q26) -> 0 | AS26: =SUM(R26:T26) -> 0 | AT26: =SUM(U26:W26) -> 0 | AU26: =SUM(X26:Z26) -> 0 | AV26: =SUM(AA26:AC26) -> 0 | AW26: =SUM(AD26:AF26) -> 0 | AX26: =SUM(AG26:AI26) -> 0 | AY26: =SUM(AJ26:AL26) -> 0 | BA26: =SUM(C26:N26) -> 0 | BB26: =SUM(O26:Z26) -> 0 | BC26: =SUM(AA26:AL26) -> 0
A27: Sales & Marketing people cost | C27: =C13+C15 -> 0 | D27: =D13+D15 -> 0 | E27: =E13+E15 -> 0 | F27: =F13+F15 -> 0 | G27: =G13+G15 -> 0 | H27: =H13+H15 -> 0 | I27: =I13+I15 -> 0 | J27: =J13+J15 -> 0 | ... AL27: =AL13+AL15 -> 0 | AN27: =SUM(C27:E27) -> 0 | AO27: =SUM(F27:H27) -> 0 | AP27: =SUM(I27:K27) -> 0 | AQ27: =SUM(L27:N27) -> 0 | AR27: =SUM(O27:Q27) -> 0 | AS27: =SUM(R27:T27) -> 0 | AT27: =SUM(U27:W27) -> 0 | AU27: =SUM(X27:Z27) -> 0 | AV27: =SUM(AA27:AC27) -> 0 | AW27: =SUM(AD27:AF27) -> 0 | AX27: =SUM(AG27:AI27) -> 0 | AY27: =SUM(AJ27:AL27) -> 0 | BA27: =SUM(C27:N27) -> 0 | BB27: =SUM(O27:Z27) -> 0 | BC27: =SUM(AA27:AL27) -> 0

Sheet Revenue
A1: B2B SaaS + Usage — 3-Year Financial Model — Revenue
A2: Customer/logo bridge -> MRR bridge (new/expansion/contraction/churn) -> usage overage revenue.
A5: Line item | B5: Units / source | C5: Monthly (36 months) | AN5: Quarterly | BA5: Annual
C6: 46023 | D6: 46054 | E6: 46082 | F6: 46113 | G6: 46143 | H6: 46174 | I6: 46204 | J6: 46235 | K6: 46266 | L6: 46296 | M6: 46327 | N6: 46357 | O6: 46388 | P6: 46419 | Q6: 46447 | R6: 46478 | S6: 46508 | T6: 46539 | U6: 46569 | V6: 46600 | W6: 46631 | X6: 46661 | Y6: 46692 | Z6: 46722 | AA6: 46753 | AB6: 46784 | AC6: 46813 | AD6: 46844 | AE6: 46874 | AF6: 46905 | AG6: 46935 | AH6: 46966 | AI6: 46997 | AJ6: 47027 | AK6: 47058 | AL6: 47088 | AN6: Q1 | AO6: Q2 | AP6: Q3 | AQ6: Q4 | AR6: Q5 | AS6: Q6 | AT6: Q7 | AU6: Q8 | AV6: Q9 | AW6: Q10 | AX6: Q11 | AY6: Q12 | BA6: FY1 | BB6: FY2 | BC6: FY3
A7: Customer / Logo Bridge
A8: Beginning Customers | C8: ='Assumptions'!$F$13 -> 0 | D8: =C8 -> 0 | E8: =D8 -> 0 | F8: =E8 -> 0 | G8: =F8 -> 0 | H8: =G8 -> 0 | I8: =H8 -> 0 | J8: =I8 -> 0 | K8: =J8 -> 0 | ... AL8: =AK8 -> 0 | AN8: =E8 -> 0 | AO8: =H8 -> 0 | AP8: =K8 -> 0 | AQ8: =N8 -> 0 | AR8: =Q8 -> 0 | AS8: =T8 -> 0 | AT8: =W8 -> 0 | AU8: =Z8 -> 0 | AV8: =AC8 -> 0 | AW8: =AF8 -> 0 | AX8: =AI8 -> 0 | AY8: =AL8 -> 0 | BA8: =N8 -> 0 | BB8: =Z8 -> 0 | BC8: =AL8 -> 0
A9: New Logos Added | C9: ='Assumptions'!$F$14 -> 0 | D9: =C9*(1+'Assumptions'!$F$15) -> 0 | E9: =D9*(1+'Assumptions'!$F$15) -> 0 | F9: =E9*(1+'Assumptions'!$F$15) -> 0 | G9: =F9*(1+'Assumptions'!$F$15) -> 0 | H9: =G9*(1+'Assumptions'!$F$15) -> 0 | I9: =H9*(1+'Assumptions'!$F$15) -> 0 | J9: =I9*(1+'Assumptions'!$F$15) -> 0 | K9: =J9*(1+'Assumptions'!$F$15) -> 0 | ... AL9: =AK9*(1+'Assumptions'!$F$15) -> 0 | AN9: =SUM(C9:E9) -> 0 | AO9: =SUM(F9:H9) -> 0 | AP9: =SUM(I9:K9) -> 0 | AQ9: =SUM(L9:N9) -> 0 | AR9: =SUM(O9:Q9) -> 0 | AS9: =SUM(R9:T9) -> 0 | AT9: =SUM(U9:W9) -> 0 | AU9: =SUM(X9:Z9) -> 0 | AV9: =SUM(AA9:AC9) -> 0 | AW9: =SUM(AD9:AF9) -> 0 | AX9: =SUM(AG9:AI9) -> 0 | AY9: =SUM(AJ9:AL9) -> 0 | BA9: =SUM(C9:N9) -> 0 | BB9: =SUM(O9:Z9) -> 0 | BC9: =SUM(AA9:AL9) -> 0
A10: Churned Customers | C10: =-C8*'Assumptions'!$F$16 -> 0 | D10: =-D8*'Assumptions'!$F$16 -> 0 | E10: =-E8*'Assumptions'!$F$16 -> 0 | F10: =-F8*'Assumptions'!$F$16 -> 0 | G10: =-G8*'Assumptions'!$F$16 -> 0 | H10: =-H8*'Assumptions'!$F$16 -> 0 | I10: =-I8*'Assumptions'!$F$16 -> 0 | J10: =-J8*'Assumptions'!$F$16 -> 0 | ... AL10: =-AL8*'Assumptions'!$F$16 -> 0 | AN10: =SUM(C10:E10) -> 0 | AO10: =SUM(F10:H10) -> 0 | AP10: =SUM(I10:K10) -> 0 | AQ10: =SUM(L10:N10) -> 0 | AR10: =SUM(O10:Q10) -> 0 | AS10: =SUM(R10:T10) -> 0 | AT10: =SUM(U10:W10) -> 0 | AU10: =SUM(X10:Z10) -> 0 | AV10: =SUM(AA10:AC10) -> 0 | AW10: =SUM(AD10:AF10) -> 0 | AX10: =SUM(AG10:AI10) -> 0 | AY10: =SUM(AJ10:AL10) -> 0 | BA10: =SUM(C10:N10) -> 0 | BB10: =SUM(O10:Z10) -> 0 | BC10: =SUM(AA10:AL10) -> 0
A11: Ending Customers | C11: =C8+C9+C10 -> 0 | D11: =D8+D9+D10 -> 0 | E11: =E8+E9+E10 -> 0 | F11: =F8+F9+F10 -> 0 | G11: =G8+G9+G10 -> 0 | H11: =H8+H9+H10 -> 0 | I11: =I8+I9+I10 -> 0 | J11: =J8+J9+J10 -> 0 | ... AL11: =AL8+AL9+AL10 -> 0 | AN11: =E11 -> 0 | AO11: =H11 -> 0 | AP11: =K11 -> 0 | AQ11: =N11 -> 0 | AR11: =Q11 -> 0 | AS11: =T11 -> 0 | AT11: =W11 -> 0 | AU11: =Z11 -> 0 | AV11: =AC11 -> 0 | AW11: =AF11 -> 0 | AX11: =AI11 -> 0 | AY11: =AL11 -> 0 | BA11: =N11 -> 0 | BB11: =Z11 -> 0 | BC11: =AL11 -> 0
A13: MRR Bridge
A14: ARPA (avg MRR per account) | C14: ='Assumptions'!$F$21 -> 0 | D14: =C14*(1+'Assumptions'!$F$22) -> 0 | E14: =D14*(1+'Assumptions'!$F$22) -> 0 | F14: =E14*(1+'Assumptions'!$F$22) -> 0 | G14: =F14*(1+'Assumptions'!$F$22) -> 0 | H14: =G14*(1+'Assumptions'!$F$22) -> 0 | I14: =H14*(1+'Assumptions'!$F$22) -> 0 | J14: =I14*(1+'Assumptions'!$F$22) -> 0 | K14: =J14*(1+'Assumptions'!$F$22) -> 0 | ... AL14: =AK14*(1+'Assumptions'!$F$22) -> 0 | AN14: =AVERAGE(C14:E14) -> 0 | AO14: =AVERAGE(F14:H14) -> 0 | AP14: =AVERAGE(I14:K14) -> 0 | AQ14: =AVERAGE(L14:N14) -> 0 | AR14: =AVERAGE(O14:Q14) -> 0 | AS14: =AVERAGE(R14:T14) -> 0 | AT14: =AVERAGE(U14:W14) -> 0 | AU14: =AVERAGE(X14:Z14) -> 0 | AV14: =AVERAGE(AA14:AC14) -> 0 | AW14: =AVERAGE(AD14:AF14) -> 0 | AX14: =AVERAGE(AG14:AI14) -> 0 | AY14: =AVERAGE(AJ14:AL14) -> 0 | BA14: =AVERAGE(C14:N14) -> 0 | BB14: =AVERAGE(O14:Z14) -> 0 | BC14: =AVERAGE(AA14:AL14) -> 0
A15: Beginning MRR | C15: ='Assumptions'!$F$13*'Assumptions'!$F$21 -> 0 | D15: =C15 -> 0 | E15: =D15 -> 0 | F15: =E15 -> 0 | G15: =F15 -> 0 | H15: =G15 -> 0 | I15: =H15 -> 0 | J15: =I15 -> 0 | K15: =J15 -> 0 | ... AL15: =AK15 -> 0 | AN15: =E15 -> 0 | AO15: =H15 -> 0 | AP15: =K15 -> 0 | AQ15: =N15 -> 0 | AR15: =Q15 -> 0 | AS15: =T15 -> 0 | AT15: =W15 -> 0 | AU15: =Z15 -> 0 | AV15: =AC15 -> 0 | AW15: =AF15 -> 0 | AX15: =AI15 -> 0 | AY15: =AL15 -> 0 | BA15: =N15 -> 0 | BB15: =Z15 -> 0 | BC15: =AL15 -> 0
A16: New MRR | C16: =C9*C14 -> 0 | D16: =D9*D14 -> 0 | E16: =E9*E14 -> 0 | F16: =F9*F14 -> 0 | G16: =G9*G14 -> 0 | H16: =H9*H14 -> 0 | I16: =I9*I14 -> 0 | J16: =J9*J14 -> 0 | ... AL16: =AL9*AL14 -> 0 | AN16: =SUM(C16:E16) -> 0 | AO16: =SUM(F16:H16) -> 0 | AP16: =SUM(I16:K16) -> 0 | AQ16: =SUM(L16:N16) -> 0 | AR16: =SUM(O16:Q16) -> 0 | AS16: =SUM(R16:T16) -> 0 | AT16: =SUM(U16:W16) -> 0 | AU16: =SUM(X16:Z16) -> 0 | AV16: =SUM(AA16:AC16) -> 0 | AW16: =SUM(AD16:AF16) -> 0 | AX16: =SUM(AG16:AI16) -> 0 | AY16: =SUM(AJ16:AL16) -> 0 | BA16: =SUM(C16:N16) -> 0 | BB16: =SUM(O16:Z16) -> 0 | BC16: =SUM(AA16:AL16) -> 0
A17: Expansion MRR | C17: =C15*'Assumptions'!$F$17 -> 0 | D17: =D15*'Assumptions'!$F$17 -> 0 | E17: =E15*'Assumptions'!$F$17 -> 0 | F17: =F15*'Assumptions'!$F$17 -> 0 | G17: =G15*'Assumptions'!$F$17 -> 0 | H17: =H15*'Assumptions'!$F$17 -> 0 | I17: =I15*'Assumptions'!$F$17 -> 0 | J17: =J15*'Assumptions'!$F$17 -> 0 | ... AL17: =AL15*'Assumptions'!$F$17 -> 0 | AN17: =SUM(C17:E17) -> 0 | AO17: =SUM(F17:H17) -> 0 | AP17: =SUM(I17:K17) -> 0 | AQ17: =SUM(L17:N17) -> 0 | AR17: =SUM(O17:Q17) -> 0 | AS17: =SUM(R17:T17) -> 0 | AT17: =SUM(U17:W17) -> 0 | AU17: =SUM(X17:Z17) -> 0 | AV17: =SUM(AA17:AC17) -> 0 | AW17: =SUM(AD17:AF17) -> 0 | AX17: =SUM(AG17:AI17) -> 0 | AY17: =SUM(AJ17:AL17) -> 0 | BA17: =SUM(C17:N17) -> 0 | BB17: =SUM(O17:Z17) -> 0 | BC17: =SUM(AA17:AL17) -> 0
A18: Contraction MRR | C18: =-C15*'Assumptions'!$F$18 -> 0 | D18: =-D15*'Assumptions'!$F$18 -> 0 | E18: =-E15*'Assumptions'!$F$18 -> 0 | F18: =-F15*'Assumptions'!$F$18 -> 0 | G18: =-G15*'Assumptions'!$F$18 -> 0 | H18: =-H15*'Assumptions'!$F$18 -> 0 | I18: =-I15*'Assumptions'!$F$18 -> 0 | J18: =-J15*'Assumptions'!$F$18 -> 0 | ... AL18: =-AL15*'Assumptions'!$F$18 -> 0 | AN18: =SUM(C18:E18) -> 0 | AO18: =SUM(F18:H18) -> 0 | AP18: =SUM(I18:K18) -> 0 | AQ18: =SUM(L18:N18) -> 0 | AR18: =SUM(O18:Q18) -> 0 | AS18: =SUM(R18:T18) -> 0 | AT18: =SUM(U18:W18) -> 0 | AU18: =SUM(X18:Z18) -> 0 | AV18: =SUM(AA18:AC18) -> 0 | AW18: =SUM(AD18:AF18) -> 0 | AX18: =SUM(AG18:AI18) -> 0 | AY18: =SUM(AJ18:AL18) -> 0 | BA18: =SUM(C18:N18) -> 0 | BB18: =SUM(O18:Z18) -> 0 | BC18: =SUM(AA18:AL18) -> 0
A19: Churned MRR | C19: =-C15*'Assumptions'!$F$16 -> 0 | D19: =-D15*'Assumptions'!$F$16 -> 0 | E19: =-E15*'Assumptions'!$F$16 -> 0 | F19: =-F15*'Assumptions'!$F$16 -> 0 | G19: =-G15*'Assumptions'!$F$16 -> 0 | H19: =-H15*'Assumptions'!$F$16 -> 0 | I19: =-I15*'Assumptions'!$F$16 -> 0 | J19: =-J15*'Assumptions'!$F$16 -> 0 | ... AL19: =-AL15*'Assumptions'!$F$16 -> 0 | AN19: =SUM(C19:E19) -> 0 | AO19: =SUM(F19:H19) -> 0 | AP19: =SUM(I19:K19) -> 0 | AQ19: =SUM(L19:N19) -> 0 | AR19: =SUM(O19:Q19) -> 0 | AS19: =SUM(R19:T19) -> 0 | AT19: =SUM(U19:W19) -> 0 | AU19: =SUM(X19:Z19) -> 0 | AV19: =SUM(AA19:AC19) -> 0 | AW19: =SUM(AD19:AF19) -> 0 | AX19: =SUM(AG19:AI19) -> 0 | AY19: =SUM(AJ19:AL19) -> 0 | BA19: =SUM(C19:N19) -> 0 | BB19: =SUM(O19:Z19) -> 0 | BC19: =SUM(AA19:AL19) -> 0
A20: Ending MRR | C20: =C15+C16+C17+C18+C19 -> 0 | D20: =D15+D16+D17+D18+D19 -> 0 | E20: =E15+E16+E17+E18+E19 -> 0 | F20: =F15+F16+F17+F18+F19 -> 0 | G20: =G15+G16+G17+G18+G19 -> 0 | H20: =H15+H16+H17+H18+H19 -> 0 | I20: =I15+I16+I17+I18+I19 -> 0 | J20: =J15+J16+J17+J18+J19 -> 0 | ... AL20: =AL15+AL16+AL17+AL18+AL19 -> 0 | AN20: =E20 -> 0 | AO20: =H20 -> 0 | AP20: =K20 -> 0 | AQ20: =N20 -> 0 | AR20: =Q20 -> 0 | AS20: =T20 -> 0 | AT20: =W20 -> 0 | AU20: =Z20 -> 0 | AV20: =AC20 -> 0 | AW20: =AF20 -> 0 | AX20: =AI20 -> 0 | AY20: =AL20 -> 0 | BA20: =N20 -> 0 | BB20: =Z20 -> 0 | BC20: =AL20 -> 0
A21: ARR (Ending MRR x 12) | C21: =C20*12 -> 0 | D21: =D20*12 -> 0 | E21: =E20*12 -> 0 | F21: =F20*12 -> 0 | G21: =G20*12 -> 0 | H21: =H20*12 -> 0 | I21: =I20*12 -> 0 | J21: =J20*12 -> 0 | ... AL21: =AL20*12 -> 0 | AN21: =E21 -> 0 | AO21: =H21 -> 0 | AP21: =K21 -> 0 | AQ21: =N21 -> 0 | AR21: =Q21 -> 0 | AS21: =T21 -> 0 | AT21: =W21 -> 0 | AU21: =Z21 -> 0 | AV21: =AC21 -> 0 | AW21: =AF21 -> 0 | AX21: =AI21 -> 0 | AY21: =AL21 -> 0 | BA21: =N21 -> 0 | BB21: =Z21 -> 0 | BC21: =AL21 -> 0
A23: Usage & Overage Revenue
A24: Usage revenue per customer | C24: ='Assumptions'!$F$23 -> 0 | D24: =C24*(1+'Assumptions'!$F$24) -> 0 | E24: =D24*(1+'Assumptions'!$F$24) -> 0 | F24: =E24*(1+'Assumptions'!$F$24) -> 0 | G24: =F24*(1+'Assumptions'!$F$24) -> 0 | H24: =G24*(1+'Assumptions'!$F$24) -> 0 | I24: =H24*(1+'Assumptions'!$F$24) -> 0 | J24: =I24*(1+'Assumptions'!$F$24) -> 0 | K24: =J24*(1+'Assumptions'!$F$24) -> 0 | ... AL24: =AK24*(1+'Assumptions'!$F$24) -> 0 | AN24: =AVERAGE(C24:E24) -> 0 | AO24: =AVERAGE(F24:H24) -> 0 | AP24: =AVERAGE(I24:K24) -> 0 | AQ24: =AVERAGE(L24:N24) -> 0 | AR24: =AVERAGE(O24:Q24) -> 0 | AS24: =AVERAGE(R24:T24) -> 0 | AT24: =AVERAGE(U24:W24) -> 0 | AU24: =AVERAGE(X24:Z24) -> 0 | AV24: =AVERAGE(AA24:AC24) -> 0 | AW24: =AVERAGE(AD24:AF24) -> 0 | AX24: =AVERAGE(AG24:AI24) -> 0 | AY24: =AVERAGE(AJ24:AL24) -> 0 | BA24: =AVERAGE(C24:N24) -> 0 | BB24: =AVERAGE(O24:Z24) -> 0 | BC24: =AVERAGE(AA24:AL24) -> 0
A25: Usage & Overage Revenue | C25: =C11*C24 -> 0 | D25: =D11*D24 -> 0 | E25: =E11*E24 -> 0 | F25: =F11*F24 -> 0 | G25: =G11*G24 -> 0 | H25: =H11*H24 -> 0 | I25: =I11*I24 -> 0 | J25: =J11*J24 -> 0 | ... AL25: =AL11*AL24 -> 0 | AN25: =SUM(C25:E25) -> 0 | AO25: =SUM(F25:H25) -> 0 | AP25: =SUM(I25:K25) -> 0 | AQ25: =SUM(L25:N25) -> 0 | AR25: =SUM(O25:Q25) -> 0 | AS25: =SUM(R25:T25) -> 0 | AT25: =SUM(U25:W25) -> 0 | AU25: =SUM(X25:Z25) -> 0 | AV25: =SUM(AA25:AC25) -> 0 | AW25: =SUM(AD25:AF25) -> 0 | AX25: =SUM(AG25:AI25) -> 0 | AY25: =SUM(AJ25:AL25) -> 0 | BA25: =SUM(C25:N25) -> 0 | BB25: =SUM(O25:Z25) -> 0 | BC25: =SUM(AA25:AL25) -> 0
A27: Total Revenue | C27: =C20+C25 -> 0 | D27: =D20+D25 -> 0 | E27: =E20+E25 -> 0 | F27: =F20+F25 -> 0 | G27: =G20+G25 -> 0 | H27: =H20+H25 -> 0 | I27: =I20+I25 -> 0 | J27: =J20+J25 -> 0 | ... AL27: =AL20+AL25 -> 0 | AN27: =SUM(C27:E27) -> 0 | AO27: =SUM(F27:H27) -> 0 | AP27: =SUM(I27:K27) -> 0 | AQ27: =SUM(L27:N27) -> 0 | AR27: =SUM(O27:Q27) -> 0 | AS27: =SUM(R27:T27) -> 0 | AT27: =SUM(U27:W27) -> 0 | AU27: =SUM(X27:Z27) -> 0 | AV27: =SUM(AA27:AC27) -> 0 | AW27: =SUM(AD27:AF27) -> 0 | AX27: =SUM(AG27:AI27) -> 0 | AY27: =SUM(AJ27:AL27) -> 0 | BA27: =SUM(C27:N27) -> 0 | BB27: =SUM(O27:Z27) -> 0 | BC27: =SUM(AA27:AL27) -> 0
A29: SaaS KPIs
A30: Gross Revenue Retention (GRR) | C30: =IFERROR((C15+C18+C19)/C15,1) -> 0 | D30: =IFERROR((D15+D18+D19)/D15,1) -> 0 | E30: =IFERROR((E15+E18+E19)/E15,1) -> 0 | F30: =IFERROR((F15+F18+F19)/F15,1) -> 0 | G30: =IFERROR((G15+G18+G19)/G15,1) -> 0 | H30: =IFERROR((H15+H18+H19)/H15,1) -> 0 | I30: =IFERROR((I15+I18+I19)/I15,1) -> 0 | J30: =IFERROR((J15+J18+J19)/J15,1) -> 0 | ... AL30: =IFERROR((AL15+AL18+AL19)/AL15,1) -> 0 | AN30: =AVERAGE(C30:E30) -> 0 | AO30: =AVERAGE(F30:H30) -> 0 | AP30: =AVERAGE(I30:K30) -> 0 | AQ30: =AVERAGE(L30:N30) -> 0 | AR30: =AVERAGE(O30:Q30) -> 0 | AS30: =AVERAGE(R30:T30) -> 0 | AT30: =AVERAGE(U30:W30) -> 0 | AU30: =AVERAGE(X30:Z30) -> 0 | AV30: =AVERAGE(AA30:AC30) -> 0 | AW30: =AVERAGE(AD30:AF30) -> 0 | AX30: =AVERAGE(AG30:AI30) -> 0 | AY30: =AVERAGE(AJ30:AL30) -> 0 | BA30: =AVERAGE(C30:N30) -> 0 | BB30: =AVERAGE(O30:Z30) -> 0 | BC30: =AVERAGE(AA30:AL30) -> 0
A31: Net Revenue Retention (NRR) | C31: =IFERROR((C15+C17+C18+C19)/C15,1) -> 0 | D31: =IFERROR((D15+D17+D18+D19)/D15,1) -> 0 | E31: =IFERROR((E15+E17+E18+E19)/E15,1) -> 0 | F31: =IFERROR((F15+F17+F18+F19)/F15,1) -> 0 | G31: =IFERROR((G15+G17+G18+G19)/G15,1) -> 0 | H31: =IFERROR((H15+H17+H18+H19)/H15,1) -> 0 | I31: =IFERROR((I15+I17+I18+I19)/I15,1) -> 0 | J31: =IFERROR((J15+J17+J18+J19)/J15,1) -> 0 | ... AL31: =IFERROR((AL15+AL17+AL18+AL19)/AL15,1) -> 0 | AN31: =AVERAGE(C31:E31) -> 0 | AO31: =AVERAGE(F31:H31) -> 0 | AP31: =AVERAGE(I31:K31) -> 0 | AQ31: =AVERAGE(L31:N31) -> 0 | AR31: =AVERAGE(O31:Q31) -> 0 | AS31: =AVERAGE(R31:T31) -> 0 | AT31: =AVERAGE(U31:W31) -> 0 | AU31: =AVERAGE(X31:Z31) -> 0 | AV31: =AVERAGE(AA31:AC31) -> 0 | AW31: =AVERAGE(AD31:AF31) -> 0 | AX31: =AVERAGE(AG31:AI31) -> 0 | AY31: =AVERAGE(AJ31:AL31) -> 0 | BA31: =AVERAGE(C31:N31) -> 0 | BB31: =AVERAGE(O31:Z31) -> 0 | BC31: =AVERAGE(AA31:AL31) -> 0
A32: MRR Growth (month over month) | C32: =IFERROR(C20/C15-1,0) -> 0 | D32: =IFERROR(D20/D15-1,0) -> 0 | E32: =IFERROR(E20/E15-1,0) -> 0 | F32: =IFERROR(F20/F15-1,0) -> 0 | G32: =IFERROR(G20/G15-1,0) -> 0 | H32: =IFERROR(H20/H15-1,0) -> 0 | I32: =IFERROR(I20/I15-1,0) -> 0 | J32: =IFERROR(J20/J15-1,0) -> 0 | ... AL32: =IFERROR(AL20/AL15-1,0) -> 0 | AN32: =AVERAGE(C32:E32) -> 0 | AO32: =AVERAGE(F32:H32) -> 0 | AP32: =AVERAGE(I32:K32) -> 0 | AQ32: =AVERAGE(L32:N32) -> 0 | AR32: =AVERAGE(O32:Q32) -> 0 | AS32: =AVERAGE(R32:T32) -> 0 | AT32: =AVERAGE(U32:W32) -> 0 | AU32: =AVERAGE(X32:Z32) -> 0 | AV32: =AVERAGE(AA32:AC32) -> 0 | AW32: =AVERAGE(AD32:AF32) -> 0 | AX32: =AVERAGE(AG32:AI32) -> 0 | AY32: =AVERAGE(AJ32:AL32) -> 0 | BA32: =AVERAGE(C32:N32) -> 0 | BB32: =AVERAGE(O32:Z32) -> 0 | BC32: =AVERAGE(AA32:AL32) -> 0

Sheet COGS & GM
A1: B2B SaaS + Usage — 3-Year Financial Model — COGS & GM
A2: Hosting, third-party data/API, payment processing, and Customer Success headcount.
A5: Line item | B5: Units / source | C5: Monthly (36 months) | AN5: Quarterly | BA5: Annual
C6: 46023 | D6: 46054 | E6: 46082 | F6: 46113 | G6: 46143 | H6: 46174 | I6: 46204 | J6: 46235 | K6: 46266 | L6: 46296 | M6: 46327 | N6: 46357 | O6: 46388 | P6: 46419 | Q6: 46447 | R6: 46478 | S6: 46508 | T6: 46539 | U6: 46569 | V6: 46600 | W6: 46631 | X6: 46661 | Y6: 46692 | Z6: 46722 | AA6: 46753 | AB6: 46784 | AC6: 46813 | AD6: 46844 | AE6: 46874 | AF6: 46905 | AG6: 46935 | AH6: 46966 | AI6: 46997 | AJ6: 47027 | AK6: 47058 | AL6: 47088 | AN6: Q1 | AO6: Q2 | AP6: Q3 | AQ6: Q4 | AR6: Q5 | AS6: Q6 | AT6: Q7 | AU6: Q8 | AV6: Q9 | AW6: Q10 | AX6: Q11 | AY6: Q12 | BA6: FY1 | BB6: FY2 | BC6: FY3
A7: COGS Components
A8: Hosting & Infrastructure | C8: ='Revenue'!C27*'Assumptions'!$F$27 -> 0 | D8: ='Revenue'!D27*'Assumptions'!$F$27 -> 0 | E8: ='Revenue'!E27*'Assumptions'!$F$27 -> 0 | F8: ='Revenue'!F27*'Assumptions'!$F$27 -> 0 | G8: ='Revenue'!G27*'Assumptions'!$F$27 -> 0 | H8: ='Revenue'!H27*'Assumptions'!$F$27 -> 0 | I8: ='Revenue'!I27*'Assumptions'!$F$27 -> 0 | J8: ='Revenue'!J27*'Assumptions'!$F$27 -> 0 | ... AL8: ='Revenue'!AL27*'Assumptions'!$F$27 -> 0 | AN8: =SUM(C8:E8) -> 0 | AO8: =SUM(F8:H8) -> 0 | AP8: =SUM(I8:K8) -> 0 | AQ8: =SUM(L8:N8) -> 0 | AR8: =SUM(O8:Q8) -> 0 | AS8: =SUM(R8:T8) -> 0 | AT8: =SUM(U8:W8) -> 0 | AU8: =SUM(X8:Z8) -> 0 | AV8: =SUM(AA8:AC8) -> 0 | AW8: =SUM(AD8:AF8) -> 0 | AX8: =SUM(AG8:AI8) -> 0 | AY8: =SUM(AJ8:AL8) -> 0 | BA8: =SUM(C8:N8) -> 0 | BB8: =SUM(O8:Z8) -> 0 | BC8: =SUM(AA8:AL8) -> 0
A9: Third-Party Data / APIs | C9: ='Revenue'!C27*'Assumptions'!$F$28 -> 0 | D9: ='Revenue'!D27*'Assumptions'!$F$28 -> 0 | E9: ='Revenue'!E27*'Assumptions'!$F$28 -> 0 | F9: ='Revenue'!F27*'Assumptions'!$F$28 -> 0 | G9: ='Revenue'!G27*'Assumptions'!$F$28 -> 0 | H9: ='Revenue'!H27*'Assumptions'!$F$28 -> 0 | I9: ='Revenue'!I27*'Assumptions'!$F$28 -> 0 | J9: ='Revenue'!J27*'Assumptions'!$F$28 -> 0 | ... AL9: ='Revenue'!AL27*'Assumptions'!$F$28 -> 0 | AN9: =SUM(C9:E9) -> 0 | AO9: =SUM(F9:H9) -> 0 | AP9: =SUM(I9:K9) -> 0 | AQ9: =SUM(L9:N9) -> 0 | AR9: =SUM(O9:Q9) -> 0 | AS9: =SUM(R9:T9) -> 0 | AT9: =SUM(U9:W9) -> 0 | AU9: =SUM(X9:Z9) -> 0 | AV9: =SUM(AA9:AC9) -> 0 | AW9: =SUM(AD9:AF9) -> 0 | AX9: =SUM(AG9:AI9) -> 0 | AY9: =SUM(AJ9:AL9) -> 0 | BA9: =SUM(C9:N9) -> 0 | BB9: =SUM(O9:Z9) -> 0 | BC9: =SUM(AA9:AL9) -> 0
A10: Payment Processing Fees | C10: ='Revenue'!C27*'Assumptions'!$F$29 -> 0 | D10: ='Revenue'!D27*'Assumptions'!$F$29 -> 0 | E10: ='Revenue'!E27*'Assumptions'!$F$29 -> 0 | F10: ='Revenue'!F27*'Assumptions'!$F$29 -> 0 | G10: ='Revenue'!G27*'Assumptions'!$F$29 -> 0 | H10: ='Revenue'!H27*'Assumptions'!$F$29 -> 0 | I10: ='Revenue'!I27*'Assumptions'!$F$29 -> 0 | J10: ='Revenue'!J27*'Assumptions'!$F$29 -> 0 | ... AL10: ='Revenue'!AL27*'Assumptions'!$F$29 -> 0 | AN10: =SUM(C10:E10) -> 0 | AO10: =SUM(F10:H10) -> 0 | AP10: =SUM(I10:K10) -> 0 | AQ10: =SUM(L10:N10) -> 0 | AR10: =SUM(O10:Q10) -> 0 | AS10: =SUM(R10:T10) -> 0 | AT10: =SUM(U10:W10) -> 0 | AU10: =SUM(X10:Z10) -> 0 | AV10: =SUM(AA10:AC10) -> 0 | AW10: =SUM(AD10:AF10) -> 0 | AX10: =SUM(AG10:AI10) -> 0 | AY10: =SUM(AJ10:AL10) -> 0 | BA10: =SUM(C10:N10) -> 0 | BB10: =SUM(O10:Z10) -> 0 | BC10: =SUM(AA10:AL10) -> 0
A11: Customer Success & Support (people) | C11: ='Headcount'!$C$23 -> 0 | D11: ='Headcount'!$D$23 -> 0 | E11: ='Headcount'!$E$23 -> 0 | F11: ='Headcount'!$F$23 -> 0 | G11: ='Headcount'!$G$23 -> 0 | H11: ='Headcount'!$H$23 -> 0 | I11: ='Headcount'!$I$23 -> 0 | J11: ='Headcount'!$J$23 -> 0 | K11: ='Headcount'!$K$23 -> 0 | L11: ='Headcount'!$L$23 -> 0 | M11: ='Headcount'!$M$23 -> 0 | N11: ='Headcount'!$N$23 -> 0 | O11: ='Headcount'!$O$23 -> 0 | P11: ='Headcount'!$P$23 -> 0 | Q11: ='Headcount'!$Q$23 -> 0 | R11: ='Headcount'!$R$23 -> 0 | S11: ='Headcount'!$S$23 -> 0 | T11: ='Headcount'!$T$23 -> 0 | U11: ='Headcount'!$U$23 -> 0 | V11: ='Headcount'!$V$23 -> 0 | W11: ='Headcount'!$W$23 -> 0 | X11: ='Headcount'!$X$23 -> 0 | Y11: ='Headcount'!$Y$23 -> 0 | Z11: ='Headcount'!$Z$23 -> 0 | AA11: ='Headcount'!$AA$23 -> 0 | AB11: ='Headcount'!$AB$23 -> 0 | AC11: ='Headcount'!$AC$23 -> 0 | AD11: ='Headcount'!$AD$23 -> 0 | AE11: ='Headcount'!$AE$23 -> 0 | AF11: ='Headcount'!$AF$23 -> 0 | AG11: ='Headcount'!$AG$23 -> 0 | AH11: ='Headcount'!$AH$23 -> 0 | AI11: ='Headcount'!$AI$23 -> 0 | AJ11: ='Headcount'!$AJ$23 -> 0 | AK11: ='Headcount'!$AK$23 -> 0 | AL11: ='Headcount'!$AL$23 -> 0 | AN11: =SUM(C11:E11) -> 0 | AO11: =SUM(F11:H11) -> 0 | AP11: =SUM(I11:K11) -> 0 | AQ11: =SUM(L11:N11) -> 0 | AR11: =SUM(O11:Q11) -> 0 | AS11: =SUM(R11:T11) -> 0 | AT11: =SUM(U11:W11) -> 0 | AU11: =SUM(X11:Z11) -> 0 | AV11: =SUM(AA11:AC11) -> 0 | AW11: =SUM(AD11:AF11) -> 0 | AX11: =SUM(AG11:AI11) -> 0 | AY11: =SUM(AJ11:AL11) -> 0 | BA11: =SUM(C11:N11) -> 0 | BB11: =SUM(O11:Z11) -> 0 | BC11: =SUM(AA11:AL11) -> 0
A12: Total COGS | C12: =C8+C9+C10+C11 -> 0 | D12: =D8+D9+D10+D11 -> 0 | E12: =E8+E9+E10+E11 -> 0 | F12: =F8+F9+F10+F11 -> 0 | G12: =G8+G9+G10+G11 -> 0 | H12: =H8+H9+H10+H11 -> 0 | I12: =I8+I9+I10+I11 -> 0 | J12: =J8+J9+J10+J11 -> 0 | ... AL12: =AL8+AL9+AL10+AL11 -> 0 | AN12: =SUM(C12:E12) -> 0 | AO12: =SUM(F12:H12) -> 0 | AP12: =SUM(I12:K12) -> 0 | AQ12: =SUM(L12:N12) -> 0 | AR12: =SUM(O12:Q12) -> 0 | AS12: =SUM(R12:T12) -> 0 | AT12: =SUM(U12:W12) -> 0 | AU12: =SUM(X12:Z12) -> 0 | AV12: =SUM(AA12:AC12) -> 0 | AW12: =SUM(AD12:AF12) -> 0 | AX12: =SUM(AG12:AI12) -> 0 | AY12: =SUM(AJ12:AL12) -> 0 | BA12: =SUM(C12:N12) -> 0 | BB12: =SUM(O12:Z12) -> 0 | BC12: =SUM(AA12:AL12) -> 0
A14: Gross Profit
A15: Gross Profit | C15: ='Revenue'!C27-C12 -> 0 | D15: ='Revenue'!D27-D12 -> 0 | E15: ='Revenue'!E27-E12 -> 0 | F15: ='Revenue'!F27-F12 -> 0 | G15: ='Revenue'!G27-G12 -> 0 | H15: ='Revenue'!H27-H12 -> 0 | I15: ='Revenue'!I27-I12 -> 0 | J15: ='Revenue'!J27-J12 -> 0 | ... AL15: ='Revenue'!AL27-AL12 -> 0 | AN15: =SUM(C15:E15) -> 0 | AO15: =SUM(F15:H15) -> 0 | AP15: =SUM(I15:K15) -> 0 | AQ15: =SUM(L15:N15) -> 0 | AR15: =SUM(O15:Q15) -> 0 | AS15: =SUM(R15:T15) -> 0 | AT15: =SUM(U15:W15) -> 0 | AU15: =SUM(X15:Z15) -> 0 | AV15: =SUM(AA15:AC15) -> 0 | AW15: =SUM(AD15:AF15) -> 0 | AX15: =SUM(AG15:AI15) -> 0 | AY15: =SUM(AJ15:AL15) -> 0 | BA15: =SUM(C15:N15) -> 0 | BB15: =SUM(O15:Z15) -> 0 | BC15: =SUM(AA15:AL15) -> 0
A16: Gross Margin % | C16: =IFERROR(C15/'Revenue'!C27,0) -> 0 | D16: =IFERROR(D15/'Revenue'!D27,0) -> 0 | E16: =IFERROR(E15/'Revenue'!E27,0) -> 0 | F16: =IFERROR(F15/'Revenue'!F27,0) -> 0 | G16: =IFERROR(G15/'Revenue'!G27,0) -> 0 | H16: =IFERROR(H15/'Revenue'!H27,0) -> 0 | I16: =IFERROR(I15/'Revenue'!I27,0) -> 0 | J16: =IFERROR(J15/'Revenue'!J27,0) -> 0 | ... AL16: =IFERROR(AL15/'Revenue'!AL27,0) -> 0 | AN16: =AVERAGE(C16:E16) -> 0 | AO16: =AVERAGE(F16:H16) -> 0 | AP16: =AVERAGE(I16:K16) -> 0 | AQ16: =AVERAGE(L16:N16) -> 0 | AR16: =AVERAGE(O16:Q16) -> 0 | AS16: =AVERAGE(R16:T16) -> 0 | AT16: =AVERAGE(U16:W16) -> 0 | AU16: =AVERAGE(X16:Z16) -> 0 | AV16: =AVERAGE(AA16:AC16) -> 0 | AW16: =AVERAGE(AD16:AF16) -> 0 | AX16: =AVERAGE(AG16:AI16) -> 0 | AY16: =AVERAGE(AJ16:AL16) -> 0 | BA16: =AVERAGE(C16:N16) -> 0 | BB16: =AVERAGE(O16:Z16) -> 0 | BC16: =AVERAGE(AA16:AL16) -> 0

Sheet Opex
A1: B2B SaaS + Usage — 3-Year Financial Model — Opex
A2: Operating expenses by department — headcount cost plus program spend.
A5: Line item | B5: Units / source | C5: Monthly (36 months) | AN5: Quarterly | BA5: Annual
C6: 46023 | D6: 46054 | E6: 46082 | F6: 46113 | G6: 46143 | H6: 46174 | I6: 46204 | J6: 46235 | K6: 46266 | L6: 46296 | M6: 46327 | N6: 46357 | O6: 46388 | P6: 46419 | Q6: 46447 | R6: 46478 | S6: 46508 | T6: 46539 | U6: 46569 | V6: 46600 | W6: 46631 | X6: 46661 | Y6: 46692 | Z6: 46722 | AA6: 46753 | AB6: 46784 | AC6: 46813 | AD6: 46844 | AE6: 46874 | AF6: 46905 | AG6: 46935 | AH6: 46966 | AI6: 46997 | AJ6: 47027 | AK6: 47058 | AL6: 47088 | AN6: Q1 | AO6: Q2 | AP6: Q3 | AQ6: Q4 | AR6: Q5 | AS6: Q6 | AT6: Q7 | AU6: Q8 | AV6: Q9 | AW6: Q10 | AX6: Q11 | AY6: Q12 | BA6: FY1 | BB6: FY2 | BC6: FY3
A7: Sales & Marketing
A8: Sales & Marketing — people cost | B8: Linked from Headcount tab | C8: ='Headcount'!$C$27 -> 0 | D8: ='Headcount'!$D$27 -> 0 | E8: ='Headcount'!$E$27 -> 0 | F8: ='Headcount'!$F$27 -> 0 | G8: ='Headcount'!$G$27 -> 0 | H8: ='Headcount'!$H$27 -> 0 | I8: ='Headcount'!$I$27 -> 0 | J8: ='Headcount'!$J$27 -> 0 | K8: ='Headcount'!$K$27 -> 0 | L8: ='Headcount'!$L$27 -> 0 | M8: ='Headcount'!$M$27 -> 0 | N8: ='Headcount'!$N$27 -> 0 | O8: ='Headcount'!$O$27 -> 0 | P8: ='Headcount'!$P$27 -> 0 | Q8: ='Headcount'!$Q$27 -> 0 | R8: ='Headcount'!$R$27 -> 0 | S8: ='Headcount'!$S$27 -> 0 | T8: ='Headcount'!$T$27 -> 0 | U8: ='Headcount'!$U$27 -> 0 | V8: ='Headcount'!$V$27 -> 0 | W8: ='Headcount'!$W$27 -> 0 | X8: ='Headcount'!$X$27 -> 0 | Y8: ='Headcount'!$Y$27 -> 0 | Z8: ='Headcount'!$Z$27 -> 0 | AA8: ='Headcount'!$AA$27 -> 0 | AB8: ='Headcount'!$AB$27 -> 0 | AC8: ='Headcount'!$AC$27 -> 0 | AD8: ='Headcount'!$AD$27 -> 0 | AE8: ='Headcount'!$AE$27 -> 0 | AF8: ='Headcount'!$AF$27 -> 0 | AG8: ='Headcount'!$AG$27 -> 0 | AH8: ='Headcount'!$AH$27 -> 0 | AI8: ='Headcount'!$AI$27 -> 0 | AJ8: ='Headcount'!$AJ$27 -> 0 | AK8: ='Headcount'!$AK$27 -> 0 | AL8: ='Headcount'!$AL$27 -> 0 | AN8: =SUM(C8:E8) -> 0 | AO8: =SUM(F8:H8) -> 0 | AP8: =SUM(I8:K8) -> 0 | AQ8: =SUM(L8:N8) -> 0 | AR8: =SUM(O8:Q8) -> 0 | AS8: =SUM(R8:T8) -> 0 | AT8: =SUM(U8:W8) -> 0 | AU8: =SUM(X8:Z8) -> 0 | AV8: =SUM(AA8:AC8) -> 0 | AW8: =SUM(AD8:AF8) -> 0 | AX8: =SUM(AG8:AI8) -> 0 | AY8: =SUM(AJ8:AL8) -> 0 | BA8: =SUM(C8:N8) -> 0 | BB8: =SUM(O8:Z8) -> 0 | BC8: =SUM(AA8:AL8) -> 0
A9: Sales Commissions | B9: 10% of newly booked ARR | C9: ='Revenue'!C16*12*'Assumptions'!$F$55 -> 0 | D9: ='Revenue'!D16*12*'Assumptions'!$F$55 -> 0 | E9: ='Revenue'!E16*12*'Assumptions'!$F$55 -> 0 | F9: ='Revenue'!F16*12*'Assumptions'!$F$55 -> 0 | G9: ='Revenue'!G16*12*'Assumptions'!$F$55 -> 0 | H9: ='Revenue'!H16*12*'Assumptions'!$F$55 -> 0 | I9: ='Revenue'!I16*12*'Assumptions'!$F$55 -> 0 | J9: ='Revenue'!J16*12*'Assumptions'!$F$55 -> 0 | ... AL9: ='Revenue'!AL16*12*'Assumptions'!$F$55 -> 0 | AN9: =SUM(C9:E9) -> 0 | AO9: =SUM(F9:H9) -> 0 | AP9: =SUM(I9:K9) -> 0 | AQ9: =SUM(L9:N9) -> 0 | AR9: =SUM(O9:Q9) -> 0 | AS9: =SUM(R9:T9) -> 0 | AT9: =SUM(U9:W9) -> 0 | AU9: =SUM(X9:Z9) -> 0 | AV9: =SUM(AA9:AC9) -> 0 | AW9: =SUM(AD9:AF9) -> 0 | AX9: =SUM(AG9:AI9) -> 0 | AY9: =SUM(AJ9:AL9) -> 0 | BA9: =SUM(C9:N9) -> 0 | BB9: =SUM(O9:Z9) -> 0 | BC9: =SUM(AA9:AL9) -> 0
A10: Marketing Programs | B10: % of total revenue | C10: ='Revenue'!C27*'Assumptions'!$F$56 -> 0 | D10: ='Revenue'!D27*'Assumptions'!$F$56 -> 0 | E10: ='Revenue'!E27*'Assumptions'!$F$56 -> 0 | F10: ='Revenue'!F27*'Assumptions'!$F$56 -> 0 | G10: ='Revenue'!G27*'Assumptions'!$F$56 -> 0 | H10: ='Revenue'!H27*'Assumptions'!$F$56 -> 0 | I10: ='Revenue'!I27*'Assumptions'!$F$56 -> 0 | J10: ='Revenue'!J27*'Assumptions'!$F$56 -> 0 | ... AL10: ='Revenue'!AL27*'Assumptions'!$F$56 -> 0 | AN10: =SUM(C10:E10) -> 0 | AO10: =SUM(F10:H10) -> 0 | AP10: =SUM(I10:K10) -> 0 | AQ10: =SUM(L10:N10) -> 0 | AR10: =SUM(O10:Q10) -> 0 | AS10: =SUM(R10:T10) -> 0 | AT10: =SUM(U10:W10) -> 0 | AU10: =SUM(X10:Z10) -> 0 | AV10: =SUM(AA10:AC10) -> 0 | AW10: =SUM(AD10:AF10) -> 0 | AX10: =SUM(AG10:AI10) -> 0 | AY10: =SUM(AJ10:AL10) -> 0 | BA10: =SUM(C10:N10) -> 0 | BB10: =SUM(O10:Z10) -> 0 | BC10: =SUM(AA10:AL10) -> 0
A11: Total Sales & Marketing | C11: =C8+C9+C10 -> 0 | D11: =D8+D9+D10 -> 0 | E11: =E8+E9+E10 -> 0 | F11: =F8+F9+F10 -> 0 | G11: =G8+G9+G10 -> 0 | H11: =H8+H9+H10 -> 0 | I11: =I8+I9+I10 -> 0 | J11: =J8+J9+J10 -> 0 | ... AL11: =AL8+AL9+AL10 -> 0 | AN11: =SUM(C11:E11) -> 0 | AO11: =SUM(F11:H11) -> 0 | AP11: =SUM(I11:K11) -> 0 | AQ11: =SUM(L11:N11) -> 0 | AR11: =SUM(O11:Q11) -> 0 | AS11: =SUM(R11:T11) -> 0 | AT11: =SUM(U11:W11) -> 0 | AU11: =SUM(X11:Z11) -> 0 | AV11: =SUM(AA11:AC11) -> 0 | AW11: =SUM(AD11:AF11) -> 0 | AX11: =SUM(AG11:AI11) -> 0 | AY11: =SUM(AJ11:AL11) -> 0 | BA11: =SUM(C11:N11) -> 0 | BB11: =SUM(O11:Z11) -> 0 | BC11: =SUM(AA11:AL11) -> 0
A13: R&D / Engineering
A14: R&D / Engineering — people cost | B14: Linked from Headcount tab | C14: ='Headcount'!$C$26 -> 0 | D14: ='Headcount'!$D$26 -> 0 | E14: ='Headcount'!$E$26 -> 0 | F14: ='Headcount'!$F$26 -> 0 | G14: ='Headcount'!$G$26 -> 0 | H14: ='Headcount'!$H$26 -> 0 | I14: ='Headcount'!$I$26 -> 0 | J14: ='Headcount'!$J$26 -> 0 | K14: ='Headcount'!$K$26 -> 0 | L14: ='Headcount'!$L$26 -> 0 | M14: ='Headcount'!$M$26 -> 0 | N14: ='Headcount'!$N$26 -> 0 | O14: ='Headcount'!$O$26 -> 0 | P14: ='Headcount'!$P$26 -> 0 | Q14: ='Headcount'!$Q$26 -> 0 | R14: ='Headcount'!$R$26 -> 0 | S14: ='Headcount'!$S$26 -> 0 | T14: ='Headcount'!$T$26 -> 0 | U14: ='Headcount'!$U$26 -> 0 | V14: ='Headcount'!$V$26 -> 0 | W14: ='Headcount'!$W$26 -> 0 | X14: ='Headcount'!$X$26 -> 0 | Y14: ='Headcount'!$Y$26 -> 0 | Z14: ='Headcount'!$Z$26 -> 0 | AA14: ='Headcount'!$AA$26 -> 0 | AB14: ='Headcount'!$AB$26 -> 0 | AC14: ='Headcount'!$AC$26 -> 0 | AD14: ='Headcount'!$AD$26 -> 0 | AE14: ='Headcount'!$AE$26 -> 0 | AF14: ='Headcount'!$AF$26 -> 0 | AG14: ='Headcount'!$AG$26 -> 0 | AH14: ='Headcount'!$AH$26 -> 0 | AI14: ='Headcount'!$AI$26 -> 0 | AJ14: ='Headcount'!$AJ$26 -> 0 | AK14: ='Headcount'!$AK$26 -> 0 | AL14: ='Headcount'!$AL$26 -> 0 | AN14: =SUM(C14:E14) -> 0 | AO14: =SUM(F14:H14) -> 0 | AP14: =SUM(I14:K14) -> 0 | AQ14: =SUM(L14:N14) -> 0 | AR14: =SUM(O14:Q14) -> 0 | AS14: =SUM(R14:T14) -> 0 | AT14: =SUM(U14:W14) -> 0 | AU14: =SUM(X14:Z14) -> 0 | AV14: =SUM(AA14:AC14) -> 0 | AW14: =SUM(AD14:AF14) -> 0 | AX14: =SUM(AG14:AI14) -> 0 | AY14: =SUM(AJ14:AL14) -> 0 | BA14: =SUM(C14:N14) -> 0 | BB14: =SUM(O14:Z14) -> 0 | BC14: =SUM(AA14:AL14) -> 0
A15: Total R&D / Engineering | C15: =C14 -> 0 | D15: =D14 -> 0 | E15: =E14 -> 0 | F15: =F14 -> 0 | G15: =G14 -> 0 | H15: =H14 -> 0 | I15: =I14 -> 0 | J15: =J14 -> 0 | ... AL15: =AL14 -> 0 | AN15: =SUM(C15:E15) -> 0 | AO15: =SUM(F15:H15) -> 0 | AP15: =SUM(I15:K15) -> 0 | AQ15: =SUM(L15:N15) -> 0 | AR15: =SUM(O15:Q15) -> 0 | AS15: =SUM(R15:T15) -> 0 | AT15: =SUM(U15:W15) -> 0 | AU15: =SUM(X15:Z15) -> 0 | AV15: =SUM(AA15:AC15) -> 0 | AW15: =SUM(AD15:AF15) -> 0 | AX15: =SUM(AG15:AI15) -> 0 | AY15: =SUM(AJ15:AL15) -> 0 | BA15: =SUM(C15:N15) -> 0 | BB15: =SUM(O15:Z15) -> 0 | BC15: =SUM(AA15:AL15) -> 0
A17: General & Administrative
A18: General & Administrative — people cost | B18: Linked from Headcount tab | C18: ='Headcount'!$C$25 -> 0 | D18: ='Headcount'!$D$25 -> 0 | E18: ='Headcount'!$E$25 -> 0 | F18: ='Headcount'!$F$25 -> 0 | G18: ='Headcount'!$G$25 -> 0 | H18: ='Headcount'!$H$25 -> 0 | I18: ='Headcount'!$I$25 -> 0 | J18: ='Headcount'!$J$25 -> 0 | K18: ='Headcount'!$K$25 -> 0 | L18: ='Headcount'!$L$25 -> 0 | M18: ='Headcount'!$M$25 -> 0 | N18: ='Headcount'!$N$25 -> 0 | O18: ='Headcount'!$O$25 -> 0 | P18: ='Headcount'!$P$25 -> 0 | Q18: ='Headcount'!$Q$25 -> 0 | R18: ='Headcount'!$R$25 -> 0 | S18: ='Headcount'!$S$25 -> 0 | T18: ='Headcount'!$T$25 -> 0 | U18: ='Headcount'!$U$25 -> 0 | V18: ='Headcount'!$V$25 -> 0 | W18: ='Headcount'!$W$25 -> 0 | X18: ='Headcount'!$X$25 -> 0 | Y18: ='Headcount'!$Y$25 -> 0 | Z18: ='Headcount'!$Z$25 -> 0 | AA18: ='Headcount'!$AA$25 -> 0 | AB18: ='Headcount'!$AB$25 -> 0 | AC18: ='Headcount'!$AC$25 -> 0 | AD18: ='Headcount'!$AD$25 -> 0 | AE18: ='Headcount'!$AE$25 -> 0 | AF18: ='Headcount'!$AF$25 -> 0 | AG18: ='Headcount'!$AG$25 -> 0 | AH18: ='Headcount'!$AH$25 -> 0 | AI18: ='Headcount'!$AI$25 -> 0 | AJ18: ='Headcount'!$AJ$25 -> 0 | AK18: ='Headcount'!$AK$25 -> 0 | AL18: ='Headcount'!$AL$25 -> 0 | AN18: =SUM(C18:E18) -> 0 | AO18: =SUM(F18:H18) -> 0 | AP18: =SUM(I18:K18) -> 0 | AQ18: =SUM(L18:N18) -> 0 | AR18: =SUM(O18:Q18) -> 0 | AS18: =SUM(R18:T18) -> 0 | AT18: =SUM(U18:W18) -> 0 | AU18: =SUM(X18:Z18) -> 0 | AV18: =SUM(AA18:AC18) -> 0 | AW18: =SUM(AD18:AF18) -> 0 | AX18: =SUM(AG18:AI18) -> 0 | AY18: =SUM(AJ18:AL18) -> 0 | BA18: =SUM(C18:N18) -> 0 | BB18: =SUM(O18:Z18) -> 0 | BC18: =SUM(AA18:AL18) -> 0
A19: Software & Tools | B19: Fixed monthly | C19: ='Assumptions'!$F$57 -> 0 | D19: ='Assumptions'!$F$57 -> 0 | E19: ='Assumptions'!$F$57 -> 0 | F19: ='Assumptions'!$F$57 -> 0 | G19: ='Assumptions'!$F$57 -> 0 | H19: ='Assumptions'!$F$57 -> 0 | I19: ='Assumptions'!$F$57 -> 0 | J19: ='Assumptions'!$F$57 -> 0 | ... AL19: ='Assumptions'!$F$57 -> 0 | AN19: =SUM(C19:E19) -> 0 | AO19: =SUM(F19:H19) -> 0 | AP19: =SUM(I19:K19) -> 0 | AQ19: =SUM(L19:N19) -> 0 | AR19: =SUM(O19:Q19) -> 0 | AS19: =SUM(R19:T19) -> 0 | AT19: =SUM(U19:W19) -> 0 | AU19: =SUM(X19:Z19) -> 0 | AV19: =SUM(AA19:AC19) -> 0 | AW19: =SUM(AD19:AF19) -> 0 | AX19: =SUM(AG19:AI19) -> 0 | AY19: =SUM(AJ19:AL19) -> 0 | BA19: =SUM(C19:N19) -> 0 | BB19: =SUM(O19:Z19) -> 0 | BC19: =SUM(AA19:AL19) -> 0
A20: Facilities & Other | B20: Fixed monthly | C20: ='Assumptions'!$F$58 -> 0 | D20: ='Assumptions'!$F$58 -> 0 | E20: ='Assumptions'!$F$58 -> 0 | F20: ='Assumptions'!$F$58 -> 0 | G20: ='Assumptions'!$F$58 -> 0 | H20: ='Assumptions'!$F$58 -> 0 | I20: ='Assumptions'!$F$58 -> 0 | J20: ='Assumptions'!$F$58 -> 0 | ... AL20: ='Assumptions'!$F$58 -> 0 | AN20: =SUM(C20:E20) -> 0 | AO20: =SUM(F20:H20) -> 0 | AP20: =SUM(I20:K20) -> 0 | AQ20: =SUM(L20:N20) -> 0 | AR20: =SUM(O20:Q20) -> 0 | AS20: =SUM(R20:T20) -> 0 | AT20: =SUM(U20:W20) -> 0 | AU20: =SUM(X20:Z20) -> 0 | AV20: =SUM(AA20:AC20) -> 0 | AW20: =SUM(AD20:AF20) -> 0 | AX20: =SUM(AG20:AI20) -> 0 | AY20: =SUM(AJ20:AL20) -> 0 | BA20: =SUM(C20:N20) -> 0 | BB20: =SUM(O20:Z20) -> 0 | BC20: =SUM(AA20:AL20) -> 0
A21: Total General & Administrative | C21: =C18+C19+C20 -> 0 | D21: =D18+D19+D20 -> 0 | E21: =E18+E19+E20 -> 0 | F21: =F18+F19+F20 -> 0 | G21: =G18+G19+G20 -> 0 | H21: =H18+H19+H20 -> 0 | I21: =I18+I19+I20 -> 0 | J21: =J18+J19+J20 -> 0 | ... AL21: =AL18+AL19+AL20 -> 0 | AN21: =SUM(C21:E21) -> 0 | AO21: =SUM(F21:H21) -> 0 | AP21: =SUM(I21:K21) -> 0 | AQ21: =SUM(L21:N21) -> 0 | AR21: =SUM(O21:Q21) -> 0 | AS21: =SUM(R21:T21) -> 0 | AT21: =SUM(U21:W21) -> 0 | AU21: =SUM(X21:Z21) -> 0 | AV21: =SUM(AA21:AC21) -> 0 | AW21: =SUM(AD21:AF21) -> 0 | AX21: =SUM(AG21:AI21) -> 0 | AY21: =SUM(AJ21:AL21) -> 0 | BA21: =SUM(C21:N21) -> 0 | BB21: =SUM(O21:Z21) -> 0 | BC21: =SUM(AA21:AL21) -> 0
A23: Total Operating Expenses
A24: Total Opex | C24: =C11+C15+C21 -> 0 | D24: =D11+D15+D21 -> 0 | E24: =E11+E15+E21 -> 0 | F24: =F11+F15+F21 -> 0 | G24: =G11+G15+G21 -> 0 | H24: =H11+H15+H21 -> 0 | I24: =I11+I15+I21 -> 0 | J24: =J11+J15+J21 -> 0 | ... AL24: =AL11+AL15+AL21 -> 0 | AN24: =SUM(C24:E24) -> 0 | AO24: =SUM(F24:H24) -> 0 | AP24: =SUM(I24:K24) -> 0 | AQ24: =SUM(L24:N24) -> 0 | AR24: =SUM(O24:Q24) -> 0 | AS24: =SUM(R24:T24) -> 0 | AT24: =SUM(U24:W24) -> 0 | AU24: =SUM(X24:Z24) -> 0 | AV24: =SUM(AA24:AC24) -> 0 | AW24: =SUM(AD24:AF24) -> 0 | AX24: =SUM(AG24:AI24) -> 0 | AY24: =SUM(AJ24:AL24) -> 0 | BA24: =SUM(C24:N24) -> 0 | BB24: =SUM(O24:Z24) -> 0 | BC24: =SUM(AA24:AL24) -> 0

Sheet Working Capital
A1: B2B SaaS + Usage — 3-Year Financial Model — Working Capital
A2: Balance-sheet drivers: receivables, payables, deferred revenue, capex/depreciation, debt & equity financing.
A5: Line item | B5: Units / source | C5: Monthly (36 months) | AN5: Quarterly | BA5: Annual
C6: 46023 | D6: 46054 | E6: 46082 | F6: 46113 | G6: 46143 | H6: 46174 | I6: 46204 | J6: 46235 | K6: 46266 | L6: 46296 | M6: 46327 | N6: 46357 | O6: 46388 | P6: 46419 | Q6: 46447 | R6: 46478 | S6: 46508 | T6: 46539 | U6: 46569 | V6: 46600 | W6: 46631 | X6: 46661 | Y6: 46692 | Z6: 46722 | AA6: 46753 | AB6: 46784 | AC6: 46813 | AD6: 46844 | AE6: 46874 | AF6: 46905 | AG6: 46935 | AH6: 46966 | AI6: 46997 | AJ6: 47027 | AK6: 47058 | AL6: 47088 | AN6: Q1 | AO6: Q2 | AP6: Q3 | AQ6: Q4 | AR6: Q5 | AS6: Q6 | AT6: Q7 | AU6: Q8 | AV6: Q9 | AW6: Q10 | AX6: Q11 | AY6: Q12 | BA6: FY1 | BB6: FY2 | BC6: FY3
A7: Receivables, Payables & Deferred Revenue
A8: Accounts Receivable balance | B8: Revenue × DSO ÷ 30 | C8: ='Revenue'!C27*'Assumptions'!$F$61/30 -> 0 | D8: ='Revenue'!D27*'Assumptions'!$F$61/30 -> 0 | E8: ='Revenue'!E27*'Assumptions'!$F$61/30 -> 0 | F8: ='Revenue'!F27*'Assumptions'!$F$61/30 -> 0 | G8: ='Revenue'!G27*'Assumptions'!$F$61/30 -> 0 | H8: ='Revenue'!H27*'Assumptions'!$F$61/30 -> 0 | I8: ='Revenue'!I27*'Assumptions'!$F$61/30 -> 0 | J8: ='Revenue'!J27*'Assumptions'!$F$61/30 -> 0 | ... AL8: ='Revenue'!AL27*'Assumptions'!$F$61/30 -> 0 | AN8: =E8 -> 0 | AO8: =H8 -> 0 | AP8: =K8 -> 0 | AQ8: =N8 -> 0 | AR8: =Q8 -> 0 | AS8: =T8 -> 0 | AT8: =W8 -> 0 | AU8: =Z8 -> 0 | AV8: =AC8 -> 0 | AW8: =AF8 -> 0 | AX8: =AI8 -> 0 | AY8: =AL8 -> 0 | BA8: =N8 -> 0 | BB8: =Z8 -> 0 | BC8: =AL8 -> 0
A9: Accounts Payable balance | B9: (COGS + Opex) × DPO ÷ 30 | C9: =('COGS & GM'!C12+'Opex'!C24)*'Assumptions'!$F$62/30 -> 0 | D9: =('COGS & GM'!D12+'Opex'!D24)*'Assumptions'!$F$62/30 -> 0 | E9: =('COGS & GM'!E12+'Opex'!E24)*'Assumptions'!$F$62/30 -> 0 | F9: =('COGS & GM'!F12+'Opex'!F24)*'Assumptions'!$F$62/30 -> 0 | G9: =('COGS & GM'!G12+'Opex'!G24)*'Assumptions'!$F$62/30 -> 0 | H9: =('COGS & GM'!H12+'Opex'!H24)*'Assumptions'!$F$62/30 -> 0 | I9: =('COGS & GM'!I12+'Opex'!I24)*'Assumptions'!$F$62/30 -> 0 | J9: =('COGS & GM'!J12+'Opex'!J24)*'Assumptions'!$F$62/30 -> 0 | ... AL9: =('COGS & GM'!AL12+'Opex'!AL24)*'Assumptions'!$F$62/30 -> 0 | AN9: =E9 -> 0 | AO9: =H9 -> 0 | AP9: =K9 -> 0 | AQ9: =N9 -> 0 | AR9: =Q9 -> 0 | AS9: =T9 -> 0 | AT9: =W9 -> 0 | AU9: =Z9 -> 0 | AV9: =AC9 -> 0 | AW9: =AF9 -> 0 | AX9: =AI9 -> 0 | AY9: =AL9 -> 0 | BA9: =N9 -> 0 | BB9: =Z9 -> 0 | BC9: =AL9 -> 0
A10: Deferred Revenue balance | B10: Revenue × months collected in advance | C10: ='Revenue'!C27*'Assumptions'!$F$63 -> 0 | D10: ='Revenue'!D27*'Assumptions'!$F$63 -> 0 | E10: ='Revenue'!E27*'Assumptions'!$F$63 -> 0 | F10: ='Revenue'!F27*'Assumptions'!$F$63 -> 0 | G10: ='Revenue'!G27*'Assumptions'!$F$63 -> 0 | H10: ='Revenue'!H27*'Assumptions'!$F$63 -> 0 | I10: ='Revenue'!I27*'Assumptions'!$F$63 -> 0 | J10: ='Revenue'!J27*'Assumptions'!$F$63 -> 0 | ... AL10: ='Revenue'!AL27*'Assumptions'!$F$63 -> 0 | AN10: =E10 -> 0 | AO10: =H10 -> 0 | AP10: =K10 -> 0 | AQ10: =N10 -> 0 | AR10: =Q10 -> 0 | AS10: =T10 -> 0 | AT10: =W10 -> 0 | AU10: =Z10 -> 0 | AV10: =AC10 -> 0 | AW10: =AF10 -> 0 | AX10: =AI10 -> 0 | AY10: =AL10 -> 0 | BA10: =N10 -> 0 | BB10: =Z10 -> 0 | BC10: =AL10 -> 0
A11: Other Current Assets balance | B11: Revenue × assumption % (prepaid expenses, etc.) | C11: ='Revenue'!C27*'Assumptions'!$F$66 -> 0 | D11: ='Revenue'!D27*'Assumptions'!$F$66 -> 0 | E11: ='Revenue'!E27*'Assumptions'!$F$66 -> 0 | F11: ='Revenue'!F27*'Assumptions'!$F$66 -> 0 | G11: ='Revenue'!G27*'Assumptions'!$F$66 -> 0 | H11: ='Revenue'!H27*'Assumptions'!$F$66 -> 0 | I11: ='Revenue'!I27*'Assumptions'!$F$66 -> 0 | J11: ='Revenue'!J27*'Assumptions'!$F$66 -> 0 | ... AL11: ='Revenue'!AL27*'Assumptions'!$F$66 -> 0 | AN11: =E11 -> 0 | AO11: =H11 -> 0 | AP11: =K11 -> 0 | AQ11: =N11 -> 0 | AR11: =Q11 -> 0 | AS11: =T11 -> 0 | AT11: =W11 -> 0 | AU11: =Z11 -> 0 | AV11: =AC11 -> 0 | AW11: =AF11 -> 0 | AX11: =AI11 -> 0 | AY11: =AL11 -> 0 | BA11: =N11 -> 0 | BB11: =Z11 -> 0 | BC11: =AL11 -> 0
A12: Change in Accounts Receivable | C12: =C8 -> 0 | D12: =D8-C8 -> 0 | E12: =E8-D8 -> 0 | F12: =F8-E8 -> 0 | G12: =G8-F8 -> 0 | H12: =H8-G8 -> 0 | I12: =I8-H8 -> 0 | J12: =J8-I8 -> 0 | K12: =K8-J8 -> 0 | ... AL12: =AL8-AK8 -> 0 | AN12: =SUM(C12:E12) -> 0 | AO12: =SUM(F12:H12) -> 0 | AP12: =SUM(I12:K12) -> 0 | AQ12: =SUM(L12:N12) -> 0 | AR12: =SUM(O12:Q12) -> 0 | AS12: =SUM(R12:T12) -> 0 | AT12: =SUM(U12:W12) -> 0 | AU12: =SUM(X12:Z12) -> 0 | AV12: =SUM(AA12:AC12) -> 0 | AW12: =SUM(AD12:AF12) -> 0 | AX12: =SUM(AG12:AI12) -> 0 | AY12: =SUM(AJ12:AL12) -> 0 | BA12: =SUM(C12:N12) -> 0 | BB12: =SUM(O12:Z12) -> 0 | BC12: =SUM(AA12:AL12) -> 0
A13: Change in Accounts Payable | C13: =C9 -> 0 | D13: =D9-C9 -> 0 | E13: =E9-D9 -> 0 | F13: =F9-E9 -> 0 | G13: =G9-F9 -> 0 | H13: =H9-G9 -> 0 | I13: =I9-H9 -> 0 | J13: =J9-I9 -> 0 | K13: =K9-J9 -> 0 | ... AL13: =AL9-AK9 -> 0 | AN13: =SUM(C13:E13) -> 0 | AO13: =SUM(F13:H13) -> 0 | AP13: =SUM(I13:K13) -> 0 | AQ13: =SUM(L13:N13) -> 0 | AR13: =SUM(O13:Q13) -> 0 | AS13: =SUM(R13:T13) -> 0 | AT13: =SUM(U13:W13) -> 0 | AU13: =SUM(X13:Z13) -> 0 | AV13: =SUM(AA13:AC13) -> 0 | AW13: =SUM(AD13:AF13) -> 0 | AX13: =SUM(AG13:AI13) -> 0 | AY13: =SUM(AJ13:AL13) -> 0 | BA13: =SUM(C13:N13) -> 0 | BB13: =SUM(O13:Z13) -> 0 | BC13: =SUM(AA13:AL13) -> 0
A14: Change in Deferred Revenue | C14: =C10 -> 0 | D14: =D10-C10 -> 0 | E14: =E10-D10 -> 0 | F14: =F10-E10 -> 0 | G14: =G10-F10 -> 0 | H14: =H10-G10 -> 0 | I14: =I10-H10 -> 0 | J14: =J10-I10 -> 0 | K14: =K10-J10 -> 0 | ... AL14: =AL10-AK10 -> 0 | AN14: =SUM(C14:E14) -> 0 | AO14: =SUM(F14:H14) -> 0 | AP14: =SUM(I14:K14) -> 0 | AQ14: =SUM(L14:N14) -> 0 | AR14: =SUM(O14:Q14) -> 0 | AS14: =SUM(R14:T14) -> 0 | AT14: =SUM(U14:W14) -> 0 | AU14: =SUM(X14:Z14) -> 0 | AV14: =SUM(AA14:AC14) -> 0 | AW14: =SUM(AD14:AF14) -> 0 | AX14: =SUM(AG14:AI14) -> 0 | AY14: =SUM(AJ14:AL14) -> 0 | BA14: =SUM(C14:N14) -> 0 | BB14: =SUM(O14:Z14) -> 0 | BC14: =SUM(AA14:AL14) -> 0
