Workbook

Sheet Read Me
A1: Consumer Subscription — 3-Year Financial Model
A2: 36-month integrated financial model — Read Me
A4: Overview
A5: A 36-month, formula-driven financial model for a consumer subscription business. Start on the Assumptions tab: set Base / Upside / Downside inputs and pick a scenario. Every downstream tab recalculates automatically across acquisition, MAU, paid conversion, revenue, costs, burn, and runway.
A7: How this workbook is organized
A8: Assumptions -> Headcount -> Revenue -> COGS & GM -> Opex -> Working Capital -> P&L -> Balance Sheet -> Cash Flow -> Cash & Runway -> Scenarios -> Visuals -> Checks. Data flows strictly left-to-right through that order: change an assumption, and every downstream tab recalculates automatically (workbook calculation mode is Automatic).
A10: Formatting legend
A11: Blue text on light-blue fill = an input you can edit (Assumptions tab, and scenario selector).
A12: Black text on white = a live formula. Do not hard-code over these cells.
A13: Cells on a light-gray band = a value linked in from another tab.
A15: Color palette
A16: Purple (#7B68EE)
... A35: 36 monthly periods, plus quarterly (12) and annual (3) roll-up columns on each schedule tab. Workbook calculation is set to Automatic — Excel recalculates on every edit. Deterministic, seeded default assumptions are provided so the model is internally consistent out of the box; replace them with your own numbers on the Assumptions tab.

Sheet Assumptions
A1: Consumer Subscription — 3-Year Financial Model — Assumptions
A2: Plain-language inputs. Edit the Base / Upside / Downside columns only — everything else in this workbook is a formula.
A4: Scenario selector: | C4: Base | D4: << Pick Base / Upside / Downside. This one cell drives every formula in the model.
A6: Assumption | B6: Unit | C6: Base | D6: Upside | E6: Downside | F6: Active (used in model) | G6: Notes / definition
A7: Company & Financial
A8: Starting cash balance | B8: $ | C8: 2250000 | D8: 2250000 | E8: 2250000 | F8: =CHOOSE(MATCH('Assumptions'!$C$4,{"Base","Upside","Downside"},0),C8,D8,E8) -> 0 | G8: Cash on hand at the start of month 1.
A9: Starting paid-in capital | B9: $ | C9: 3000000 | D9: 3000000 | E9: 3000000 | F9: =CHOOSE(MATCH('Assumptions'!$C$4,{"Base","Upside","Downside"},0),C9,D9,E9) -> 0 | G9: Cumulative equity raised before the modeled period.
A10: Income tax rate | B10: % | C10: 0 | D10: 0 | E10: 0 | F10: =CHOOSE(MATCH('Assumptions'!$C$4,{"Base","Upside","Downside"},0),C10,D10,E10) -> 0 | G10: Applied only when Earnings Before Tax is positive; no NOL schedule modeled.
A12: Acquisition & Funnel
A13: Starting monthly active users (MAU) | B13: # | C13: 80000 | D13: 90000 | E13: 70000 | F13: =CHOOSE(MATCH('Assumptions'!$C$4,{"Base","Upside","Downside"},0),C13,D13,E13) -> 0 | G13: All active users at the start of month 1, including paid subscribers.
A14: Monthly active-user churn rate | B14: % | C14: 0.08 | D14: 0.06 | E14: 0.105 | F14: =CHOOSE(MATCH('Assumptions'!$C$4,{"Base","Upside","Downside"},0),C14,D14,E14) -> 0 | G14: Share of beginning MAU that goes inactive each month.
A15: Starting paid subscribers | B15: # | C15: 4000 | D15: 4500 | E15: 3500 | F15: =CHOOSE(MATCH('Assumptions'!$C$4,{"Base","Upside","Downside"},0),C15,D15,E15) -> 0 | G15: Active subscribers paying at the start of month 1.
A16: Paid-channel new signups, month 1 | B16: # | C16: 2500 | D16: 3000 | E16: 2000 | F16: =CHOOSE(MATCH('Assumptions'!$C$4,{"Base","Upside","Downside"},0),C16,D16,E16) -> 0 | G16: Users acquired from paid media in month 1.
A17: Paid-channel signups growth, month over month | B17: % | C17: 0.0635 | D17: 0.0943 | E17: 0.0147 | F17: =CHOOSE(MATCH('Assumptions'!$C$4,{"Base","Upside","Downside"},0),C17,D17,E17) -> 0 | G17: Compounding growth in paid-media signups each month.
A18: Paid-channel CAC per new signup | B18: $/user | C18: 28 | D18: 24 | E18: 34 | F18: =CHOOSE(MATCH('Assumptions'!$C$4,{"Base","Upside","Downside"},0),C18,D18,E18) -> 0 | G18: Blended paid-media acquisition cost per new user.
A19: Organic / viral new signups, month 1 | B19: # | C19: 3500 | D19: 4200 | E19: 2800 | F19: =CHOOSE(MATCH('Assumptions'!$C$4,{"Base","Upside","Downside"},0),C19,D19,E19) -> 0 | G19: Users arriving via word-of-mouth, SEO, app-store discovery, and product virality.
A20: Organic / viral signups growth, month over month | B20: % | C20: 0.0279 | D20: 0.0607 | E20: 0.012 | F20: =CHOOSE(MATCH('Assumptions'!$C$4,{"Base","Upside","Downside"},0),C20,D20,E20) -> 0 | G20: Organic signups often scale with awareness and product-market fit.
A21: Organic / viral CAC equivalent per signup | B21: $/user | C21: 4 | D21: 3 | E21: 5.5 | F21: =CHOOSE(MATCH('Assumptions'!$C$4,{"Base","Upside","Downside"},0),C21,D21,E21) -> 0 | G21: Represents community/content/program costs allocated per organic user.
A22: Influencer / referral new signups, month 1 | B22: # | C22: 1200 | D22: 1500 | E22: 900 | F22: =CHOOSE(MATCH('Assumptions'!$C$4,{"Base","Upside","Downside"},0),C22,D22,E22) -> 0 | G22: Users acquired from creators, affiliate partners, and referral loops.
A23: Influencer / referral signups growth, month over month | B23: % | C23: 0.0422 | D23: 0.0625 | E23: 0.0075 | F23: =CHOOSE(MATCH('Assumptions'!$C$4,{"Base","Upside","Downside"},0),C23,D23,E23) -> 0 | G23: Compounding growth in creator and referral-driven acquisition.
A24: Influencer / referral CAC per new signup | B24: $/user | C24: 16 | D24: 13 | E24: 20 | F24: =CHOOSE(MATCH('Assumptions'!$C$4,{"Base","Upside","Downside"},0),C24,D24,E24) -> 0 | G24: Creator fees, referral rewards, and affiliate payouts per acquired user.
A26: Retention & Monetization
A27: Free-to-paid conversion rate | B27: % | C27: 0.025 | D27: 0.032 | E27: 0.018 | F27: =CHOOSE(MATCH('Assumptions'!$C$4,{"Base","Upside","Downside"},0),C27,D27,E27) -> 0 | G27: Share of free MAU that converts to paid each month.
A28: Paid subscriber churn rate | B28: % | C28: 0.045 | D28: 0.032 | E28: 0.06 | F28: =CHOOSE(MATCH('Assumptions'!$C$4,{"Base","Upside","Downside"},0),C28,D28,E28) -> 0 | G28: Monthly churn of beginning paid subscribers.
A29: Plus plan price per subscriber | B29: $/mo | C29: 12 | D29: 13 | E29: 11 | F29: =CHOOSE(MATCH('Assumptions'!$C$4,{"Base","Upside","Downside"},0),C29,D29,E29) -> 0 | G29: Blended realized monthly price for the standard paid tier.
A30: Premium / family plan price per subscriber | B30: $/mo | C30: 24 | D30: 26 | E30: 22 | F30: =CHOOSE(MATCH('Assumptions'!$C$4,{"Base","Upside","Downside"},0),C30,D30,E30) -> 0 | G30: Higher-value tier with more seats/features.
A31: Premium-tier mix, month 1 | B31: % | C31: 0.18 | D31: 0.24 | E31: 0.12 | F31: =CHOOSE(MATCH('Assumptions'!$C$4,{"Base","Upside","Downside"},0),C31,D31,E31) -> 0 | G31: Share of paid subscribers on the higher-value plan at the start of the model.
A32: Premium-tier mix shift, month over month | B32: % | C32: 0.0045 | D32: 0.007 | E32: -0.0006 | F32: =CHOOSE(MATCH('Assumptions'!$C$4,{"Base","Upside","Downside"},0),C32,D32,E32) -> 0 | G32: Monthly change in premium-plan mix, capped inside the model.
A34: COGS & Platform Fees
A35: App-store / platform fee, % of revenue | B35: % | C35: 0.18 | D35: 0.15 | E35: 0.22 | F35: =CHOOSE(MATCH('Assumptions'!$C$4,{"Base","Upside","Downside"},0),C35,D35,E35) -> 0 | G35: Blended app-store take rate / merchant-of-record fee on subscription revenue.
A36: Payment processing fee, % of revenue | B36: % | C36: 0.03 | D36: 0.025 | E36: 0.035 | F36: =CHOOSE(MATCH('Assumptions'!$C$4,{"Base","Upside","Downside"},0),C36,D36,E36) -> 0 | G36: Card and payment-processor fees on direct-web billing.
A37: Hosting & infra cost per MAU | B37: $/MAU/mo | C37: 0.35 | D37: 0.3 | E37: 0.42 | F37: =CHOOSE(MATCH('Assumptions'!$C$4,{"Base","Upside","Downside"},0),C37,D37,E37) -> 0 | G37: Storage, delivery, and core application infrastructure per active user.
A38: AI inference / premium support cost per paid subscriber | B38: $/sub/mo | C38: 1.8 | D38: 1.5 | E38: 2.2 | F38: =CHOOSE(MATCH('Assumptions'!$C$4,{"Base","Upside","Downside"},0),C38,D38,E38) -> 0 | G38: Variable AI feature cost and premium support burden per active paid subscriber.
A40: Headcount — Support / Community Ops (COGS)
A41: Starting Support / Community Ops FTEs | B41: # | C41: 5 | D41: 5 | E41: 5 | F41: =CHOOSE(MATCH('Assumptions'!$C$4,{"Base","Upside","Downside"},0),C41,D41,E41) -> 0 | G41: Customer support, trust & safety, and community operations.
A42: Support / Community Ops net adds per quarter | B42: # | C42: 1 | D42: 1.5 | E42: 0.5 | F42: =CHOOSE(MATCH('Assumptions'!$C$4,{"Base","Upside","Downside"},0),C42,D42,E42) -> 0
A43: Support / Community Ops fully-loaded cost per FTE | B43: $/mo | C43: 7000 | D43: 7000 | E43: 7000 | F43: =CHOOSE(MATCH('Assumptions'!$C$4,{"Base","Upside","Downside"},0),C43,D43,E43) -> 0 | G43: Salary + benefits + payroll tax, monthly.
A45: Headcount — Growth / Marketing (Opex)
A46: Starting Growth / Marketing FTEs | B46: # | C46: 4 | D46: 4 | E46: 4 | F46: =CHOOSE(MATCH('Assumptions'!$C$4,{"Base","Upside","Downside"},0),C46,D46,E46) -> 0 | G46: Performance marketing, lifecycle CRM, and growth analytics.
A47: Growth / Marketing net adds per quarter | B47: # | C47: 1 | D47: 1.5 | E47: 0.5 | F47: =CHOOSE(MATCH('Assumptions'!$C$4,{"Base","Upside","Downside"},0),C47,D47,E47) -> 0
...

Sheet Headcount
A1: Consumer Subscription — 3-Year Financial Model — Headcount
A2: Fully-loaded FTE ramps by role — flows into COGS or Opex by classification.
A5: Line item | B5: Units / source | C5: Monthly (36 months) | AN5: Quarterly | BA5: Annual
C6: 46023 | D6: 46054 | E6: 46082 | F6: 46113 | G6: 46143 | H6: 46174 | I6: 46204 | J6: 46235 | K6: 46266 | L6: 46296 | M6: 46327 | N6: 46357 | O6: 46388 | P6: 46419 | Q6: 46447 | R6: 46478 | S6: 46508 | T6: 46539 | U6: 46569 | V6: 46600 | W6: 46631 | X6: 46661 | Y6: 46692 | Z6: 46722 | AA6: 46753 | AB6: 46784 | AC6: 46813 | AD6: 46844 | AE6: 46874 | AF6: 46905 | AG6: 46935 | AH6: 46966 | AI6: 46997 | AJ6: 47027 | AK6: 47058 | AL6: 47088 | AN6: Q1 | AO6: Q2 | AP6: Q3 | AQ6: Q4 | AR6: Q5 | AS6: Q6 | AT6: Q7 | AU6: Q8 | AV6: Q9 | AW6: Q10 | AX6: Q11 | AY6: Q12 | BA6: FY1 | BB6: FY2 | BC6: FY3
A7: Cost of Goods Sold headcount (COGS-classified)
A8: Support / Community Ops — headcount (FTE) | B8: Cost of Revenue · start + net adds/qtr ÷ 3 | C8: =ROUND('Assumptions'!$F$41,1) -> 0 | D8: =ROUND(C8+'Assumptions'!$F$42/3,1) -> 0 | E8: =ROUND(D8+'Assumptions'!$F$42/3,1) -> 0 | F8: =ROUND(E8+'Assumptions'!$F$42/3,1) -> 0 | G8: =ROUND(F8+'Assumptions'!$F$42/3,1) -> 0 | H8: =ROUND(G8+'Assumptions'!$F$42/3,1) -> 0 | I8: =ROUND(H8+'Assumptions'!$F$42/3,1) -> 0 | J8: =ROUND(I8+'Assumptions'!$F$42/3,1) -> 0 | K8: =ROUND(J8+'Assumptions'!$F$42/3,1) -> 0 | ... AL8: =ROUND(AK8+'Assumptions'!$F$42/3,1) -> 0 | AN8: =E8 -> 0 | AO8: =H8 -> 0 | AP8: =K8 -> 0 | AQ8: =N8 -> 0 | AR8: =Q8 -> 0 | AS8: =T8 -> 0 | AT8: =W8 -> 0 | AU8: =Z8 -> 0 | AV8: =AC8 -> 0 | AW8: =AF8 -> 0 | AX8: =AI8 -> 0 | AY8: =AL8 -> 0 | BA8: =N8 -> 0 | BB8: =Z8 -> 0 | BC8: =AL8 -> 0
A9: Support / Community Ops — fully-loaded cost | B9: Headcount × monthly fully-loaded cost/FTE | C9: =C8*'Assumptions'!$F$43 -> 0 | D9: =D8*'Assumptions'!$F$43 -> 0 | E9: =E8*'Assumptions'!$F$43 -> 0 | F9: =F8*'Assumptions'!$F$43 -> 0 | G9: =G8*'Assumptions'!$F$43 -> 0 | H9: =H8*'Assumptions'!$F$43 -> 0 | I9: =I8*'Assumptions'!$F$43 -> 0 | J9: =J8*'Assumptions'!$F$43 -> 0 | ... AL9: =AL8*'Assumptions'!$F$43 -> 0 | AN9: =SUM(C9:E9) -> 0 | AO9: =SUM(F9:H9) -> 0 | AP9: =SUM(I9:K9) -> 0 | AQ9: =SUM(L9:N9) -> 0 | AR9: =SUM(O9:Q9) -> 0 | AS9: =SUM(R9:T9) -> 0 | AT9: =SUM(U9:W9) -> 0 | AU9: =SUM(X9:Z9) -> 0 | AV9: =SUM(AA9:AC9) -> 0 | AW9: =SUM(AD9:AF9) -> 0 | AX9: =SUM(AG9:AI9) -> 0 | AY9: =SUM(AJ9:AL9) -> 0 | BA9: =SUM(C9:N9) -> 0 | BB9: =SUM(O9:Z9) -> 0 | BC9: =SUM(AA9:AL9) -> 0
A11: Operating expense headcount (Opex-classified)
A12: Growth / Marketing — headcount (FTE) | B12: Growth & Marketing · start + net adds/qtr ÷ 3 | C12: =ROUND('Assumptions'!$F$46,1) -> 0 | D12: =ROUND(C12+'Assumptions'!$F$47/3,1) -> 0 | E12: =ROUND(D12+'Assumptions'!$F$47/3,1) -> 0 | F12: =ROUND(E12+'Assumptions'!$F$47/3,1) -> 0 | G12: =ROUND(F12+'Assumptions'!$F$47/3,1) -> 0 | H12: =ROUND(G12+'Assumptions'!$F$47/3,1) -> 0 | I12: =ROUND(H12+'Assumptions'!$F$47/3,1) -> 0 | J12: =ROUND(I12+'Assumptions'!$F$47/3,1) -> 0 | K12: =ROUND(J12+'Assumptions'!$F$47/3,1) -> 0 | ... AL12: =ROUND(AK12+'Assumptions'!$F$47/3,1) -> 0 | AN12: =E12 -> 0 | AO12: =H12 -> 0 | AP12: =K12 -> 0 | AQ12: =N12 -> 0 | AR12: =Q12 -> 0 | AS12: =T12 -> 0 | AT12: =W12 -> 0 | AU12: =Z12 -> 0 | AV12: =AC12 -> 0 | AW12: =AF12 -> 0 | AX12: =AI12 -> 0 | AY12: =AL12 -> 0 | BA12: =N12 -> 0 | BB12: =Z12 -> 0 | BC12: =AL12 -> 0
A13: Growth / Marketing — fully-loaded cost | B13: Headcount × monthly fully-loaded cost/FTE | C13: =C12*'Assumptions'!$F$48 -> 0 | D13: =D12*'Assumptions'!$F$48 -> 0 | E13: =E12*'Assumptions'!$F$48 -> 0 | F13: =F12*'Assumptions'!$F$48 -> 0 | G13: =G12*'Assumptions'!$F$48 -> 0 | H13: =H12*'Assumptions'!$F$48 -> 0 | I13: =I12*'Assumptions'!$F$48 -> 0 | J13: =J12*'Assumptions'!$F$48 -> 0 | ... AL13: =AL12*'Assumptions'!$F$48 -> 0 | AN13: =SUM(C13:E13) -> 0 | AO13: =SUM(F13:H13) -> 0 | AP13: =SUM(I13:K13) -> 0 | AQ13: =SUM(L13:N13) -> 0 | AR13: =SUM(O13:Q13) -> 0 | AS13: =SUM(R13:T13) -> 0 | AT13: =SUM(U13:W13) -> 0 | AU13: =SUM(X13:Z13) -> 0 | AV13: =SUM(AA13:AC13) -> 0 | AW13: =SUM(AD13:AF13) -> 0 | AX13: =SUM(AG13:AI13) -> 0 | AY13: =SUM(AJ13:AL13) -> 0 | BA13: =SUM(C13:N13) -> 0 | BB13: =SUM(O13:Z13) -> 0 | BC13: =SUM(AA13:AL13) -> 0
A14: Product / Engineering — headcount (FTE) | B14: Product & Engineering · start + net adds/qtr ÷ 3 | C14: =ROUND('Assumptions'!$F$51,1) -> 0 | D14: =ROUND(C14+'Assumptions'!$F$52/3,1) -> 0 | E14: =ROUND(D14+'Assumptions'!$F$52/3,1) -> 0 | F14: =ROUND(E14+'Assumptions'!$F$52/3,1) -> 0 | G14: =ROUND(F14+'Assumptions'!$F$52/3,1) -> 0 | H14: =ROUND(G14+'Assumptions'!$F$52/3,1) -> 0 | I14: =ROUND(H14+'Assumptions'!$F$52/3,1) -> 0 | J14: =ROUND(I14+'Assumptions'!$F$52/3,1) -> 0 | K14: =ROUND(J14+'Assumptions'!$F$52/3,1) -> 0 | ... AL14: =ROUND(AK14+'Assumptions'!$F$52/3,1) -> 0 | AN14: =E14 -> 0 | AO14: =H14 -> 0 | AP14: =K14 -> 0 | AQ14: =N14 -> 0 | AR14: =Q14 -> 0 | AS14: =T14 -> 0 | AT14: =W14 -> 0 | AU14: =Z14 -> 0 | AV14: =AC14 -> 0 | AW14: =AF14 -> 0 | AX14: =AI14 -> 0 | AY14: =AL14 -> 0 | BA14: =N14 -> 0 | BB14: =Z14 -> 0 | BC14: =AL14 -> 0
A15: Product / Engineering — fully-loaded cost | B15: Headcount × monthly fully-loaded cost/FTE | C15: =C14*'Assumptions'!$F$53 -> 0 | D15: =D14*'Assumptions'!$F$53 -> 0 | E15: =E14*'Assumptions'!$F$53 -> 0 | F15: =F14*'Assumptions'!$F$53 -> 0 | G15: =G14*'Assumptions'!$F$53 -> 0 | H15: =H14*'Assumptions'!$F$53 -> 0 | I15: =I14*'Assumptions'!$F$53 -> 0 | J15: =J14*'Assumptions'!$F$53 -> 0 | ... AL15: =AL14*'Assumptions'!$F$53 -> 0 | AN15: =SUM(C15:E15) -> 0 | AO15: =SUM(F15:H15) -> 0 | AP15: =SUM(I15:K15) -> 0 | AQ15: =SUM(L15:N15) -> 0 | AR15: =SUM(O15:Q15) -> 0 | AS15: =SUM(R15:T15) -> 0 | AT15: =SUM(U15:W15) -> 0 | AU15: =SUM(X15:Z15) -> 0 | AV15: =SUM(AA15:AC15) -> 0 | AW15: =SUM(AD15:AF15) -> 0 | AX15: =SUM(AG15:AI15) -> 0 | AY15: =SUM(AJ15:AL15) -> 0 | BA15: =SUM(C15:N15) -> 0 | BB15: =SUM(O15:Z15) -> 0 | BC15: =SUM(AA15:AL15) -> 0
A16: G&A — headcount (FTE) | B16: General & Administrative · start + net adds/qtr ÷ 3 | C16: =ROUND('Assumptions'!$F$56,1) -> 0 | D16: =ROUND(C16+'Assumptions'!$F$57/3,1) -> 0 | E16: =ROUND(D16+'Assumptions'!$F$57/3,1) -> 0 | F16: =ROUND(E16+'Assumptions'!$F$57/3,1) -> 0 | G16: =ROUND(F16+'Assumptions'!$F$57/3,1) -> 0 | H16: =ROUND(G16+'Assumptions'!$F$57/3,1) -> 0 | I16: =ROUND(H16+'Assumptions'!$F$57/3,1) -> 0 | J16: =ROUND(I16+'Assumptions'!$F$57/3,1) -> 0 | K16: =ROUND(J16+'Assumptions'!$F$57/3,1) -> 0 | ... AL16: =ROUND(AK16+'Assumptions'!$F$57/3,1) -> 0 | AN16: =E16 -> 0 | AO16: =H16 -> 0 | AP16: =K16 -> 0 | AQ16: =N16 -> 0 | AR16: =Q16 -> 0 | AS16: =T16 -> 0 | AT16: =W16 -> 0 | AU16: =Z16 -> 0 | AV16: =AC16 -> 0 | AW16: =AF16 -> 0 | AX16: =AI16 -> 0 | AY16: =AL16 -> 0 | BA16: =N16 -> 0 | BB16: =Z16 -> 0 | BC16: =AL16 -> 0
A17: G&A — fully-loaded cost | B17: Headcount × monthly fully-loaded cost/FTE | C17: =C16*'Assumptions'!$F$58 -> 0 | D17: =D16*'Assumptions'!$F$58 -> 0 | E17: =E16*'Assumptions'!$F$58 -> 0 | F17: =F16*'Assumptions'!$F$58 -> 0 | G17: =G16*'Assumptions'!$F$58 -> 0 | H17: =H16*'Assumptions'!$F$58 -> 0 | I17: =I16*'Assumptions'!$F$58 -> 0 | J17: =J16*'Assumptions'!$F$58 -> 0 | ... AL17: =AL16*'Assumptions'!$F$58 -> 0 | AN17: =SUM(C17:E17) -> 0 | AO17: =SUM(F17:H17) -> 0 | AP17: =SUM(I17:K17) -> 0 | AQ17: =SUM(L17:N17) -> 0 | AR17: =SUM(O17:Q17) -> 0 | AS17: =SUM(R17:T17) -> 0 | AT17: =SUM(U17:W17) -> 0 | AU17: =SUM(X17:Z17) -> 0 | AV17: =SUM(AA17:AC17) -> 0 | AW17: =SUM(AD17:AF17) -> 0 | AX17: =SUM(AG17:AI17) -> 0 | AY17: =SUM(AJ17:AL17) -> 0 | BA17: =SUM(C17:N17) -> 0 | BB17: =SUM(O17:Z17) -> 0 | BC17: =SUM(AA17:AL17) -> 0
A19: Totals
A20: Total headcount (FTE) | B20: Sum of all roles | C20: =C8+C12+C14+C16 -> 0 | D20: =D8+D12+D14+D16 -> 0 | E20: =E8+E12+E14+E16 -> 0 | F20: =F8+F12+F14+F16 -> 0 | G20: =G8+G12+G14+G16 -> 0 | H20: =H8+H12+H14+H16 -> 0 | I20: =I8+I12+I14+I16 -> 0 | J20: =J8+J12+J14+J16 -> 0 | ... AL20: =AL8+AL12+AL14+AL16 -> 0 | AN20: =E20 -> 0 | AO20: =H20 -> 0 | AP20: =K20 -> 0 | AQ20: =N20 -> 0 | AR20: =Q20 -> 0 | AS20: =T20 -> 0 | AT20: =W20 -> 0 | AU20: =Z20 -> 0 | AV20: =AC20 -> 0 | AW20: =AF20 -> 0 | AX20: =AI20 -> 0 | AY20: =AL20 -> 0 | BA20: =N20 -> 0 | BB20: =Z20 -> 0 | BC20: =AL20 -> 0
A21: Total COGS-classified people cost | B21: Feeds COGS & GM tab | C21: =C9 -> 0 | D21: =D9 -> 0 | E21: =E9 -> 0 | F21: =F9 -> 0 | G21: =G9 -> 0 | H21: =H9 -> 0 | I21: =I9 -> 0 | J21: =J9 -> 0 | ... AL21: =AL9 -> 0 | AN21: =SUM(C21:E21) -> 0 | AO21: =SUM(F21:H21) -> 0 | AP21: =SUM(I21:K21) -> 0 | AQ21: =SUM(L21:N21) -> 0 | AR21: =SUM(O21:Q21) -> 0 | AS21: =SUM(R21:T21) -> 0 | AT21: =SUM(U21:W21) -> 0 | AU21: =SUM(X21:Z21) -> 0 | AV21: =SUM(AA21:AC21) -> 0 | AW21: =SUM(AD21:AF21) -> 0 | AX21: =SUM(AG21:AI21) -> 0 | AY21: =SUM(AJ21:AL21) -> 0 | BA21: =SUM(C21:N21) -> 0 | BB21: =SUM(O21:Z21) -> 0 | BC21: =SUM(AA21:AL21) -> 0
A22: Total Opex-classified people cost | B22: Feeds Opex tab | C22: =C13+C15+C17 -> 0 | D22: =D13+D15+D17 -> 0 | E22: =E13+E15+E17 -> 0 | F22: =F13+F15+F17 -> 0 | G22: =G13+G15+G17 -> 0 | H22: =H13+H15+H17 -> 0 | I22: =I13+I15+I17 -> 0 | J22: =J13+J15+J17 -> 0 | ... AL22: =AL13+AL15+AL17 -> 0 | AN22: =SUM(C22:E22) -> 0 | AO22: =SUM(F22:H22) -> 0 | AP22: =SUM(I22:K22) -> 0 | AQ22: =SUM(L22:N22) -> 0 | AR22: =SUM(O22:Q22) -> 0 | AS22: =SUM(R22:T22) -> 0 | AT22: =SUM(U22:W22) -> 0 | AU22: =SUM(X22:Z22) -> 0 | AV22: =SUM(AA22:AC22) -> 0 | AW22: =SUM(AD22:AF22) -> 0 | AX22: =SUM(AG22:AI22) -> 0 | AY22: =SUM(AJ22:AL22) -> 0 | BA22: =SUM(C22:N22) -> 0 | BB22: =SUM(O22:Z22) -> 0 | BC22: =SUM(AA22:AL22) -> 0
A23: General & Administrative people cost | C23: =C17 -> 0 | D23: =D17 -> 0 | E23: =E17 -> 0 | F23: =F17 -> 0 | G23: =G17 -> 0 | H23: =H17 -> 0 | I23: =I17 -> 0 | J23: =J17 -> 0 | ... AL23: =AL17 -> 0 | AN23: =SUM(C23:E23) -> 0 | AO23: =SUM(F23:H23) -> 0 | AP23: =SUM(I23:K23) -> 0 | AQ23: =SUM(L23:N23) -> 0 | AR23: =SUM(O23:Q23) -> 0 | AS23: =SUM(R23:T23) -> 0 | AT23: =SUM(U23:W23) -> 0 | AU23: =SUM(X23:Z23) -> 0 | AV23: =SUM(AA23:AC23) -> 0 | AW23: =SUM(AD23:AF23) -> 0 | AX23: =SUM(AG23:AI23) -> 0 | AY23: =SUM(AJ23:AL23) -> 0 | BA23: =SUM(C23:N23) -> 0 | BB23: =SUM(O23:Z23) -> 0 | BC23: =SUM(AA23:AL23) -> 0
A24: Growth & Marketing people cost | C24: =C13 -> 0 | D24: =D13 -> 0 | E24: =E13 -> 0 | F24: =F13 -> 0 | G24: =G13 -> 0 | H24: =H13 -> 0 | I24: =I13 -> 0 | J24: =J13 -> 0 | ... AL24: =AL13 -> 0 | AN24: =SUM(C24:E24) -> 0 | AO24: =SUM(F24:H24) -> 0 | AP24: =SUM(I24:K24) -> 0 | AQ24: =SUM(L24:N24) -> 0 | AR24: =SUM(O24:Q24) -> 0 | AS24: =SUM(R24:T24) -> 0 | AT24: =SUM(U24:W24) -> 0 | AU24: =SUM(X24:Z24) -> 0 | AV24: =SUM(AA24:AC24) -> 0 | AW24: =SUM(AD24:AF24) -> 0 | AX24: =SUM(AG24:AI24) -> 0 | AY24: =SUM(AJ24:AL24) -> 0 | BA24: =SUM(C24:N24) -> 0 | BB24: =SUM(O24:Z24) -> 0 | BC24: =SUM(AA24:AL24) -> 0
A25: Product & Engineering people cost | C25: =C15 -> 0 | D25: =D15 -> 0 | E25: =E15 -> 0 | F25: =F15 -> 0 | G25: =G15 -> 0 | H25: =H15 -> 0 | I25: =I15 -> 0 | J25: =J15 -> 0 | ... AL25: =AL15 -> 0 | AN25: =SUM(C25:E25) -> 0 | AO25: =SUM(F25:H25) -> 0 | AP25: =SUM(I25:K25) -> 0 | AQ25: =SUM(L25:N25) -> 0 | AR25: =SUM(O25:Q25) -> 0 | AS25: =SUM(R25:T25) -> 0 | AT25: =SUM(U25:W25) -> 0 | AU25: =SUM(X25:Z25) -> 0 | AV25: =SUM(AA25:AC25) -> 0 | AW25: =SUM(AD25:AF25) -> 0 | AX25: =SUM(AG25:AI25) -> 0 | AY25: =SUM(AJ25:AL25) -> 0 | BA25: =SUM(C25:N25) -> 0 | BB25: =SUM(O25:Z25) -> 0 | BC25: =SUM(AA25:AL25) -> 0

Sheet Revenue
A1: Consumer Subscription — 3-Year Financial Model — Revenue
A2: Channel acquisition -> MAU bridge -> free-to-paid conversion -> paid subscriber bridge -> blended ARPU.
A5: Line item | B5: Units / source | C5: Monthly (36 months) | AN5: Quarterly | BA5: Annual
C6: 46023 | D6: 46054 | E6: 46082 | F6: 46113 | G6: 46143 | H6: 46174 | I6: 46204 | J6: 46235 | K6: 46266 | L6: 46296 | M6: 46327 | N6: 46357 | O6: 46388 | P6: 46419 | Q6: 46447 | R6: 46478 | S6: 46508 | T6: 46539 | U6: 46569 | V6: 46600 | W6: 46631 | X6: 46661 | Y6: 46692 | Z6: 46722 | AA6: 46753 | AB6: 46784 | AC6: 46813 | AD6: 46844 | AE6: 46874 | AF6: 46905 | AG6: 46935 | AH6: 46966 | AI6: 46997 | AJ6: 47027 | AK6: 47058 | AL6: 47088 | AN6: Q1 | AO6: Q2 | AP6: Q3 | AQ6: Q4 | AR6: Q5 | AS6: Q6 | AT6: Q7 | AU6: Q8 | AV6: Q9 | AW6: Q10 | AX6: Q11 | AY6: Q12 | BA6: FY1 | BB6: FY2 | BC6: FY3
A7: Acquisition by Channel
A8: Paid new signups | B8: Monthly new users from this channel | C8: ='Assumptions'!$F$16 -> 0 | D8: =C8*(1+'Assumptions'!$F$17) -> 0 | E8: =D8*(1+'Assumptions'!$F$17) -> 0 | F8: =E8*(1+'Assumptions'!$F$17) -> 0 | G8: =F8*(1+'Assumptions'!$F$17) -> 0 | H8: =G8*(1+'Assumptions'!$F$17) -> 0 | I8: =H8*(1+'Assumptions'!$F$17) -> 0 | J8: =I8*(1+'Assumptions'!$F$17) -> 0 | K8: =J8*(1+'Assumptions'!$F$17) -> 0 | ... AL8: =AK8*(1+'Assumptions'!$F$17) -> 0 | AN8: =SUM(C8:E8) -> 0 | AO8: =SUM(F8:H8) -> 0 | AP8: =SUM(I8:K8) -> 0 | AQ8: =SUM(L8:N8) -> 0 | AR8: =SUM(O8:Q8) -> 0 | AS8: =SUM(R8:T8) -> 0 | AT8: =SUM(U8:W8) -> 0 | AU8: =SUM(X8:Z8) -> 0 | AV8: =SUM(AA8:AC8) -> 0 | AW8: =SUM(AD8:AF8) -> 0 | AX8: =SUM(AG8:AI8) -> 0 | AY8: =SUM(AJ8:AL8) -> 0 | BA8: =SUM(C8:N8) -> 0 | BB8: =SUM(O8:Z8) -> 0 | BC8: =SUM(AA8:AL8) -> 0
A9: Paid acquisition spend | B9: New signups × CAC / signup | C9: =C8*'Assumptions'!$F$18 -> 0 | D9: =D8*'Assumptions'!$F$18 -> 0 | E9: =E8*'Assumptions'!$F$18 -> 0 | F9: =F8*'Assumptions'!$F$18 -> 0 | G9: =G8*'Assumptions'!$F$18 -> 0 | H9: =H8*'Assumptions'!$F$18 -> 0 | I9: =I8*'Assumptions'!$F$18 -> 0 | J9: =J8*'Assumptions'!$F$18 -> 0 | ... AL9: =AL8*'Assumptions'!$F$18 -> 0 | AN9: =SUM(C9:E9) -> 0 | AO9: =SUM(F9:H9) -> 0 | AP9: =SUM(I9:K9) -> 0 | AQ9: =SUM(L9:N9) -> 0 | AR9: =SUM(O9:Q9) -> 0 | AS9: =SUM(R9:T9) -> 0 | AT9: =SUM(U9:W9) -> 0 | AU9: =SUM(X9:Z9) -> 0 | AV9: =SUM(AA9:AC9) -> 0 | AW9: =SUM(AD9:AF9) -> 0 | AX9: =SUM(AG9:AI9) -> 0 | AY9: =SUM(AJ9:AL9) -> 0 | BA9: =SUM(C9:N9) -> 0 | BB9: =SUM(O9:Z9) -> 0 | BC9: =SUM(AA9:AL9) -> 0
A10: Organic / Viral new signups | B10: Monthly new users from this channel | C10: ='Assumptions'!$F$19 -> 0 | D10: =C10*(1+'Assumptions'!$F$20) -> 0 | E10: =D10*(1+'Assumptions'!$F$20) -> 0 | F10: =E10*(1+'Assumptions'!$F$20) -> 0 | G10: =F10*(1+'Assumptions'!$F$20) -> 0 | H10: =G10*(1+'Assumptions'!$F$20) -> 0 | I10: =H10*(1+'Assumptions'!$F$20) -> 0 | J10: =I10*(1+'Assumptions'!$F$20) -> 0 | K10: =J10*(1+'Assumptions'!$F$20) -> 0 | ... AL10: =AK10*(1+'Assumptions'!$F$20) -> 0 | AN10: =SUM(C10:E10) -> 0 | AO10: =SUM(F10:H10) -> 0 | AP10: =SUM(I10:K10) -> 0 | AQ10: =SUM(L10:N10) -> 0 | AR10: =SUM(O10:Q10) -> 0 | AS10: =SUM(R10:T10) -> 0 | AT10: =SUM(U10:W10) -> 0 | AU10: =SUM(X10:Z10) -> 0 | AV10: =SUM(AA10:AC10) -> 0 | AW10: =SUM(AD10:AF10) -> 0 | AX10: =SUM(AG10:AI10) -> 0 | AY10: =SUM(AJ10:AL10) -> 0 | BA10: =SUM(C10:N10) -> 0 | BB10: =SUM(O10:Z10) -> 0 | BC10: =SUM(AA10:AL10) -> 0
A11: Organic / Viral acquisition spend | B11: New signups × CAC / signup | C11: =C10*'Assumptions'!$F$21 -> 0 | D11: =D10*'Assumptions'!$F$21 -> 0 | E11: =E10*'Assumptions'!$F$21 -> 0 | F11: =F10*'Assumptions'!$F$21 -> 0 | G11: =G10*'Assumptions'!$F$21 -> 0 | H11: =H10*'Assumptions'!$F$21 -> 0 | I11: =I10*'Assumptions'!$F$21 -> 0 | J11: =J10*'Assumptions'!$F$21 -> 0 | ... AL11: =AL10*'Assumptions'!$F$21 -> 0 | AN11: =SUM(C11:E11) -> 0 | AO11: =SUM(F11:H11) -> 0 | AP11: =SUM(I11:K11) -> 0 | AQ11: =SUM(L11:N11) -> 0 | AR11: =SUM(O11:Q11) -> 0 | AS11: =SUM(R11:T11) -> 0 | AT11: =SUM(U11:W11) -> 0 | AU11: =SUM(X11:Z11) -> 0 | AV11: =SUM(AA11:AC11) -> 0 | AW11: =SUM(AD11:AF11) -> 0 | AX11: =SUM(AG11:AI11) -> 0 | AY11: =SUM(AJ11:AL11) -> 0 | BA11: =SUM(C11:N11) -> 0 | BB11: =SUM(O11:Z11) -> 0 | BC11: =SUM(AA11:AL11) -> 0
A12: Influencer / Referral new signups | B12: Monthly new users from this channel | C12: ='Assumptions'!$F$22 -> 0 | D12: =C12*(1+'Assumptions'!$F$23) -> 0 | E12: =D12*(1+'Assumptions'!$F$23) -> 0 | F12: =E12*(1+'Assumptions'!$F$23) -> 0 | G12: =F12*(1+'Assumptions'!$F$23) -> 0 | H12: =G12*(1+'Assumptions'!$F$23) -> 0 | I12: =H12*(1+'Assumptions'!$F$23) -> 0 | J12: =I12*(1+'Assumptions'!$F$23) -> 0 | K12: =J12*(1+'Assumptions'!$F$23) -> 0 | ... AL12: =AK12*(1+'Assumptions'!$F$23) -> 0 | AN12: =SUM(C12:E12) -> 0 | AO12: =SUM(F12:H12) -> 0 | AP12: =SUM(I12:K12) -> 0 | AQ12: =SUM(L12:N12) -> 0 | AR12: =SUM(O12:Q12) -> 0 | AS12: =SUM(R12:T12) -> 0 | AT12: =SUM(U12:W12) -> 0 | AU12: =SUM(X12:Z12) -> 0 | AV12: =SUM(AA12:AC12) -> 0 | AW12: =SUM(AD12:AF12) -> 0 | AX12: =SUM(AG12:AI12) -> 0 | AY12: =SUM(AJ12:AL12) -> 0 | BA12: =SUM(C12:N12) -> 0 | BB12: =SUM(O12:Z12) -> 0 | BC12: =SUM(AA12:AL12) -> 0
A13: Influencer / Referral acquisition spend | B13: New signups × CAC / signup | C13: =C12*'Assumptions'!$F$24 -> 0 | D13: =D12*'Assumptions'!$F$24 -> 0 | E13: =E12*'Assumptions'!$F$24 -> 0 | F13: =F12*'Assumptions'!$F$24 -> 0 | G13: =G12*'Assumptions'!$F$24 -> 0 | H13: =H12*'Assumptions'!$F$24 -> 0 | I13: =I12*'Assumptions'!$F$24 -> 0 | J13: =J12*'Assumptions'!$F$24 -> 0 | ... AL13: =AL12*'Assumptions'!$F$24 -> 0 | AN13: =SUM(C13:E13) -> 0 | AO13: =SUM(F13:H13) -> 0 | AP13: =SUM(I13:K13) -> 0 | AQ13: =SUM(L13:N13) -> 0 | AR13: =SUM(O13:Q13) -> 0 | AS13: =SUM(R13:T13) -> 0 | AT13: =SUM(U13:W13) -> 0 | AU13: =SUM(X13:Z13) -> 0 | AV13: =SUM(AA13:AC13) -> 0 | AW13: =SUM(AD13:AF13) -> 0 | AX13: =SUM(AG13:AI13) -> 0 | AY13: =SUM(AJ13:AL13) -> 0 | BA13: =SUM(C13:N13) -> 0 | BB13: =SUM(O13:Z13) -> 0 | BC13: =SUM(AA13:AL13) -> 0
A14: Total new signups | B14: Sum of paid, organic / viral, and influencer / referral channels | C14: =C8+C10+C12 -> 0 | D14: =D8+D10+D12 -> 0 | E14: =E8+E10+E12 -> 0 | F14: =F8+F10+F12 -> 0 | G14: =G8+G10+G12 -> 0 | H14: =H8+H10+H12 -> 0 | I14: =I8+I10+I12 -> 0 | J14: =J8+J10+J12 -> 0 | ... AL14: =AL8+AL10+AL12 -> 0 | AN14: =SUM(C14:E14) -> 0 | AO14: =SUM(F14:H14) -> 0 | AP14: =SUM(I14:K14) -> 0 | AQ14: =SUM(L14:N14) -> 0 | AR14: =SUM(O14:Q14) -> 0 | AS14: =SUM(R14:T14) -> 0 | AT14: =SUM(U14:W14) -> 0 | AU14: =SUM(X14:Z14) -> 0 | AV14: =SUM(AA14:AC14) -> 0 | AW14: =SUM(AD14:AF14) -> 0 | AX14: =SUM(AG14:AI14) -> 0 | AY14: =SUM(AJ14:AL14) -> 0 | BA14: =SUM(C14:N14) -> 0 | BB14: =SUM(O14:Z14) -> 0 | BC14: =SUM(AA14:AL14) -> 0
A15: Total acquisition spend | B15: Channel acquisition spend that flows into Growth & Marketing Opex | C15: =C9+C11+C13 -> 0 | D15: =D9+D11+D13 -> 0 | E15: =E9+E11+E13 -> 0 | F15: =F9+F11+F13 -> 0 | G15: =G9+G11+G13 -> 0 | H15: =H9+H11+H13 -> 0 | I15: =I9+I11+I13 -> 0 | J15: =J9+J11+J13 -> 0 | ... AL15: =AL9+AL11+AL13 -> 0 | AN15: =SUM(C15:E15) -> 0 | AO15: =SUM(F15:H15) -> 0 | AP15: =SUM(I15:K15) -> 0 | AQ15: =SUM(L15:N15) -> 0 | AR15: =SUM(O15:Q15) -> 0 | AS15: =SUM(R15:T15) -> 0 | AT15: =SUM(U15:W15) -> 0 | AU15: =SUM(X15:Z15) -> 0 | AV15: =SUM(AA15:AC15) -> 0 | AW15: =SUM(AD15:AF15) -> 0 | AX15: =SUM(AG15:AI15) -> 0 | AY15: =SUM(AJ15:AL15) -> 0 | BA15: =SUM(C15:N15) -> 0 | BB15: =SUM(O15:Z15) -> 0 | BC15: =SUM(AA15:AL15) -> 0
A17: MAU & Paid Subscriber Funnel
A18: Beginning MAU | B18: Prior month ending MAU (or starting MAU in month 1) | C18: ='Assumptions'!$F$13 -> 0 | D18: =C21 -> 0 | E18: =D21 -> 0 | F18: =E21 -> 0 | G18: =F21 -> 0 | H18: =G21 -> 0 | I18: =H21 -> 0 | J18: =I21 -> 0 | K18: =J21 -> 0 | ... AL18: =AK21 -> 0 | AN18: =E18 -> 0 | AO18: =H18 -> 0 | AP18: =K18 -> 0 | AQ18: =N18 -> 0 | AR18: =Q18 -> 0 | AS18: =T18 -> 0 | AT18: =W18 -> 0 | AU18: =Z18 -> 0 | AV18: =AC18 -> 0 | AW18: =AF18 -> 0 | AX18: =AI18 -> 0 | AY18: =AL18 -> 0 | BA18: =N18 -> 0 | BB18: =Z18 -> 0 | BC18: =AL18 -> 0
A19: New signups | B19: Linked from channel acquisition above | C19: =C14 -> 0 | D19: =D14 -> 0 | E19: =E14 -> 0 | F19: =F14 -> 0 | G19: =G14 -> 0 | H19: =H14 -> 0 | I19: =I14 -> 0 | J19: =J14 -> 0 | ... AL19: =AL14 -> 0 | AN19: =SUM(C19:E19) -> 0 | AO19: =SUM(F19:H19) -> 0 | AP19: =SUM(I19:K19) -> 0 | AQ19: =SUM(L19:N19) -> 0 | AR19: =SUM(O19:Q19) -> 0 | AS19: =SUM(R19:T19) -> 0 | AT19: =SUM(U19:W19) -> 0 | AU19: =SUM(X19:Z19) -> 0 | AV19: =SUM(AA19:AC19) -> 0 | AW19: =SUM(AD19:AF19) -> 0 | AX19: =SUM(AG19:AI19) -> 0 | AY19: =SUM(AJ19:AL19) -> 0 | BA19: =SUM(C19:N19) -> 0 | BB19: =SUM(O19:Z19) -> 0 | BC19: =SUM(AA19:AL19) -> 0
A20: Churned / inactive MAU | B20: Beginning MAU × active-user churn rate | C20: =-C18*'Assumptions'!$F$14 -> 0 | D20: =-D18*'Assumptions'!$F$14 -> 0 | E20: =-E18*'Assumptions'!$F$14 -> 0 | F20: =-F18*'Assumptions'!$F$14 -> 0 | G20: =-G18*'Assumptions'!$F$14 -> 0 | H20: =-H18*'Assumptions'!$F$14 -> 0 | I20: =-I18*'Assumptions'!$F$14 -> 0 | J20: =-J18*'Assumptions'!$F$14 -> 0 | ... AL20: =-AL18*'Assumptions'!$F$14 -> 0 | AN20: =SUM(C20:E20) -> 0 | AO20: =SUM(F20:H20) -> 0 | AP20: =SUM(I20:K20) -> 0 | AQ20: =SUM(L20:N20) -> 0 | AR20: =SUM(O20:Q20) -> 0 | AS20: =SUM(R20:T20) -> 0 | AT20: =SUM(U20:W20) -> 0 | AU20: =SUM(X20:Z20) -> 0 | AV20: =SUM(AA20:AC20) -> 0 | AW20: =SUM(AD20:AF20) -> 0 | AX20: =SUM(AG20:AI20) -> 0 | AY20: =SUM(AJ20:AL20) -> 0 | BA20: =SUM(C20:N20) -> 0 | BB20: =SUM(O20:Z20) -> 0 | BC20: =SUM(AA20:AL20) -> 0
A21: Ending MAU | B21: Beginning MAU + new signups − MAU churn | C21: =C18+C19+C20 -> 0 | D21: =D18+D19+D20 -> 0 | E21: =E18+E19+E20 -> 0 | F21: =F18+F19+F20 -> 0 | G21: =G18+G19+G20 -> 0 | H21: =H18+H19+H20 -> 0 | I21: =I18+I19+I20 -> 0 | J21: =J18+J19+J20 -> 0 | ... AL21: =AL18+AL19+AL20 -> 0 | AN21: =E21 -> 0 | AO21: =H21 -> 0 | AP21: =K21 -> 0 | AQ21: =N21 -> 0 | AR21: =Q21 -> 0 | AS21: =T21 -> 0 | AT21: =W21 -> 0 | AU21: =Z21 -> 0 | AV21: =AC21 -> 0 | AW21: =AF21 -> 0 | AX21: =AI21 -> 0 | AY21: =AL21 -> 0 | BA21: =N21 -> 0 | BB21: =Z21 -> 0 | BC21: =AL21 -> 0
A22: Beginning paid subscribers | B22: Prior month ending paid subscribers | C22: ='Assumptions'!$F$15 -> 0 | D22: =C28 -> 0 | E22: =D28 -> 0 | F22: =E28 -> 0 | G22: =F28 -> 0 | H22: =G28 -> 0 | I22: =H28 -> 0 | J22: =I28 -> 0 | K22: =J28 -> 0 | ... AL22: =AK28 -> 0 | AN22: =E22 -> 0 | AO22: =H22 -> 0 | AP22: =K22 -> 0 | AQ22: =N22 -> 0 | AR22: =Q22 -> 0 | AS22: =T22 -> 0 | AT22: =W22 -> 0 | AU22: =Z22 -> 0 | AV22: =AC22 -> 0 | AW22: =AF22 -> 0 | AX22: =AI22 -> 0 | AY22: =AL22 -> 0 | BA22: =N22 -> 0 | BB22: =Z22 -> 0 | BC22: =AL22 -> 0
A23: Churned paid subscribers | B23: Beginning paid subscribers × paid churn | C23: =-C22*'Assumptions'!$F$28 -> 0 | D23: =-D22*'Assumptions'!$F$28 -> 0 | E23: =-E22*'Assumptions'!$F$28 -> 0 | F23: =-F22*'Assumptions'!$F$28 -> 0 | G23: =-G22*'Assumptions'!$F$28 -> 0 | H23: =-H22*'Assumptions'!$F$28 -> 0 | I23: =-I22*'Assumptions'!$F$28 -> 0 | J23: =-J22*'Assumptions'!$F$28 -> 0 | ... AL23: =-AL22*'Assumptions'!$F$28 -> 0 | AN23: =SUM(C23:E23) -> 0 | AO23: =SUM(F23:H23) -> 0 | AP23: =SUM(I23:K23) -> 0 | AQ23: =SUM(L23:N23) -> 0 | AR23: =SUM(O23:Q23) -> 0 | AS23: =SUM(R23:T23) -> 0 | AT23: =SUM(U23:W23) -> 0 | AU23: =SUM(X23:Z23) -> 0 | AV23: =SUM(AA23:AC23) -> 0 | AW23: =SUM(AD23:AF23) -> 0 | AX23: =SUM(AG23:AI23) -> 0 | AY23: =SUM(AJ23:AL23) -> 0 | BA23: =SUM(C23:N23) -> 0 | BB23: =SUM(O23:Z23) -> 0 | BC23: =SUM(AA23:AL23) -> 0
A24: Retained paid before new adds | B24: Beginning paid subscribers net of subscriber churn | C24: =C22+C23 -> 0 | D24: =D22+D23 -> 0 | E24: =E22+E23 -> 0 | F24: =F22+F23 -> 0 | G24: =G22+G23 -> 0 | H24: =H22+H23 -> 0 | I24: =I22+I23 -> 0 | J24: =J22+J23 -> 0 | ... AL24: =AL22+AL23 -> 0 | AN24: =E24 -> 0 | AO24: =H24 -> 0 | AP24: =K24 -> 0 | AQ24: =N24 -> 0 | AR24: =Q24 -> 0 | AS24: =T24 -> 0 | AT24: =W24 -> 0 | AU24: =Z24 -> 0 | AV24: =AC24 -> 0 | AW24: =AF24 -> 0 | AX24: =AI24 -> 0 | AY24: =AL24 -> 0 | BA24: =N24 -> 0 | BB24: =Z24 -> 0 | BC24: =AL24 -> 0
A25: Free MAU available to convert | B25: Ending MAU less retained paid subscribers | C25: =MAX(0,C21-C24) -> 0 | D25: =MAX(0,D21-D24) -> 0 | E25: =MAX(0,E21-E24) -> 0 | F25: =MAX(0,F21-F24) -> 0 | G25: =MAX(0,G21-G24) -> 0 | H25: =MAX(0,H21-H24) -> 0 | I25: =MAX(0,I21-I24) -> 0 | J25: =MAX(0,J21-J24) -> 0 | ... AL25: =MAX(0,AL21-AL24) -> 0 | AN25: =E25 -> 0 | AO25: =H25 -> 0 | AP25: =K25 -> 0 | AQ25: =N25 -> 0 | AR25: =Q25 -> 0 | AS25: =T25 -> 0 | AT25: =W25 -> 0 | AU25: =Z25 -> 0 | AV25: =AC25 -> 0 | AW25: =AF25 -> 0 | AX25: =AI25 -> 0 | AY25: =AL25 -> 0 | BA25: =N25 -> 0 | BB25: =Z25 -> 0 | BC25: =AL25 -> 0
A26: Free-to-paid conversion % | B26: Monthly free-user conversion assumption | C26: ='Assumptions'!$F$27 -> 0 | D26: ='Assumptions'!$F$27 -> 0 | E26: ='Assumptions'!$F$27 -> 0 | F26: ='Assumptions'!$F$27 -> 0 | G26: ='Assumptions'!$F$27 -> 0 | H26: ='Assumptions'!$F$27 -> 0 | I26: ='Assumptions'!$F$27 -> 0 | J26: ='Assumptions'!$F$27 -> 0 | ... AL26: ='Assumptions'!$F$27 -> 0 | AN26: =AVERAGE(C26:E26) -> 0 | AO26: =AVERAGE(F26:H26) -> 0 | AP26: =AVERAGE(I26:K26) -> 0 | AQ26: =AVERAGE(L26:N26) -> 0 | AR26: =AVERAGE(O26:Q26) -> 0 | AS26: =AVERAGE(R26:T26) -> 0 | AT26: =AVERAGE(U26:W26) -> 0 | AU26: =AVERAGE(X26:Z26) -> 0 | AV26: =AVERAGE(AA26:AC26) -> 0 | AW26: =AVERAGE(AD26:AF26) -> 0 | AX26: =AVERAGE(AG26:AI26) -> 0 | AY26: =AVERAGE(AJ26:AL26) -> 0 | BA26: =AVERAGE(C26:N26) -> 0 | BB26: =AVERAGE(O26:Z26) -> 0 | BC26: =AVERAGE(AA26:AL26) -> 0
A27: New paid adds | B27: Free MAU pool × conversion % | C27: =C25*C26 -> 0 | D27: =D25*D26 -> 0 | E27: =E25*E26 -> 0 | F27: =F25*F26 -> 0 | G27: =G25*G26 -> 0 | H27: =H25*H26 -> 0 | I27: =I25*I26 -> 0 | J27: =J25*J26 -> 0 | ... AL27: =AL25*AL26 -> 0 | AN27: =SUM(C27:E27) -> 0 | AO27: =SUM(F27:H27) -> 0 | AP27: =SUM(I27:K27) -> 0 | AQ27: =SUM(L27:N27) -> 0 | AR27: =SUM(O27:Q27) -> 0 | AS27: =SUM(R27:T27) -> 0 | AT27: =SUM(U27:W27) -> 0 | AU27: =SUM(X27:Z27) -> 0 | AV27: =SUM(AA27:AC27) -> 0 | AW27: =SUM(AD27:AF27) -> 0 | AX27: =SUM(AG27:AI27) -> 0 | AY27: =SUM(AJ27:AL27) -> 0 | BA27: =SUM(C27:N27) -> 0 | BB27: =SUM(O27:Z27) -> 0 | BC27: =SUM(AA27:AL27) -> 0
A28: Ending paid subscribers | B28: Retained paid subscribers + new paid adds | C28: =C24+C27 -> 0 | D28: =D24+D27 -> 0 | E28: =E24+E27 -> 0 | F28: =F24+F27 -> 0 | G28: =G24+G27 -> 0 | H28: =H24+H27 -> 0 | I28: =I24+I27 -> 0 | J28: =J24+J27 -> 0 | ... AL28: =AL24+AL27 -> 0 | AN28: =E28 -> 0 | AO28: =H28 -> 0 | AP28: =K28 -> 0 | AQ28: =N28 -> 0 | AR28: =Q28 -> 0 | AS28: =T28 -> 0 | AT28: =W28 -> 0 | AU28: =Z28 -> 0 | AV28: =AC28 -> 0 | AW28: =AF28 -> 0 | AX28: =AI28 -> 0 | AY28: =AL28 -> 0 | BA28: =N28 -> 0 | BB28: =Z28 -> 0 | BC28: =AL28 -> 0
A30: Plans, ARPU & Revenue
A31: Premium-tier subscriber mix | B31: Higher-value plan mix, capped inside the model | C31: ='Assumptions'!$F$31 -> 0 | D31: =MIN(0.50,MAX(0.05,C31+'Assumptions'!$F$32)) -> 0 | E31: =MIN(0.50,MAX(0.05,D31+'Assumptions'!$F$32)) -> 0 | F31: =MIN(0.50,MAX(0.05,E31+'Assumptions'!$F$32)) -> 0 | G31: =MIN(0.50,MAX(0.05,F31+'Assumptions'!$F$32)) -> 0 | H31: =MIN(0.50,MAX(0.05,G31+'Assumptions'!$F$32)) -> 0 | I31: =MIN(0.50,MAX(0.05,H31+'Assumptions'!$F$32)) -> 0 | J31: =MIN(0.50,MAX(0.05,I31+'Assumptions'!$F$32)) -> 0 | K31: =MIN(0.50,MAX(0.05,J31+'Assumptions'!$F$32)) -> 0 | ... AL31: =MIN(0.50,MAX(0.05,AK31+'Assumptions'!$F$32)) -> 0 | AN31: =AVERAGE(C31:E31) -> 0 | AO31: =AVERAGE(F31:H31) -> 0 | AP31: =AVERAGE(I31:K31) -> 0 | AQ31: =AVERAGE(L31:N31) -> 0 | AR31: =AVERAGE(O31:Q31) -> 0 | AS31: =AVERAGE(R31:T31) -> 0 | AT31: =AVERAGE(U31:W31) -> 0 | AU31: =AVERAGE(X31:Z31) -> 0 | AV31: =AVERAGE(AA31:AC31) -> 0 | AW31: =AVERAGE(AD31:AF31) -> 0 | AX31: =AVERAGE(AG31:AI31) -> 0 | AY31: =AVERAGE(AJ31:AL31) -> 0 | BA31: =AVERAGE(C31:N31) -> 0 | BB31: =AVERAGE(O31:Z31) -> 0 | BC31: =AVERAGE(AA31:AL31) -> 0
A32: Blended ARPU | B32: Weighted average of standard and premium plan pricing | C32: ='Assumptions'!$F$29*(1-C31)+'Assumptions'!$F$30*C31 -> 0 | D32: ='Assumptions'!$F$29*(1-D31)+'Assumptions'!$F$30*D31 -> 0 | E32: ='Assumptions'!$F$29*(1-E31)+'Assumptions'!$F$30*E31 -> 0 | F32: ='Assumptions'!$F$29*(1-F31)+'Assumptions'!$F$30*F31 -> 0 | G32: ='Assumptions'!$F$29*(1-G31)+'Assumptions'!$F$30*G31 -> 0 | H32: ='Assumptions'!$F$29*(1-H31)+'Assumptions'!$F$30*H31 -> 0 | I32: ='Assumptions'!$F$29*(1-I31)+'Assumptions'!$F$30*I31 -> 0 | J32: ='Assumptions'!$F$29*(1-J31)+'Assumptions'!$F$30*J31 -> 0 | ... AL32: ='Assumptions'!$F$29*(1-AL31)+'Assumptions'!$F$30*AL31 -> 0 | AN32: =AVERAGE(C32:E32) -> 0 | AO32: =AVERAGE(F32:H32) -> 0 | AP32: =AVERAGE(I32:K32) -> 0 | AQ32: =AVERAGE(L32:N32) -> 0 | AR32: =AVERAGE(O32:Q32) -> 0 | AS32: =AVERAGE(R32:T32) -> 0 | AT32: =AVERAGE(U32:W32) -> 0 | AU32: =AVERAGE(X32:Z32) -> 0 | AV32: =AVERAGE(AA32:AC32) -> 0 | AW32: =AVERAGE(AD32:AF32) -> 0 | AX32: =AVERAGE(AG32:AI32) -> 0 | AY32: =AVERAGE(AJ32:AL32) -> 0 | BA32: =AVERAGE(C32:N32) -> 0 | BB32: =AVERAGE(O32:Z32) -> 0 | BC32: =AVERAGE(AA32:AL32) -> 0
A33: Subscription revenue | B33: Ending paid subscribers × blended ARPU | C33: =C28*C32 -> 0 | D33: =D28*D32 -> 0 | E33: =E28*E32 -> 0 | F33: =F28*F32 -> 0 | G33: =G28*G32 -> 0 | H33: =H28*H32 -> 0 | I33: =I28*I32 -> 0 | J33: =J28*J32 -> 0 | ... AL33: =AL28*AL32 -> 0 | AN33: =SUM(C33:E33) -> 0 | AO33: =SUM(F33:H33) -> 0 | AP33: =SUM(I33:K33) -> 0 | AQ33: =SUM(L33:N33) -> 0 | AR33: =SUM(O33:Q33) -> 0 | AS33: =SUM(R33:T33) -> 0 | AT33: =SUM(U33:W33) -> 0 | AU33: =SUM(X33:Z33) -> 0 | AV33: =SUM(AA33:AC33) -> 0 | AW33: =SUM(AD33:AF33) -> 0 | AX33: =SUM(AG33:AI33) -> 0 | AY33: =SUM(AJ33:AL33) -> 0 | BA33: =SUM(C33:N33) -> 0 | BB33: =SUM(O33:Z33) -> 0 | BC33: =SUM(AA33:AL33) -> 0
A34: Revenue run-rate (monthly revenue x 12) | B34: Illustrative ARR-equivalent for a monthly consumer subscription business | C34: =C33*12 -> 0 | D34: =D33*12 -> 0 | E34: =E33*12 -> 0 | F34: =F33*12 -> 0 | G34: =G33*12 -> 0 | H34: =H33*12 -> 0 | I34: =I33*12 -> 0 | J34: =J33*12 -> 0 | ... AL34: =AL33*12 -> 0 | AN34: =E34 -> 0 | AO34: =H34 -> 0 | AP34: =K34 -> 0 | AQ34: =N34 -> 0 | AR34: =Q34 -> 0 | AS34: =T34 -> 0 | AT34: =W34 -> 0 | AU34: =Z34 -> 0 | AV34: =AC34 -> 0 | AW34: =AF34 -> 0 | AX34: =AI34 -> 0 | AY34: =AL34 -> 0 | BA34: =N34 -> 0 | BB34: =Z34 -> 0 | BC34: =AL34 -> 0
A35: Total Revenue | B35: Subscription revenue only; no ads or IAP modeled | C35: =C33 -> 0 | D35: =D33 -> 0 | E35: =E33 -> 0 | F35: =F33 -> 0 | G35: =G33 -> 0 | H35: =H33 -> 0 | I35: =I33 -> 0 | J35: =J33 -> 0 | ... AL35: =AL33 -> 0 | AN35: =SUM(C35:E35) -> 0 | AO35: =SUM(F35:H35) -> 0 | AP35: =SUM(I35:K35) -> 0 | AQ35: =SUM(L35:N35) -> 0 | AR35: =SUM(O35:Q35) -> 0 | AS35: =SUM(R35:T35) -> 0 | AT35: =SUM(U35:W35) -> 0 | AU35: =SUM(X35:Z35) -> 0 | AV35: =SUM(AA35:AC35) -> 0 | AW35: =SUM(AD35:AF35) -> 0 | AX35: =SUM(AG35:AI35) -> 0 | AY35: =SUM(AJ35:AL35) -> 0 | BA35: =SUM(C35:N35) -> 0 | BB35: =SUM(O35:Z35) -> 0 | BC35: =SUM(AA35:AL35) -> 0
A37: Consumer Subscription KPIs
A38: MAU growth (month over month) | C38: =IFERROR(C21/C18-1,0) -> 0 | D38: =IFERROR(D21/D18-1,0) -> 0 | E38: =IFERROR(E21/E18-1,0) -> 0 | F38: =IFERROR(F21/F18-1,0) -> 0 | G38: =IFERROR(G21/G18-1,0) -> 0 | H38: =IFERROR(H21/H18-1,0) -> 0 | I38: =IFERROR(I21/I18-1,0) -> 0 | J38: =IFERROR(J21/J18-1,0) -> 0 | ... AL38: =IFERROR(AL21/AL18-1,0) -> 0 | AN38: =AVERAGE(C38:E38) -> 0 | AO38: =AVERAGE(F38:H38) -> 0 | AP38: =AVERAGE(I38:K38) -> 0 | AQ38: =AVERAGE(L38:N38) -> 0 | AR38: =AVERAGE(O38:Q38) -> 0 | AS38: =AVERAGE(R38:T38) -> 0 | AT38: =AVERAGE(U38:W38) -> 0 | AU38: =AVERAGE(X38:Z38) -> 0 | AV38: =AVERAGE(AA38:AC38) -> 0 | AW38: =AVERAGE(AD38:AF38) -> 0 | AX38: =AVERAGE(AG38:AI38) -> 0 | AY38: =AVERAGE(AJ38:AL38) -> 0 | BA38: =AVERAGE(C38:N38) -> 0 | BB38: =AVERAGE(O38:Z38) -> 0 | BC38: =AVERAGE(AA38:AL38) -> 0
A39: Paid subscribers as % of MAU | C39: =IFERROR(C28/C21,0) -> 0 | D39: =IFERROR(D28/D21,0) -> 0 | E39: =IFERROR(E28/E21,0) -> 0 | F39: =IFERROR(F28/F21,0) -> 0 | G39: =IFERROR(G28/G21,0) -> 0 | H39: =IFERROR(H28/H21,0) -> 0 | I39: =IFERROR(I28/I21,0) -> 0 | J39: =IFERROR(J28/J21,0) -> 0 | ... AL39: =IFERROR(AL28/AL21,0) -> 0 | AN39: =AVERAGE(C39:E39) -> 0 | AO39: =AVERAGE(F39:H39) -> 0 | AP39: =AVERAGE(I39:K39) -> 0 | AQ39: =AVERAGE(L39:N39) -> 0 | AR39: =AVERAGE(O39:Q39) -> 0 | AS39: =AVERAGE(R39:T39) -> 0 | AT39: =AVERAGE(U39:W39) -> 0 | AU39: =AVERAGE(X39:Z39) -> 0 | AV39: =AVERAGE(AA39:AC39) -> 0 | AW39: =AVERAGE(AD39:AF39) -> 0 | AX39: =AVERAGE(AG39:AI39) -> 0 | AY39: =AVERAGE(AJ39:AL39) -> 0 | BA39: =AVERAGE(C39:N39) -> 0 | BB39: =AVERAGE(O39:Z39) -> 0 | BC39: =AVERAGE(AA39:AL39) -> 0
A40: Free-to-paid conversion % | C40: =IFERROR(C27/C25,0) -> 0 | D40: =IFERROR(D27/D25,0) -> 0 | E40: =IFERROR(E27/E25,0) -> 0 | F40: =IFERROR(F27/F25,0) -> 0 | G40: =IFERROR(G27/G25,0) -> 0 | H40: =IFERROR(H27/H25,0) -> 0 | I40: =IFERROR(I27/I25,0) -> 0 | J40: =IFERROR(J27/J25,0) -> 0 | ... AL40: =IFERROR(AL27/AL25,0) -> 0 | AN40: =AVERAGE(C40:E40) -> 0 | AO40: =AVERAGE(F40:H40) -> 0 | AP40: =AVERAGE(I40:K40) -> 0 | AQ40: =AVERAGE(L40:N40) -> 0 | AR40: =AVERAGE(O40:Q40) -> 0 | AS40: =AVERAGE(R40:T40) -> 0 | AT40: =AVERAGE(U40:W40) -> 0 | AU40: =AVERAGE(X40:Z40) -> 0 | AV40: =AVERAGE(AA40:AC40) -> 0 | AW40: =AVERAGE(AD40:AF40) -> 0 | AX40: =AVERAGE(AG40:AI40) -> 0 | AY40: =AVERAGE(AJ40:AL40) -> 0 | BA40: =AVERAGE(C40:N40) -> 0 | BB40: =AVERAGE(O40:Z40) -> 0 | BC40: =AVERAGE(AA40:AL40) -> 0
A41: Paid retention % | C41: =IFERROR(C24/C22,1) -> 0 | D41: =IFERROR(D24/D22,1) -> 0 | E41: =IFERROR(E24/E22,1) -> 0 | F41: =IFERROR(F24/F22,1) -> 0 | G41: =IFERROR(G24/G22,1) -> 0 | H41: =IFERROR(H24/H22,1) -> 0 | I41: =IFERROR(I24/I22,1) -> 0 | J41: =IFERROR(J24/J22,1) -> 0 | ... AL41: =IFERROR(AL24/AL22,1) -> 0 | AN41: =AVERAGE(C41:E41) -> 0 | AO41: =AVERAGE(F41:H41) -> 0 | AP41: =AVERAGE(I41:K41) -> 0 | AQ41: =AVERAGE(L41:N41) -> 0 | AR41: =AVERAGE(O41:Q41) -> 0 | AS41: =AVERAGE(R41:T41) -> 0 | AT41: =AVERAGE(U41:W41) -> 0 | AU41: =AVERAGE(X41:Z41) -> 0 | AV41: =AVERAGE(AA41:AC41) -> 0 | AW41: =AVERAGE(AD41:AF41) -> 0 | AX41: =AVERAGE(AG41:AI41) -> 0 | AY41: =AVERAGE(AJ41:AL41) -> 0 | BA41: =AVERAGE(C41:N41) -> 0 | BB41: =AVERAGE(O41:Z41) -> 0 | BC41: =AVERAGE(AA41:AL41) -> 0
A42: Paid churn % | C42: =IFERROR(-C23/C22,'Assumptions'!$F$28) -> 0 | D42: =IFERROR(-D23/D22,'Assumptions'!$F$28) -> 0 | E42: =IFERROR(-E23/E22,'Assumptions'!$F$28) -> 0 | F42: =IFERROR(-F23/F22,'Assumptions'!$F$28) -> 0 | G42: =IFERROR(-G23/G22,'Assumptions'!$F$28) -> 0 | H42: =IFERROR(-H23/H22,'Assumptions'!$F$28) -> 0 | I42: =IFERROR(-I23/I22,'Assumptions'!$F$28) -> 0 | J42: =IFERROR(-J23/J22,'Assumptions'!$F$28) -> 0 | ... AL42: =IFERROR(-AL23/AL22,'Assumptions'!$F$28) -> 0 | AN42: =AVERAGE(C42:E42) -> 0 | AO42: =AVERAGE(F42:H42) -> 0 | AP42: =AVERAGE(I42:K42) -> 0 | AQ42: =AVERAGE(L42:N42) -> 0 | AR42: =AVERAGE(O42:Q42) -> 0 | AS42: =AVERAGE(R42:T42) -> 0 | AT42: =AVERAGE(U42:W42) -> 0 | AU42: =AVERAGE(X42:Z42) -> 0 | AV42: =AVERAGE(AA42:AC42) -> 0 | AW42: =AVERAGE(AD42:AF42) -> 0 | AX42: =AVERAGE(AG42:AI42) -> 0 | AY42: =AVERAGE(AJ42:AL42) -> 0 | BA42: =AVERAGE(C42:N42) -> 0 | BB42: =AVERAGE(O42:Z42) -> 0 | BC42: =AVERAGE(AA42:AL42) -> 0
A43: Blended CAC | B43: Total acquisition spend ÷ new paid adds | C43: =IFERROR(C15/MAX(1,C27),0) -> 0 | D43: =IFERROR(D15/MAX(1,D27),0) -> 0 | E43: =IFERROR(E15/MAX(1,E27),0) -> 0 | F43: =IFERROR(F15/MAX(1,F27),0) -> 0 | G43: =IFERROR(G15/MAX(1,G27),0) -> 0 | H43: =IFERROR(H15/MAX(1,H27),0) -> 0 | I43: =IFERROR(I15/MAX(1,I27),0) -> 0 | J43: =IFERROR(J15/MAX(1,J27),0) -> 0 | ... AL43: =IFERROR(AL15/MAX(1,AL27),0) -> 0 | AN43: =AVERAGE(C43:E43) -> 0 | AO43: =AVERAGE(F43:H43) -> 0 | AP43: =AVERAGE(I43:K43) -> 0 | AQ43: =AVERAGE(L43:N43) -> 0 | AR43: =AVERAGE(O43:Q43) -> 0 | AS43: =AVERAGE(R43:T43) -> 0 | AT43: =AVERAGE(U43:W43) -> 0 | AU43: =AVERAGE(X43:Z43) -> 0 | AV43: =AVERAGE(AA43:AC43) -> 0 | AW43: =AVERAGE(AD43:AF43) -> 0 | AX43: =AVERAGE(AG43:AI43) -> 0 | AY43: =AVERAGE(AJ43:AL43) -> 0 | BA43: =AVERAGE(C43:N43) -> 0 | BB43: =AVERAGE(O43:Z43) -> 0 | BC43: =AVERAGE(AA43:AL43) -> 0
A44: Revenue per MAU | C44: =IFERROR(C35/C21,0) -> 0 | D44: =IFERROR(D35/D21,0) -> 0 | E44: =IFERROR(E35/E21,0) -> 0 | F44: =IFERROR(F35/F21,0) -> 0 | G44: =IFERROR(G35/G21,0) -> 0 | H44: =IFERROR(H35/H21,0) -> 0 | I44: =IFERROR(I35/I21,0) -> 0 | J44: =IFERROR(J35/J21,0) -> 0 | ... AL44: =IFERROR(AL35/AL21,0) -> 0 | AN44: =AVERAGE(C44:E44) -> 0 | AO44: =AVERAGE(F44:H44) -> 0 | AP44: =AVERAGE(I44:K44) -> 0 | AQ44: =AVERAGE(L44:N44) -> 0 | AR44: =AVERAGE(O44:Q44) -> 0 | AS44: =AVERAGE(R44:T44) -> 0 | AT44: =AVERAGE(U44:W44) -> 0 | AU44: =AVERAGE(X44:Z44) -> 0 | AV44: =AVERAGE(AA44:AC44) -> 0 | AW44: =AVERAGE(AD44:AF44) -> 0 | AX44: =AVERAGE(AG44:AI44) -> 0 | AY44: =AVERAGE(AJ44:AL44) -> 0 | BA44: =AVERAGE(C44:N44) -> 0 | BB44: =AVERAGE(O44:Z44) -> 0 | BC44: =AVERAGE(AA44:AL44) -> 0

Sheet COGS & GM
A1: Consumer Subscription — 3-Year Financial Model — COGS & GM
A2: App-store / payment fees, hosting, AI inference cost, and Support / Community Ops people cost.
A5: Line item | B5: Units / source | C5: Monthly (36 months) | AN5: Quarterly | BA5: Annual
C6: 46023 | D6: 46054 | E6: 46082 | F6: 46113 | G6: 46143 | H6: 46174 | I6: 46204 | J6: 46235 | K6: 46266 | L6: 46296 | M6: 46327 | N6: 46357 | O6: 46388 | P6: 46419 | Q6: 46447 | R6: 46478 | S6: 46508 | T6: 46539 | U6: 46569 | V6: 46600 | W6: 46631 | X6: 46661 | Y6: 46692 | Z6: 46722 | AA6: 46753 | AB6: 46784 | AC6: 46813 | AD6: 46844 | AE6: 46874 | AF6: 46905 | AG6: 46935 | AH6: 46966 | AI6: 46997 | AJ6: 47027 | AK6: 47058 | AL6: 47088 | AN6: Q1 | AO6: Q2 | AP6: Q3 | AQ6: Q4 | AR6: Q5 | AS6: Q6 | AT6: Q7 | AU6: Q8 | AV6: Q9 | AW6: Q10 | AX6: Q11 | AY6: Q12 | BA6: FY1 | BB6: FY2 | BC6: FY3
A7: COGS Components
A8: App-store / platform fees | C8: ='Revenue'!C35*'Assumptions'!$F$35 -> 0 | D8: ='Revenue'!D35*'Assumptions'!$F$35 -> 0 | E8: ='Revenue'!E35*'Assumptions'!$F$35 -> 0 | F8: ='Revenue'!F35*'Assumptions'!$F$35 -> 0 | G8: ='Revenue'!G35*'Assumptions'!$F$35 -> 0 | H8: ='Revenue'!H35*'Assumptions'!$F$35 -> 0 | I8: ='Revenue'!I35*'Assumptions'!$F$35 -> 0 | J8: ='Revenue'!J35*'Assumptions'!$F$35 -> 0 | ... AL8: ='Revenue'!AL35*'Assumptions'!$F$35 -> 0 | AN8: =SUM(C8:E8) -> 0 | AO8: =SUM(F8:H8) -> 0 | AP8: =SUM(I8:K8) -> 0 | AQ8: =SUM(L8:N8) -> 0 | AR8: =SUM(O8:Q8) -> 0 | AS8: =SUM(R8:T8) -> 0 | AT8: =SUM(U8:W8) -> 0 | AU8: =SUM(X8:Z8) -> 0 | AV8: =SUM(AA8:AC8) -> 0 | AW8: =SUM(AD8:AF8) -> 0 | AX8: =SUM(AG8:AI8) -> 0 | AY8: =SUM(AJ8:AL8) -> 0 | BA8: =SUM(C8:N8) -> 0 | BB8: =SUM(O8:Z8) -> 0 | BC8: =SUM(AA8:AL8) -> 0
A9: Payment processing fees | C9: ='Revenue'!C35*'Assumptions'!$F$36 -> 0 | D9: ='Revenue'!D35*'Assumptions'!$F$36 -> 0 | E9: ='Revenue'!E35*'Assumptions'!$F$36 -> 0 | F9: ='Revenue'!F35*'Assumptions'!$F$36 -> 0 | G9: ='Revenue'!G35*'Assumptions'!$F$36 -> 0 | H9: ='Revenue'!H35*'Assumptions'!$F$36 -> 0 | I9: ='Revenue'!I35*'Assumptions'!$F$36 -> 0 | J9: ='Revenue'!J35*'Assumptions'!$F$36 -> 0 | ... AL9: ='Revenue'!AL35*'Assumptions'!$F$36 -> 0 | AN9: =SUM(C9:E9) -> 0 | AO9: =SUM(F9:H9) -> 0 | AP9: =SUM(I9:K9) -> 0 | AQ9: =SUM(L9:N9) -> 0 | AR9: =SUM(O9:Q9) -> 0 | AS9: =SUM(R9:T9) -> 0 | AT9: =SUM(U9:W9) -> 0 | AU9: =SUM(X9:Z9) -> 0 | AV9: =SUM(AA9:AC9) -> 0 | AW9: =SUM(AD9:AF9) -> 0 | AX9: =SUM(AG9:AI9) -> 0 | AY9: =SUM(AJ9:AL9) -> 0 | BA9: =SUM(C9:N9) -> 0 | BB9: =SUM(O9:Z9) -> 0 | BC9: =SUM(AA9:AL9) -> 0
A10: Hosting & infrastructure | C10: ='Revenue'!C21*'Assumptions'!$F$37 -> 0 | D10: ='Revenue'!D21*'Assumptions'!$F$37 -> 0 | E10: ='Revenue'!E21*'Assumptions'!$F$37 -> 0 | F10: ='Revenue'!F21*'Assumptions'!$F$37 -> 0 | G10: ='Revenue'!G21*'Assumptions'!$F$37 -> 0 | H10: ='Revenue'!H21*'Assumptions'!$F$37 -> 0 | I10: ='Revenue'!I21*'Assumptions'!$F$37 -> 0 | J10: ='Revenue'!J21*'Assumptions'!$F$37 -> 0 | ... AL10: ='Revenue'!AL21*'Assumptions'!$F$37 -> 0 | AN10: =SUM(C10:E10) -> 0 | AO10: =SUM(F10:H10) -> 0 | AP10: =SUM(I10:K10) -> 0 | AQ10: =SUM(L10:N10) -> 0 | AR10: =SUM(O10:Q10) -> 0 | AS10: =SUM(R10:T10) -> 0 | AT10: =SUM(U10:W10) -> 0 | AU10: =SUM(X10:Z10) -> 0 | AV10: =SUM(AA10:AC10) -> 0 | AW10: =SUM(AD10:AF10) -> 0 | AX10: =SUM(AG10:AI10) -> 0 | AY10: =SUM(AJ10:AL10) -> 0 | BA10: =SUM(C10:N10) -> 0 | BB10: =SUM(O10:Z10) -> 0 | BC10: =SUM(AA10:AL10) -> 0
A11: AI inference / premium support | C11: ='Revenue'!C28*'Assumptions'!$F$38 -> 0 | D11: ='Revenue'!D28*'Assumptions'!$F$38 -> 0 | E11: ='Revenue'!E28*'Assumptions'!$F$38 -> 0 | F11: ='Revenue'!F28*'Assumptions'!$F$38 -> 0 | G11: ='Revenue'!G28*'Assumptions'!$F$38 -> 0 | H11: ='Revenue'!H28*'Assumptions'!$F$38 -> 0 | I11: ='Revenue'!I28*'Assumptions'!$F$38 -> 0 | J11: ='Revenue'!J28*'Assumptions'!$F$38 -> 0 | ... AL11: ='Revenue'!AL28*'Assumptions'!$F$38 -> 0 | AN11: =SUM(C11:E11) -> 0 | AO11: =SUM(F11:H11) -> 0 | AP11: =SUM(I11:K11) -> 0 | AQ11: =SUM(L11:N11) -> 0 | AR11: =SUM(O11:Q11) -> 0 | AS11: =SUM(R11:T11) -> 0 | AT11: =SUM(U11:W11) -> 0 | AU11: =SUM(X11:Z11) -> 0 | AV11: =SUM(AA11:AC11) -> 0 | AW11: =SUM(AD11:AF11) -> 0 | AX11: =SUM(AG11:AI11) -> 0 | AY11: =SUM(AJ11:AL11) -> 0 | BA11: =SUM(C11:N11) -> 0 | BB11: =SUM(O11:Z11) -> 0 | BC11: =SUM(AA11:AL11) -> 0
A12: Support / Community Ops people cost | C12: ='Headcount'!$C$21 -> 0 | D12: ='Headcount'!$D$21 -> 0 | E12: ='Headcount'!$E$21 -> 0 | F12: ='Headcount'!$F$21 -> 0 | G12: ='Headcount'!$G$21 -> 0 | H12: ='Headcount'!$H$21 -> 0 | I12: ='Headcount'!$I$21 -> 0 | J12: ='Headcount'!$J$21 -> 0 | K12: ='Headcount'!$K$21 -> 0 | L12: ='Headcount'!$L$21 -> 0 | M12: ='Headcount'!$M$21 -> 0 | N12: ='Headcount'!$N$21 -> 0 | O12: ='Headcount'!$O$21 -> 0 | P12: ='Headcount'!$P$21 -> 0 | Q12: ='Headcount'!$Q$21 -> 0 | R12: ='Headcount'!$R$21 -> 0 | S12: ='Headcount'!$S$21 -> 0 | T12: ='Headcount'!$T$21 -> 0 | U12: ='Headcount'!$U$21 -> 0 | V12: ='Headcount'!$V$21 -> 0 | W12: ='Headcount'!$W$21 -> 0 | X12: ='Headcount'!$X$21 -> 0 | Y12: ='Headcount'!$Y$21 -> 0 | Z12: ='Headcount'!$Z$21 -> 0 | AA12: ='Headcount'!$AA$21 -> 0 | AB12: ='Headcount'!$AB$21 -> 0 | AC12: ='Headcount'!$AC$21 -> 0 | AD12: ='Headcount'!$AD$21 -> 0 | AE12: ='Headcount'!$AE$21 -> 0 | AF12: ='Headcount'!$AF$21 -> 0 | AG12: ='Headcount'!$AG$21 -> 0 | AH12: ='Headcount'!$AH$21 -> 0 | AI12: ='Headcount'!$AI$21 -> 0 | AJ12: ='Headcount'!$AJ$21 -> 0 | AK12: ='Headcount'!$AK$21 -> 0 | AL12: ='Headcount'!$AL$21 -> 0 | AN12: =SUM(C12:E12) -> 0 | AO12: =SUM(F12:H12) -> 0 | AP12: =SUM(I12:K12) -> 0 | AQ12: =SUM(L12:N12) -> 0 | AR12: =SUM(O12:Q12) -> 0 | AS12: =SUM(R12:T12) -> 0 | AT12: =SUM(U12:W12) -> 0 | AU12: =SUM(X12:Z12) -> 0 | AV12: =SUM(AA12:AC12) -> 0 | AW12: =SUM(AD12:AF12) -> 0 | AX12: =SUM(AG12:AI12) -> 0 | AY12: =SUM(AJ12:AL12) -> 0 | BA12: =SUM(C12:N12) -> 0 | BB12: =SUM(O12:Z12) -> 0 | BC12: =SUM(AA12:AL12) -> 0
A13: Total COGS | C13: =C8+C9+C10+C11+C12 -> 0 | D13: =D8+D9+D10+D11+D12 -> 0 | E13: =E8+E9+E10+E11+E12 -> 0 | F13: =F8+F9+F10+F11+F12 -> 0 | G13: =G8+G9+G10+G11+G12 -> 0 | H13: =H8+H9+H10+H11+H12 -> 0 | I13: =I8+I9+I10+I11+I12 -> 0 | J13: =J8+J9+J10+J11+J12 -> 0 | ... AL13: =AL8+AL9+AL10+AL11+AL12 -> 0 | AN13: =SUM(C13:E13) -> 0 | AO13: =SUM(F13:H13) -> 0 | AP13: =SUM(I13:K13) -> 0 | AQ13: =SUM(L13:N13) -> 0 | AR13: =SUM(O13:Q13) -> 0 | AS13: =SUM(R13:T13) -> 0 | AT13: =SUM(U13:W13) -> 0 | AU13: =SUM(X13:Z13) -> 0 | AV13: =SUM(AA13:AC13) -> 0 | AW13: =SUM(AD13:AF13) -> 0 | AX13: =SUM(AG13:AI13) -> 0 | AY13: =SUM(AJ13:AL13) -> 0 | BA13: =SUM(C13:N13) -> 0 | BB13: =SUM(O13:Z13) -> 0 | BC13: =SUM(AA13:AL13) -> 0
A15: Gross Profit & Unit Economics
A16: Gross Profit | C16: ='Revenue'!C35-C13 -> 0 | D16: ='Revenue'!D35-D13 -> 0 | E16: ='Revenue'!E35-E13 -> 0 | F16: ='Revenue'!F35-F13 -> 0 | G16: ='Revenue'!G35-G13 -> 0 | H16: ='Revenue'!H35-H13 -> 0 | I16: ='Revenue'!I35-I13 -> 0 | J16: ='Revenue'!J35-J13 -> 0 | ... AL16: ='Revenue'!AL35-AL13 -> 0 | AN16: =SUM(C16:E16) -> 0 | AO16: =SUM(F16:H16) -> 0 | AP16: =SUM(I16:K16) -> 0 | AQ16: =SUM(L16:N16) -> 0 | AR16: =SUM(O16:Q16) -> 0 | AS16: =SUM(R16:T16) -> 0 | AT16: =SUM(U16:W16) -> 0 | AU16: =SUM(X16:Z16) -> 0 | AV16: =SUM(AA16:AC16) -> 0 | AW16: =SUM(AD16:AF16) -> 0 | AX16: =SUM(AG16:AI16) -> 0 | AY16: =SUM(AJ16:AL16) -> 0 | BA16: =SUM(C16:N16) -> 0 | BB16: =SUM(O16:Z16) -> 0 | BC16: =SUM(AA16:AL16) -> 0
A17: Gross Margin % | C17: =IFERROR(C16/'Revenue'!C35,0) -> 0 | D17: =IFERROR(D16/'Revenue'!D35,0) -> 0 | E17: =IFERROR(E16/'Revenue'!E35,0) -> 0 | F17: =IFERROR(F16/'Revenue'!F35,0) -> 0 | G17: =IFERROR(G16/'Revenue'!G35,0) -> 0 | H17: =IFERROR(H16/'Revenue'!H35,0) -> 0 | I17: =IFERROR(I16/'Revenue'!I35,0) -> 0 | J17: =IFERROR(J16/'Revenue'!J35,0) -> 0 | ... AL17: =IFERROR(AL16/'Revenue'!AL35,0) -> 0 | AN17: =AVERAGE(C17:E17) -> 0 | AO17: =AVERAGE(F17:H17) -> 0 | AP17: =AVERAGE(I17:K17) -> 0 | AQ17: =AVERAGE(L17:N17) -> 0 | AR17: =AVERAGE(O17:Q17) -> 0 | AS17: =AVERAGE(R17:T17) -> 0 | AT17: =AVERAGE(U17:W17) -> 0 | AU17: =AVERAGE(X17:Z17) -> 0 | AV17: =AVERAGE(AA17:AC17) -> 0 | AW17: =AVERAGE(AD17:AF17) -> 0 | AX17: =AVERAGE(AG17:AI17) -> 0 | AY17: =AVERAGE(AJ17:AL17) -> 0 | BA17: =AVERAGE(C17:N17) -> 0 | BB17: =AVERAGE(O17:Z17) -> 0 | BC17: =AVERAGE(AA17:AL17) -> 0
A18: Contribution Margin % | B18: (Gross profit − acquisition spend) ÷ revenue | C18: =IFERROR((C16-'Revenue'!C15)/'Revenue'!C35,0) -> 0 | D18: =IFERROR((D16-'Revenue'!D15)/'Revenue'!D35,0) -> 0 | E18: =IFERROR((E16-'Revenue'!E15)/'Revenue'!E35,0) -> 0 | F18: =IFERROR((F16-'Revenue'!F15)/'Revenue'!F35,0) -> 0 | G18: =IFERROR((G16-'Revenue'!G15)/'Revenue'!G35,0) -> 0 | H18: =IFERROR((H16-'Revenue'!H15)/'Revenue'!H35,0) -> 0 | I18: =IFERROR((I16-'Revenue'!I15)/'Revenue'!I35,0) -> 0 | J18: =IFERROR((J16-'Revenue'!J15)/'Revenue'!J35,0) -> 0 | ... AL18: =IFERROR((AL16-'Revenue'!AL15)/'Revenue'!AL35,0) -> 0 | AN18: =AVERAGE(C18:E18) -> 0 | AO18: =AVERAGE(F18:H18) -> 0 | AP18: =AVERAGE(I18:K18) -> 0 | AQ18: =AVERAGE(L18:N18) -> 0 | AR18: =AVERAGE(O18:Q18) -> 0 | AS18: =AVERAGE(R18:T18) -> 0 | AT18: =AVERAGE(U18:W18) -> 0 | AU18: =AVERAGE(X18:Z18) -> 0 | AV18: =AVERAGE(AA18:AC18) -> 0 | AW18: =AVERAGE(AD18:AF18) -> 0 | AX18: =AVERAGE(AG18:AI18) -> 0 | AY18: =AVERAGE(AJ18:AL18) -> 0 | BA18: =AVERAGE(C18:N18) -> 0 | BB18: =AVERAGE(O18:Z18) -> 0 | BC18: =AVERAGE(AA18:AL18) -> 0
A19: LTV | B19: Blended ARPU × contribution margin % ÷ monthly paid churn | C19: =IF('Revenue'!C42<=0,999,MAX(0,('Revenue'!C32*C18)/'Revenue'!C42)) -> 0 | D19: =IF('Revenue'!D42<=0,999,MAX(0,('Revenue'!D32*D18)/'Revenue'!D42)) -> 0 | E19: =IF('Revenue'!E42<=0,999,MAX(0,('Revenue'!E32*E18)/'Revenue'!E42)) -> 0 | F19: =IF('Revenue'!F42<=0,999,MAX(0,('Revenue'!F32*F18)/'Revenue'!F42)) -> 0 | G19: =IF('Revenue'!G42<=0,999,MAX(0,('Revenue'!G32*G18)/'Revenue'!G42)) -> 0 | H19: =IF('Revenue'!H42<=0,999,MAX(0,('Revenue'!H32*H18)/'Revenue'!H42)) -> 0 | I19: =IF('Revenue'!I42<=0,999,MAX(0,('Revenue'!I32*I18)/'Revenue'!I42)) -> 0 | J19: =IF('Revenue'!J42<=0,999,MAX(0,('Revenue'!J32*J18)/'Revenue'!J42)) -> 0 | ... AL19: =IF('Revenue'!AL42<=0,999,MAX(0,('Revenue'!AL32*AL18)/'Revenue'!AL42)) -> 0 | AN19: =AVERAGE(C19:E19) -> 0 | AO19: =AVERAGE(F19:H19) -> 0 | AP19: =AVERAGE(I19:K19) -> 0 | AQ19: =AVERAGE(L19:N19) -> 0 | AR19: =AVERAGE(O19:Q19) -> 0 | AS19: =AVERAGE(R19:T19) -> 0 | AT19: =AVERAGE(U19:W19) -> 0 | AU19: =AVERAGE(X19:Z19) -> 0 | AV19: =AVERAGE(AA19:AC19) -> 0 | AW19: =AVERAGE(AD19:AF19) -> 0 | AX19: =AVERAGE(AG19:AI19) -> 0 | AY19: =AVERAGE(AJ19:AL19) -> 0 | BA19: =AVERAGE(C19:N19) -> 0 | BB19: =AVERAGE(O19:Z19) -> 0 | BC19: =AVERAGE(AA19:AL19) -> 0
A20: LTV : CAC | C20: =IFERROR(C19/'Revenue'!C43,0) -> 0 | D20: =IFERROR(D19/'Revenue'!D43,0) -> 0 | E20: =IFERROR(E19/'Revenue'!E43,0) -> 0 | F20: =IFERROR(F19/'Revenue'!F43,0) -> 0 | G20: =IFERROR(G19/'Revenue'!G43,0) -> 0 | H20: =IFERROR(H19/'Revenue'!H43,0) -> 0 | I20: =IFERROR(I19/'Revenue'!I43,0) -> 0 | J20: =IFERROR(J19/'Revenue'!J43,0) -> 0 | ... AL20: =IFERROR(AL19/'Revenue'!AL43,0) -> 0 | AN20: =AVERAGE(C20:E20) -> 0 | AO20: =AVERAGE(F20:H20) -> 0 | AP20: =AVERAGE(I20:K20) -> 0 | AQ20: =AVERAGE(L20:N20) -> 0 | AR20: =AVERAGE(O20:Q20) -> 0 | AS20: =AVERAGE(R20:T20) -> 0 | AT20: =AVERAGE(U20:W20) -> 0 | AU20: =AVERAGE(X20:Z20) -> 0 | AV20: =AVERAGE(AA20:AC20) -> 0 | AW20: =AVERAGE(AD20:AF20) -> 0 | AX20: =AVERAGE(AG20:AI20) -> 0 | AY20: =AVERAGE(AJ20:AL20) -> 0 | BA20: =AVERAGE(C20:N20) -> 0 | BB20: =AVERAGE(O20:Z20) -> 0 | BC20: =AVERAGE(AA20:AL20) -> 0
A21: CAC payback (months) | B21: Blended CAC ÷ (ARPU × contribution margin %) | C21: =IF('Revenue'!C32*C18<=0,999,'Revenue'!C43/'Revenue'!C32*C18) -> 0 | D21: =IF('Revenue'!D32*D18<=0,999,'Revenue'!D43/'Revenue'!D32*D18) -> 0 | E21: =IF('Revenue'!E32*E18<=0,999,'Revenue'!E43/'Revenue'!E32*E18) -> 0 | F21: =IF('Revenue'!F32*F18<=0,999,'Revenue'!F43/'Revenue'!F32*F18) -> 0 | G21: =IF('Revenue'!G32*G18<=0,999,'Revenue'!G43/'Revenue'!G32*G18) -> 0 | H21: =IF('Revenue'!H32*H18<=0,999,'Revenue'!H43/'Revenue'!H32*H18) -> 0 | I21: =IF('Revenue'!I32*I18<=0,999,'Revenue'!I43/'Revenue'!I32*I18) -> 0 | J21: =IF('Revenue'!J32*J18<=0,999,'Revenue'!J43/'Revenue'!J32*J18) -> 0 | ... AL21: =IF('Revenue'!AL32*AL18<=0,999,'Revenue'!AL43/'Revenue'!AL32*AL18) -> 0 | AN21: =AVERAGE(C21:E21) -> 0 | AO21: =AVERAGE(F21:H21) -> 0 | AP21: =AVERAGE(I21:K21) -> 0 | AQ21: =AVERAGE(L21:N21) -> 0 | AR21: =AVERAGE(O21:Q21) -> 0 | AS21: =AVERAGE(R21:T21) -> 0 | AT21: =AVERAGE(U21:W21) -> 0 | AU21: =AVERAGE(X21:Z21) -> 0 | AV21: =AVERAGE(AA21:AC21) -> 0 | AW21: =AVERAGE(AD21:AF21) -> 0 | AX21: =AVERAGE(AG21:AI21) -> 0 | AY21: =AVERAGE(AJ21:AL21) -> 0 | BA21: =AVERAGE(C21:N21) -> 0 | BB21: =AVERAGE(O21:Z21) -> 0 | BC21: =AVERAGE(AA21:AL21) -> 0
